Workbook

Sheet Зміст
A1: Усі варіанти в одному файлі
A2: Кожен варіант має власні аркуші з префіксом «В01», «В02» тощо й свій колір вкладок. Натисніть на посилання, щоб перейти до варіанта.
A4: Варіант | B4: Перехід
A5: Варіант 01 | B5: Відкрити аркуші варіанта 01
A6: Варіант 02 | B6: Відкрити аркуші варіанта 02
A7: Варіант 03 | B7: Відкрити аркуші варіанта 03
A8: Варіант 04 | B8: Відкрити аркуші варіанта 04
A9: Варіант 05 | B9: Відкрити аркуші варіанта 05
A10: Варіант 06 | B10: Відкрити аркуші варіанта 06
A11: Варіант 07 | B11: Відкрити аркуші варіанта 07
A12: Варіант 08 | B12: Відкрити аркуші варіанта 08
A13: Варіант 09 | B13: Відкрити аркуші варіанта 09
A14: Варіант 10 | B14: Відкрити аркуші варіанта 10

Sheet В01 Інструкція
A1: ПР 3. Проєкт мережі відділення: зони, VLAN, адреси. Варіант 01
A2: Працюйте в жовтих комірках. Сірі комірки рахуються самі (захищені). Схему зон малюйте в PowerPoint-файлі варіанта.
A4: Порядок роботи
A5: 1. Зони (питання 1) | B5: На аркуші «Пристрої» для кожної групи пристроїв оберіть зону. Колонка «Перевірка» підкаже, якщо тип пристрою не відповідає зоні. Для пристроїв «потребує рішення» вирішуйте самі й поясніть вибір на аркуші «Обґрунтування».
A6: 2. Підмережі (питання 2) | B6: На аркуші «Зони й адреси» для кожної зони порахуйте, скільки адрес потрібно з запасом на зростання, оберіть префікс (від /24 до /30) і VLAN. Рахуйте на папері або в калькуляторі: файл лише перевіряє результат.
A7: 3. Адресна таблиця (питання 3) | B7: Запишіть адресу мережі й шлюз кожної зони, native VLAN. Колонка «Перевірка» має показувати «ОК» для всіх зон.
A8: 4. Чернетка колеги | B8: На аркуші «Чернетка колеги» знайдіть три помилки й запишіть у журнал. До свого проєкту їх не переносьте.
A9: 5. Нова обставина | B9: Коли завершите кроки 1–3, відкрийте окремий файл «Нова обставина» (не раніше). Оновіть таблицю й схему на другому слайді PowerPoint.
A10: 6. Обґрунтування і здача | B10: Заповніть аркуш «Обґрунтування», перевірте аркуш «Підсумок» і здайте два файли (Excel і PowerPoint).
A12: Формула запасу | B12: Потрібно адрес = пристроїв зараз × (1 + зростання за рік) + 1 адреса під шлюз, результат округлюється вгору.
A13: Місткість підмережі | B13: У підмережі /n корисних адрес 2^(32−n) − 2 (адреса мережі й адреса розсилки не видаються пристроям).
A14: Правило адрес | B14: Усе відділення використовує блок 10.A.0.0/16 (ваше A на аркуші «Картка»). Кожна зона має адресу вигляду 10.A.<VLAN>.x: третій октет дорівнює номеру VLAN.
A15: Правило VLAN | B15: Номер від 2 до 254; не 1; між номерами сусідніх зон лишайте проміжок не менше 5, щоб додавати зони без перенумерації. Native VLAN теж окремий номер, не збігається з VLAN зон.
A16: Шлюз | B16: Шлюз беріть за правилом варіанта (перша або остання корисна адреса підмережі).

Sheet В01 Картка
A1: Картка варіанта 01
A3: Студент (прізвище)
A4: Блок адрес відділення | B4: 10.162.0.0/16
A5: Значення A (другий октет) | B5: 162
A6: Правило шлюзу | B6: перша адреса підмережі
A7: Особливі пристрої (потребують вашого рішення) | B7: Мережевий принтер, спільний для кас і менеджерів (1 шт.); Інформаційні екрани й електронна черга в залі (3 шт.)
A8: Зростання за рік, % | B8: Каси 20 · Менеджери 20 · Термінали АБС 50 · Банкомати й POS 25 · Інтернет речей 100 · Гостьова Wi-Fi 50 · Керування обладнанням 20
A10: Легенда відділення
A11: 12 співробітників; два банкомати (один усередині, один на вулиці); POS-термінали; камери, електронні замки, датчики серверної; гостьова Wi-Fi; зв'язок з головним офісом через Інтернет. Усе описано в групах пристроїв на аркуші «Пристрої».

Sheet В01 Пристрої
A1: Пристрої відділення
A2: Для кожної групи оберіть зону. Нижні п'ять рядків (21–25) призначені для нової обставини.
H3: Типи пристроїв і зони
A4: № | B4: Пристрій | C4: Кількість | D4: Тип | E4: Зона (оберіть) | F4: Перевірка | H4: Тип | I4: Зона
A5: 1 | B5: Робочі місця кас | C5: 3 | D5: каса | F5: =IF(C5="","",IF(D5="","вкажіть тип",IF(E5="","призначте зону",IF(D5="потребує рішення","рішення поясніть на аркуші «Обґрунтування»",IF(IFERROR(VLOOKUP(D5,$H$5:$I$11,2,FALSE),"?")=E5,"ОК","тип пристрою не відповідає зоні"))))) -> призначте зону | H5: каса | I5: KASA
A6: 2 | B6: Принтери й сканери кас | C6: 1 | D6: каса | F6: =IF(C6="","",IF(D6="","вкажіть тип",IF(E6="","призначте зону",IF(D6="потребує рішення","рішення поясніть на аркуші «Обґрунтування»",IF(IFERROR(VLOOKUP(D6,$H$5:$I$11,2,FALSE),"?")=E6,"ОК","тип пристрою не відповідає зоні"))))) -> призначте зону | H6: менеджер | I6: MANAGERS
A7: 3 | B7: Робочі місця менеджерів і керівника | C7: 4 | D7: менеджер | F7: =IF(C7="","",IF(D7="","вкажіть тип",IF(E7="","призначте зону",IF(D7="потребує рішення","рішення поясніть на аркуші «Обґрунтування»",IF(IFERROR(VLOOKUP(D7,$H$5:$I$11,2,FALSE),"?")=E7,"ОК","тип пристрою не відповідає зоні"))))) -> призначте зону | H7: АБС | I7: ABS
A8: 4 | B8: Термінали АБС (операціоніст) | C8: 2 | D8: АБС | F8: =IF(C8="","",IF(D8="","вкажіть тип",IF(E8="","призначте зону",IF(D8="потребує рішення","рішення поясніть на аркуші «Обґрунтування»",IF(IFERROR(VLOOKUP(D8,$H$5:$I$11,2,FALSE),"?")=E8,"ОК","тип пристрою не відповідає зоні"))))) -> призначте зону | H8: платіжний пристрій | I8: ATM_POS
A9: 5 | B9: Банкомати (всередині й на вулиці) | C9: 2 | D9: платіжний пристрій | F9: =IF(C9="","",IF(D9="","вкажіть тип",IF(E9="","призначте зону",IF(D9="потребує рішення","рішення поясніть на аркуші «Обґрунтування»",IF(IFERROR(VLOOKUP(D9,$H$5:$I$11,2,FALSE),"?")=E9,"ОК","тип пристрою не відповідає зоні"))))) -> призначте зону | H9: без користувача | I9: IOT
A10: 6 | B10: POS-термінали | C10: 4 | D10: платіжний пристрій | F10: =IF(C10="","",IF(D10="","вкажіть тип",IF(E10="","призначте зону",IF(D10="потребує рішення","рішення поясніть на аркуші «Обґрунтування»",IF(IFERROR(VLOOKUP(D10,$H$5:$I$11,2,FALSE),"?")=E10,"ОК","тип пристрою не відповідає зоні"))))) -> призначте зону | H10: клієнтські пристрої | I10: GUEST
A11: 7 | B11: Камери відеоспостереження | C11: 8 | D11: без користувача | F11: =IF(C11="","",IF(D11="","вкажіть тип",IF(E11="","призначте зону",IF(D11="потребує рішення","рішення поясніть на аркуші «Обґрунтування»",IF(IFERROR(VLOOKUP(D11,$H$5:$I$11,2,FALSE),"?")=E11,"ОК","тип пристрою не відповідає зоні"))))) -> призначте зону | H11: мережеве обладнання | I11: MGMT
A12: 8 | B12: Контролери електронних замків | C12: 3 | D12: без користувача | F12: =IF(C12="","",IF(D12="","вкажіть тип",IF(E12="","призначте зону",IF(D12="потребує рішення","рішення поясніть на аркуші «Обґрунтування»",IF(IFERROR(VLOOKUP(D12,$H$5:$I$11,2,FALSE),"?")=E12,"ОК","тип пристрою не відповідає зоні"))))) -> призначте зону | H12: «потребує рішення»: зону обираєте самі
A13: 9 | B13: Датчики температури й диму в серверній | C13: 4 | D13: без користувача | F13: =IF(C13="","",IF(D13="","вкажіть тип",IF(E13="","призначте зону",IF(D13="потребує рішення","рішення поясніть на аркуші «Обґрунтування»",IF(IFERROR(VLOOKUP(D13,$H$5:$I$11,2,FALSE),"?")=E13,"ОК","тип пристрою не відповідає зоні"))))) -> призначте зону
A14: 10 | B14: Пристрої гостей Wi-Fi (одночасно) | C14: 40 | D14: клієнтські пристрої | F14: =IF(C14="","",IF(D14="","вкажіть тип",IF(E14="","призначте зону",IF(D14="потребує рішення","рішення поясніть на аркуші «Обґрунтування»",IF(IFERROR(VLOOKUP(D14,$H$5:$I$11,2,FALSE),"?")=E14,"ОК","тип пристрою не відповідає зоні"))))) -> призначте зону
A15: 11 | B15: Комутатори | C15: 2 | D15: мережеве обладнання | F15: =IF(C15="","",IF(D15="","вкажіть тип",IF(E15="","призначте зону",IF(D15="потребує рішення","рішення поясніть на аркуші «Обґрунтування»",IF(IFERROR(VLOOKUP(D15,$H$5:$I$11,2,FALSE),"?")=E15,"ОК","тип пристрою не відповідає зоні"))))) -> призначте зону
A16: 12 | B16: Точки доступу Wi-Fi | C16: 2 | D16: мережеве обладнання | F16: =IF(C16="","",IF(D16="","вкажіть тип",IF(E16="","призначте зону",IF(D16="потребує рішення","рішення поясніть на аркуші «Обґрунтування»",IF(IFERROR(VLOOKUP(D16,$H$5:$I$11,2,FALSE),"?")=E16,"ОК","тип пристрою не відповідає зоні"))))) -> призначте зону
A17: 13 | B17: Маршрутизатор і міжмережевий екран | C17: 2 | D17: мережеве обладнання | F17: =IF(C17="","",IF(D17="","вкажіть тип",IF(E17="","призначте зону",IF(D17="потребує рішення","рішення поясніть на аркуші «Обґрунтування»",IF(IFERROR(VLOOKUP(D17,$H$5:$I$11,2,FALSE),"?")=E17,"ОК","тип пристрою не відповідає зоні"))))) -> призначте зону
A18: 14 | B18: Станція адміністратора | C18: 1 | D18: мережеве обладнання | F18: =IF(C18="","",IF(D18="","вкажіть тип",IF(E18="","призначте зону",IF(D18="потребує рішення","рішення поясніть на аркуші «Обґрунтування»",IF(IFERROR(VLOOKUP(D18,$H$5:$I$11,2,FALSE),"?")=E18,"ОК","тип пристрою не відповідає зоні"))))) -> призначте зону
A19: 15 | B19: Мережевий принтер, спільний для кас і менеджерів | C19: 1 | D19: потребує рішення | F19: =IF(C19="","",IF(D19="","вкажіть тип",IF(E19="","призначте зону",IF(D19="потребує рішення","рішення поясніть на аркуші «Обґрунтування»",IF(IFERROR(VLOOKUP(D19,$H$5:$I$11,2,FALSE),"?")=E19,"ОК","тип пристрою не відповідає зоні"))))) -> призначте зону
A20: 16 | B20: Інформаційні екрани й електронна черга в залі | C20: 3 | D20: потребує рішення | F20: =IF(C20="","",IF(D20="","вкажіть тип",IF(E20="","призначте зону",IF(D20="потребує рішення","рішення поясніть на аркуші «Обґрунтування»",IF(IFERROR(VLOOKUP(D20,$H$5:$I$11,2,FALSE),"?")=E20,"ОК","тип пристрою не відповідає зоні"))))) -> призначте зону
A21: 17 | F21: =IF(C21="","",IF(D21="","вкажіть тип",IF(E21="","призначте зону",IF(D21="потребує рішення","рішення поясніть на аркуші «Обґрунтування»",IF(IFERROR(VLOOKUP(D21,$H$5:$I$11,2,FALSE),"?")=E21,"ОК","тип пристрою не відповідає зоні")))))
A22: 18 | F22: =IF(C22="","",IF(D22="","вкажіть тип",IF(E22="","призначте зону",IF(D22="потребує рішення","рішення поясніть на аркуші «Обґрунтування»",IF(IFERROR(VLOOKUP(D22,$H$5:$I$11,2,FALSE),"?")=E22,"ОК","тип пристрою не відповідає зоні")))))
A23: 19 | F23: =IF(C23="","",IF(D23="","вкажіть тип",IF(E23="","призначте зону",IF(D23="потребує рішення","рішення поясніть на аркуші «Обґрунтування»",IF(IFERROR(VLOOKUP(D23,$H$5:$I$11,2,FALSE),"?")=E23,"ОК","тип пристрою не відповідає зоні")))))
A24: 20 | F24: =IF(C24="","",IF(D24="","вкажіть тип",IF(E24="","призначте зону",IF(D24="потребує рішення","рішення поясніть на аркуші «Обґрунтування»",IF(IFERROR(VLOOKUP(D24,$H$5:$I$11,2,FALSE),"?")=E24,"ОК","тип пристрою не відповідає зоні")))))
A25: 21 | F25: =IF(C25="","",IF(D25="","вкажіть тип",IF(E25="","призначте зону",IF(D25="потребує рішення","рішення поясніть на аркуші «Обґрунтування»",IF(IFERROR(VLOOKUP(D25,$H$5:$I$11,2,FALSE),"?")=E25,"ОК","тип пристрою не відповідає зоні")))))

Sheet В01 Чернетка колеги
A1: Чернетка адресної таблиці від колеги
A2: У ній три помилки. Знайдіть їх, запишіть у журнал і не переносьте у свій проєкт. Кількість адрес колега порахував правильно.
A4: № | B4: Зона | C4: Потрібно адрес | D4: VLAN | E4: Мережа | F4: Префікс | G4: Шлюз
A5: 1 | B5: Каси | C5: 7 | D5: 20 | E5: 10.162.20.0 | F5: /28 | G5: 10.162.20.1
A6: 2 | B6: Менеджери | C6: 6 | D6: 30 | E6: 10.162.30.0 | F6: /29 | G6: 10.162.30.1
A7: 3 | B7: Термінали АБС | C7: 4 | D7: 40 | E7: 10.162.40.0 | F7: /30 | G7: 10.162.40.1
A8: 4 | B8: Банкомати й POS | C8: 9 | D8: 50 | E8: 10.162.50.0 | F8: /28 | G8: 10.162.50.1
A9: 5 | B9: Інтернет речей | C9: 37 | D9: 60 | E9: 10.162.60.0 | F9: /26 | G9: 10.162.60.63
A10: 6 | B10: Гостьова Wi-Fi | C10: 61 | D10: 70 | E10: 10.162.70.0 | F10: /26 | G10: 10.162.70.1
A11: 7 | B11: Керування обладнанням | C11: 10 | D11: 40 | E11: 10.162.40.0 | F11: /28 | G11: 10.162.40.1
A13: Журнал виправлень
A14: Рядок | B14: Тип помилки | C14: Що не так і як виправити

Sheet В01 Зони й адреси
A1: Зони, VLAN і адресна таблиця
A2: Рядки NEW1 і NEW2 потрібні лише для нової обставини. Колонка «Перевірка» підказує, що виправити.
A4: Код зони | B4: Назва зони | C4: Пристроїв зараз | D4: Зростання за рік, % | E4: Потрібно адрес (ваш розрахунок) | F4: VLAN | G4: Назва VLAN | H4: Мережа | I4: Префікс (число) | J4: Шлюз | K4: Корисних адрес | L4: Перевірка
A5: KASA | B5: Каси | C5: =SUMIF('В01 Пристрої'!$E$5:$E$25,A5,'В01 Пристрої'!$C$5:$C$25) -> 0 | D5: 20 | K5: =IF(OR(I5="",NOT(ISNUMBER(I5))),"",2^(32-I5)-2) | N5: =IF(C5=0,0,ROUNDUP(ROUND(C5*(1+D5/100),6),0)+1) -> 0 | O5: =IF(N5=0,"",32-MAX(2,ROUNDUP(LOG(N5+2,2)-0.000001,0))) | P5: =IFERROR(VALUE(LEFT(H5,FIND(".",H5)-1)),-1) -> -1 | Q5: =IFERROR(VALUE(MID(H5,FIND(".",H5)+1,FIND("#",SUBSTITUTE(H5,".","#",2))-FIND(".",H5)-1)),-1) -> -1 | R5: =IFERROR(VALUE(MID(H5,FIND("#",SUBSTITUTE(H5,".","#",2))+1,FIND("#",SUBSTITUTE(H5,".","#",3))-FIND("#",SUBSTITUTE(H5,".","#",2))-1)),-1) -> -1 | S5: =IFERROR(VALUE(MID(H5,FIND("#",SUBSTITUTE(H5,".","#",3))+1,3)),-1) -> -1 | T5: =IFERROR(VALUE(MID(J5,FIND("#",SUBSTITUTE(J5,".","#",3))+1,3)),-1) -> -1 | U5: =IF(IFERROR(LEFT(H5,FIND("#",SUBSTITUTE(H5,".","#",3))),"")=IFERROR(LEFT(J5,FIND("#",SUBSTITUTE(J5,".","#",3))),""),1,0) -> 1
A6: MANAGERS | B6: Менеджери | C6: =SUMIF('В01 Пристрої'!$E$5:$E$25,A6,'В01 Пристрої'!$C$5:$C$25) -> 0 | D6: 20 | K6: =IF(OR(I6="",NOT(ISNUMBER(I6))),"",2^(32-I6)-2) | N6: =IF(C6=0,0,ROUNDUP(ROUND(C6*(1+D6/100),6),0)+1) -> 0 | O6: =IF(N6=0,"",32-MAX(2,ROUNDUP(LOG(N6+2,2)-0.000001,0))) | P6: =IFERROR(VALUE(LEFT(H6,FIND(".",H6)-1)),-1) -> -1 | Q6: =IFERROR(VALUE(MID(H6,FIND(".",H6)+1,FIND("#",SUBSTITUTE(H6,".","#",2))-FIND(".",H6)-1)),-1) -> -1 | R6: =IFERROR(VALUE(MID(H6,FIND("#",SUBSTITUTE(H6,".","#",2))+1,FIND("#",SUBSTITUTE(H6,".","#",3))-FIND("#",SUBSTITUTE(H6,".","#",2))-1)),-1) -> -1 | S6: =IFERROR(VALUE(MID(H6,FIND("#",SUBSTITUTE(H6,".","#",3))+1,3)),-1) -> -1 | T6: =IFERROR(VALUE(MID(J6,FIND("#",SUBSTITUTE(J6,".","#",3))+1,3)),-1) -> -1 | U6: =IF(IFERROR(LEFT(H6,FIND("#",SUBSTITUTE(H6,".","#",3))),"")=IFERROR(LEFT(J6,FIND("#",SUBSTITUTE(J6,".","#",3))),""),1,0) -> 1
A7: ABS | B7: Термінали АБС | C7: =SUMIF('В01 Пристрої'!$E$5:$E$25,A7,'В01 Пристрої'!$C$5:$C$25) -> 0 | D7: 50 | K7: =IF(OR(I7="",NOT(ISNUMBER(I7))),"",2^(32-I7)-2) | N7: =IF(C7=0,0,ROUNDUP(ROUND(C7*(1+D7/100),6),0)+1) -> 0 | O7: =IF(N7=0,"",32-MAX(2,ROUNDUP(LOG(N7+2,2)-0.000001,0))) | P7: =IFERROR(VALUE(LEFT(H7,FIND(".",H7)-1)),-1) -> -1 | Q7: =IFERROR(VALUE(MID(H7,FIND(".",H7)+1,FIND("#",SUBSTITUTE(H7,".","#",2))-FIND(".",H7)-1)),-1) -> -1 | R7: =IFERROR(VALUE(MID(H7,FIND("#",SUBSTITUTE(H7,".","#",2))+1,FIND("#",SUBSTITUTE(H7,".","#",3))-FIND("#",SUBSTITUTE(H7,".","#",2))-1)),-1) -> -1 | S7: =IFERROR(VALUE(MID(H7,FIND("#",SUBSTITUTE(H7,".","#",3))+1,3)),-1) -> -1 | T7: =IFERROR(VALUE(MID(J7,FIND("#",SUBSTITUTE(J7,".","#",3))+1,3)),-1) -> -1 | U7: =IF(IFERROR(LEFT(H7,FIND("#",SUBSTITUTE(H7,".","#",3))),"")=IFERROR(LEFT(J7,FIND("#",SUBSTITUTE(J7,".","#",3))),""),1,0) -> 1
A8: ATM_POS | B8: Банкомати й POS | C8: =SUMIF('В01 Пристрої'!$E$5:$E$25,A8,'В01 Пристрої'!$C$5:$C$25) -> 0 | D8: 25 | K8: =IF(OR(I8="",NOT(ISNUMBER(I8))),"",2^(32-I8)-2) | N8: =IF(C8=0,0,ROUNDUP(ROUND(C8*(1+D8/100),6),0)+1) -> 0 | O8: =IF(N8=0,"",32-MAX(2,ROUNDUP(LOG(N8+2,2)-0.000001,0))) | P8: =IFERROR(VALUE(LEFT(H8,FIND(".",H8)-1)),-1) -> -1 | Q8: =IFERROR(VALUE(MID(H8,FIND(".",H8)+1,FIND("#",SUBSTITUTE(H8,".","#",2))-FIND(".",H8)-1)),-1) -> -1 | R8: =IFERROR(VALUE(MID(H8,FIND("#",SUBSTITUTE(H8,".","#",2))+1,FIND("#",SUBSTITUTE(H8,".","#",3))-FIND("#",SUBSTITUTE(H8,".","#",2))-1)),-1) -> -1 | S8: =IFERROR(VALUE(MID(H8,FIND("#",SUBSTITUTE(H8,".","#",3))+1,3)),-1) -> -1 | T8: =IFERROR(VALUE(MID(J8,FIND("#",SUBSTITUTE(J8,".","#",3))+1,3)),-1) -> -1 | U8: =IF(IFERROR(LEFT(H8,FIND("#",SUBSTITUTE(H8,".","#",3))),"")=IFERROR(LEFT(J8,FIND("#",SUBSTITUTE(J8,".","#",3))),""),1,0) -> 1
A9: IOT | B9: Інтернет речей | C9: =SUMIF('В01 Пристрої'!$E$5:$E$25,A9,'В01 Пристрої'!$C$5:$C$25) -> 0 | D9: 100 | K9: =IF(OR(I9="",NOT(ISNUMBER(I9))),"",2^(32-I9)-2) | N9: =IF(C9=0,0,ROUNDUP(ROUND(C9*(1+D9/100),6),0)+1) -> 0 | O9: =IF(N9=0,"",32-MAX(2,ROUNDUP(LOG(N9+2,2)-0.000001,0))) | P9: =IFERROR(VALUE(LEFT(H9,FIND(".",H9)-1)),-1) -> -1 | Q9: =IFERROR(VALUE(MID(H9,FIND(".",H9)+1,FIND("#",SUBSTITUTE(H9,".","#",2))-FIND(".",H9)-1)),-1) -> -1 | R9: =IFERROR(VALUE(MID(H9,FIND("#",SUBSTITUTE(H9,".","#",2))+1,FIND("#",SUBSTITUTE(H9,".","#",3))-FIND("#",SUBSTITUTE(H9,".","#",2))-1)),-1) -> -1 | S9: =IFERROR(VALUE(MID(H9,FIND("#",SUBSTITUTE(H9,".","#",3))+1,3)),-1) -> -1 | T9: =IFERROR(VALUE(MID(J9,FIND("#",SUBSTITUTE(J9,".","#",3))+1,3)),-1) -> -1 | U9: =IF(IFERROR(LEFT(H9,FIND("#",SUBSTITUTE(H9,".","#",3))),"")=IFERROR(LEFT(J9,FIND("#",SUBSTITUTE(J9,".","#",3))),""),1,0) -> 1
A10: GUEST | B10: Гостьова Wi-Fi | C10: =SUMIF('В01 Пристрої'!$E$5:$E$25,A10,'В01 Пристрої'!$C$5:$C$25) -> 0 | D10: 50 | K10: =IF(OR(I10="",NOT(ISNUMBER(I10))),"",2^(32-I10)-2) | N10: =IF(C10=0,0,ROUNDUP(ROUND(C10*(1+D10/100),6),0)+1) -> 0 | O10: =IF(N10=0,"",32-MAX(2,ROUNDUP(LOG(N10+2,2)-0.000001,0))) | P10: =IFERROR(VALUE(LEFT(H10,FIND(".",H10)-1)),-1) -> -1 | Q10: =IFERROR(VALUE(MID(H10,FIND(".",H10)+1,FIND("#",SUBSTITUTE(H10,".","#",2))-FIND(".",H10)-1)),-1) -> -1 | R10: =IFERROR(VALUE(MID(H10,FIND("#",SUBSTITUTE(H10,".","#",2))+1,FIND("#",SUBSTITUTE(H10,".","#",3))-FIND("#",SUBSTITUTE(H10,".","#",2))-1)),-1) -> -1 | S10: =IFERROR(VALUE(MID(H10,FIND("#",SUBSTITUTE(H10,".","#",3))+1,3)),-1) -> -1 | T10: =IFERROR(VALUE(MID(J10,FIND("#",SUBSTITUTE(J10,".","#",3))+1,3)),-1) -> -1 | U10: =IF(IFERROR(LEFT(H10,FIND("#",SUBSTITUTE(H10,".","#",3))),"")=IFERROR(LEFT(J10,FIND("#",SUBSTITUTE(J10,".","#",3))),""),1,0) -> 1
A11: MGMT | B11: Керування обладнанням | C11: =SUMIF('В01 Пристрої'!$E$5:$E$25,A11,'В01 Пристрої'!$C$5:$C$25) -> 0 | D11: 20 | K11: =IF(OR(I11="",NOT(ISNUMBER(I11))),"",2^(32-I11)-2) | N11: =IF(C11=0,0,ROUNDUP(ROUND(C11*(1+D11/100),6),0)+1) -> 0 | O11: =IF(N11=0,"",32-MAX(2,ROUNDUP(LOG(N11+2,2)-0.000001,0))) | P11: =IFERROR(VALUE(LEFT(H11,FIND(".",H11)-1)),-1) -> -1 | Q11: =IFERROR(VALUE(MID(H11,FIND(".",H11)+1,FIND("#",SUBSTITUTE(H11,".","#",2))-FIND(".",H11)-1)),-1) -> -1 | R11: =IFERROR(VALUE(MID(H11,FIND("#",SUBSTITUTE(H11,".","#",2))+1,FIND("#",SUBSTITUTE(H11,".","#",3))-FIND("#",SUBSTITUTE(H11,".","#",2))-1)),-1) -> -1 | S11: =IFERROR(VALUE(MID(H11,FIND("#",SUBSTITUTE(H11,".","#",3))+1,3)),-1) -> -1 | T11: =IFERROR(VALUE(MID(J11,FIND("#",SUBSTITUTE(J11,".","#",3))+1,3)),-1) -> -1 | U11: =IF(IFERROR(LEFT(H11,FIND("#",SUBSTITUTE(H11,".","#",3))),"")=IFERROR(LEFT(J11,FIND("#",SUBSTITUTE(J11,".","#",3))),""),1,0) -> 1
A12: NEW1 | C12: =SUMIF('В01 Пристрої'!$E$5:$E$25,A12,'В01 Пристрої'!$C$5:$C$25) -> 0 | K12: =IF(OR(I12="",NOT(ISNUMBER(I12))),"",2^(32-I12)-2) | N12: =IF(C12=0,0,ROUNDUP(ROUND(C12*(1+D12/100),6),0)+1) -> 0 | O12: =IF(N12=0,"",32-MAX(2,ROUNDUP(LOG(N12+2,2)-0.000001,0))) | P12: =IFERROR(VALUE(LEFT(H12,FIND(".",H12)-1)),-1) -> -1 | Q12: =IFERROR(VALUE(MID(H12,FIND(".",H12)+1,FIND("#",SUBSTITUTE(H12,".","#",2))-FIND(".",H12)-1)),-1) -> -1 | R12: =IFERROR(VALUE(MID(H12,FIND("#",SUBSTITUTE(H12,".","#",2))+1,FIND("#",SUBSTITUTE(H12,".","#",3))-FIND("#",SUBSTITUTE(H12,".","#",2))-1)),-1) -> -1 | S12: =IFERROR(VALUE(MID(H12,FIND("#",SUBSTITUTE(H12,".","#",3))+1,3)),-1) -> -1 | T12: =IFERROR(VALUE(MID(J12,FIND("#",SUBSTITUTE(J12,".","#",3))+1,3)),-1) -> -1 | U12: =IF(IFERROR(LEFT(H12,FIND("#",SUBSTITUTE(H12,".","#",3))),"")=IFERROR(LEFT(J12,FIND("#",SUBSTITUTE(J12,".","#",3))),""),1,0) -> 1
A13: NEW2 | C13: =SUMIF('В01 Пристрої'!$E$5:$E$25,A13,'В01 Пристрої'!$C$5:$C$25) -> 0 | K13: =IF(OR(I13="",NOT(ISNUMBER(I13))),"",2^(32-I13)-2) | N13: =IF(C13=0,0,ROUNDUP(ROUND(C13*(1+D13/100),6),0)+1) -> 0 | O13: =IF(N13=0,"",32-MAX(2,ROUNDUP(LOG(N13+2,2)-0.000001,0))) | P13: =IFERROR(VALUE(LEFT(H13,FIND(".",H13)-1)),-1) -> -1 | Q13: =IFERROR(VALUE(MID(H13,FIND(".",H13)+1,FIND("#",SUBSTITUTE(H13,".","#",2))-FIND(".",H13)-1)),-1) -> -1 | R13: =IFERROR(VALUE(MID(H13,FIND("#",SUBSTITUTE(H13,".","#",2))+1,FIND("#",SUBSTITUTE(H13,".","#",3))-FIND("#",SUBSTITUTE(H13,".","#",2))-1)),-1) -> -1 | S13: =IFERROR(VALUE(MID(H13,FIND("#",SUBSTITUTE(H13,".","#",3))+1,3)),-1) -> -1 | T13: =IFERROR(VALUE(MID(J13,FIND("#",SUBSTITUTE(J13,".","#",3))+1,3)),-1) -> -1 | U13: =IF(IFERROR(LEFT(H13,FIND("#",SUBSTITUTE(H13,".","#",3))),"")=IFERROR(LEFT(J13,FIND("#",SUBSTITUTE(J13,".","#",3))),""),1,0) -> 1
B16: Обмеження головного офісу (заповніть лише якщо воно є в «Новій обставині»)
B17: Зарезервовані VLAN: від
B18: Зарезервовані VLAN: до
B20: Native VLAN (власний номер) | L20: =IF(C20="","заповніть native VLAN",IF(NOT(AND(ISNUMBER(C20),C20>=2,C20<=254,C20=INT(C20))),"ціле число від 2 до 254",IF(COUNTIF($F$5:$F$13,C20)>0,"native VLAN не має збігатися з VLAN зони",IF(AND(C17<>"",C18<>"",C20>=C17,C20<=C18),"native VLAN у зарезервованому діапазоні","ОК")))) -> заповніть native VLAN

Sheet В01 Підсумок
A1: Підсумок і самоперевірка
A2: Усе має бути нульовим перед здачею. Файл показує кількість, а не місце помилки: шукайте самі.
A4: Усього пристроїв | B4: =SUM('В01 Пристрої'!C5:C25) -> 82
A5: Груп пристроїв без зони | B5: =COUNTIFS('В01 Пристрої'!C5:C25,">0",'В01 Пристрої'!E5:E25,"") -> 16
A6: Груп, де тип пристрою не відповідає зоні | B6: =COUNTIF('В01 Пристрої'!F5:F25,"тип*") -> 0
A7: Зон із помилкою в адресній таблиці | B7: =COUNTIFS('В01 Зони й адреси'!L5:L13,"<>ОК",'В01 Зони й адреси'!C5:C13,">0") -> 0
A8: Помилка native VLAN (1 — є) | B8: =IF('В01 Зони й адреси'!L20="ОК",0,1) -> 1
A9: Особливих пристроїв без пояснення вибору | B9: =MAX(0,COUNTIF('В01 Пристрої'!D5:D25,"потребує рішення")-COUNTA('В01 Обґрунтування'!C5:C12)) -> 2
A10: Знайдено помилок у чернетці колеги (з 3) | B10: =COUNTA('В01 Чернетка колеги'!A15:A17) -> 0
A11: Висновок | B11: =IF(AND(B5=0,B6=0,B7=0,B8=0,B9=0,B10>=3),"Можна здавати","Є що виправити") -> Є що виправити

Sheet В01 Обґрунтування
A1: Обґрунтування
A2: Своїми словами. Для особливих пристроїв: яку зону обрали і що було б, якби пристрій поклали в іншу.
A4: Пристрій, що потребував рішення | B4: Зона | C4: Чому саме так (2–3 речення)
A5: Мережевий принтер, спільний для кас і менеджерів
A6: Інформаційні екрани й електронна черга в залі
A15: Як ви нумерували VLAN і чому схема лишиться зрозумілою через рік?
A18: Нова обставина: що змінилось (було → стало) і чому решту зон ви не чіпали?
A21: Що ви знайшли під час самоперевірки й виправили до здачі?

Sheet В02 Інструкція
A1: ПР 3. Проєкт мережі відділення: зони, VLAN, адреси. Варіант 02
A2: Працюйте в жовтих комірках. Сірі комірки рахуються самі (захищені). Схему зон малюйте в PowerPoint-файлі варіанта.
A4: Порядок роботи
A5: 1. Зони (питання 1) | B5: На аркуші «Пристрої» для кожної групи пристроїв оберіть зону. Колонка «Перевірка» підкаже, якщо тип пристрою не відповідає зоні. Для пристроїв «потребує рішення» вирішуйте самі й поясніть вибір на аркуші «Обґрунтування».
A6: 2. Підмережі (питання 2) | B6: На аркуші «Зони й адреси» для кожної зони порахуйте, скільки адрес потрібно з запасом на зростання, оберіть префікс (від /24 до /30) і VLAN. Рахуйте на папері або в калькуляторі: файл лише перевіряє результат.
A7: 3. Адресна таблиця (питання 3) | B7: Запишіть адресу мережі й шлюз кожної зони, native VLAN. Колонка «Перевірка» має показувати «ОК» для всіх зон.
A8: 4. Чернетка колеги | B8: На аркуші «Чернетка колеги» знайдіть три помилки й запишіть у журнал. До свого проєкту їх не переносьте.
A9: 5. Нова обставина | B9: Коли завершите кроки 1–3, відкрийте окремий файл «Нова обставина» (не раніше). Оновіть таблицю й схему на другому слайді PowerPoint.
A10: 6. Обґрунтування і здача | B10: Заповніть аркуш «Обґрунтування», перевірте аркуш «Підсумок» і здайте два файли (Excel і PowerPoint).
A12: Формула запасу | B12: Потрібно адрес = пристроїв зараз × (1 + зростання за рік) + 1 адреса під шлюз, результат округлюється вгору.
A13: Місткість підмережі | B13: У підмережі /n корисних адрес 2^(32−n) − 2 (адреса мережі й адреса розсилки не видаються пристроям).
A14: Правило адрес | B14: Усе відділення використовує блок 10.A.0.0/16 (ваше A на аркуші «Картка»). Кожна зона має адресу вигляду 10.A.<VLAN>.x: третій октет дорівнює номеру VLAN.
A15: Правило VLAN | B15: Номер від 2 до 254; не 1; між номерами сусідніх зон лишайте проміжок не менше 5, щоб додавати зони без перенумерації. Native VLAN теж окремий номер, не збігається з VLAN зон.
A16: Шлюз | B16: Шлюз беріть за правилом варіанта (перша або остання корисна адреса підмережі).

Sheet В02 Картка
A1: Картка варіанта 02
A3: Студент (прізвище)
A4: Блок адрес відділення | B4: 10.178.0.0/16
A5: Значення A (другий октет) | B5: 178
A6: Правило шлюзу | B6: остання корисна адреса підмережі (перед адресою розсилки)
A7: Особливі пристрої (потребують вашого рішення) | B7: Ноутбуки підрядників, що налаштовують обладнання (2 шт.); Термінал самообслуговування в залі (приймає картки) (1 шт.)
A8: Зростання за рік, % | B8: Каси 10 · Менеджери 20 · Термінали АБС 30 · Банкомати й POS 30 · Інтернет речей 50 · Гостьова Wi-Fi 50 · Керування обладнанням 25
A10: Легенда відділення
A11: 12 співробітників; два банкомати (один усередині, один на вулиці); POS-термінали; камери, електронні замки, датчики серверної; гостьова Wi-Fi; зв'язок з головним офісом через Інтернет. Усе описано в групах пристроїв на аркуші «Пристрої».

Sheet В02 Пристрої
A1: Пристрої відділення
A2: Для кожної групи оберіть зону. Нижні п'ять рядків (21–25) призначені для нової обставини.
H3: Типи пристроїв і зони
A4: № | B4: Пристрій | C4: Кількість | D4: Тип | E4: Зона (оберіть) | F4: Перевірка | H4: Тип | I4: Зона
A5: 1 | B5: Робочі місця кас | C5: 4 | D5: каса | F5: =IF(C5="","",IF(D5="","вкажіть тип",IF(E5="","призначте зону",IF(D5="потребує рішення","рішення поясніть на аркуші «Обґрунтування»",IF(IFERROR(VLOOKUP(D5,$H$5:$I$11,2,FALSE),"?")=E5,"ОК","тип пристрою не відповідає зоні"))))) -> призначте зону | H5: каса | I5: KASA
A6: 2 | B6: Принтери й сканери кас | C6: 2 | D6: каса | F6: =IF(C6="","",IF(D6="","вкажіть тип",IF(E6="","призначте зону",IF(D6="потребує рішення","рішення поясніть на аркуші «Обґрунтування»",IF(IFERROR(VLOOKUP(D6,$H$5:$I$11,2,FALSE),"?")=E6,"ОК","тип пристрою не відповідає зоні"))))) -> призначте зону | H6: менеджер | I6: MANAGERS
A7: 3 | B7: Робочі місця менеджерів і керівника | C7: 5 | D7: менеджер | F7: =IF(C7="","",IF(D7="","вкажіть тип",IF(E7="","призначте зону",IF(D7="потребує рішення","рішення поясніть на аркуші «Обґрунтування»",IF(IFERROR(VLOOKUP(D7,$H$5:$I$11,2,FALSE),"?")=E7,"ОК","тип пристрою не відповідає зоні"))))) -> призначте зону | H7: АБС | I7: ABS
A8: 4 | B8: Термінали АБС (операціоніст) | C8: 3 | D8: АБС | F8: =IF(C8="","",IF(D8="","вкажіть тип",IF(E8="","призначте зону",IF(D8="потребує рішення","рішення поясніть на аркуші «Обґрунтування»",IF(IFERROR(VLOOKUP(D8,$H$5:$I$11,2,FALSE),"?")=E8,"ОК","тип пристрою не відповідає зоні"))))) -> призначте зону | H8: платіжний пристрій | I8: ATM_POS
A9: 5 | B9: Банкомати (всередині й на вулиці) | C9: 2 | D9: платіжний пристрій | F9: =IF(C9="","",IF(D9="","вкажіть тип",IF(E9="","призначте зону",IF(D9="потребує рішення","рішення поясніть на аркуші «Обґрунтування»",IF(IFERROR(VLOOKUP(D9,$H$5:$I$11,2,FALSE),"?")=E9,"ОК","тип пристрою не відповідає зоні"))))) -> призначте зону | H9: без користувача | I9: IOT
A10: 6 | B10: POS-термінали | C10: 6 | D10: платіжний пристрій | F10: =IF(C10="","",IF(D10="","вкажіть тип",IF(E10="","призначте зону",IF(D10="потребує рішення","рішення поясніть на аркуші «Обґрунтування»",IF(IFERROR(VLOOKUP(D10,$H$5:$I$11,2,FALSE),"?")=E10,"ОК","тип пристрою не відповідає зоні"))))) -> призначте зону | H10: клієнтські пристрої | I10: GUEST
A11: 7 | B11: Камери відеоспостереження | C11: 10 | D11: без користувача | F11: =IF(C11="","",IF(D11="","вкажіть тип",IF(E11="","призначте зону",IF(D11="потребує рішення","рішення поясніть на аркуші «Обґрунтування»",IF(IFERROR(VLOOKUP(D11,$H$5:$I$11,2,FALSE),"?")=E11,"ОК","тип пристрою не відповідає зоні"))))) -> призначте зону | H11: мережеве обладнання | I11: MGMT
A12: 8 | B12: Контролери електронних замків | C12: 4 | D12: без користувача | F12: =IF(C12="","",IF(D12="","вкажіть тип",IF(E12="","призначте зону",IF(D12="потребує рішення","рішення поясніть на аркуші «Обґрунтування»",IF(IFERROR(VLOOKUP(D12,$H$5:$I$11,2,FALSE),"?")=E12,"ОК","тип пристрою не відповідає зоні"))))) -> призначте зону | H12: «потребує рішення»: зону обираєте самі
A13: 9 | B13: Датчики температури й диму в серверній | C13: 3 | D13: без користувача | F13: =IF(C13="","",IF(D13="","вкажіть тип",IF(E13="","призначте зону",IF(D13="потребує рішення","рішення поясніть на аркуші «Обґрунтування»",IF(IFERROR(VLOOKUP(D13,$H$5:$I$11,2,FALSE),"?")=E13,"ОК","тип пристрою не відповідає зоні"))))) -> призначте зону
A14: 10 | B14: Пристрої гостей Wi-Fi (одночасно) | C14: 60 | D14: клієнтські пристрої | F14: =IF(C14="","",IF(D14="","вкажіть тип",IF(E14="","призначте зону",IF(D14="потребує рішення","рішення поясніть на аркуші «Обґрунтування»",IF(IFERROR(VLOOKUP(D14,$H$5:$I$11,2,FALSE),"?")=E14,"ОК","тип пристрою не відповідає зоні"))))) -> призначте зону
A15: 11 | B15: Комутатори | C15: 2 | D15: мережеве обладнання | F15: =IF(C15="","",IF(D15="","вкажіть тип",IF(E15="","призначте зону",IF(D15="потребує рішення","рішення поясніть на аркуші «Обґрунтування»",IF(IFERROR(VLOOKUP(D15,$H$5:$I$11,2,FALSE),"?")=E15,"ОК","тип пристрою не відповідає зоні"))))) -> призначте зону
A16: 12 | B16: Точки доступу Wi-Fi | C16: 3 | D16: мережеве обладнання | F16: =IF(C16="","",IF(D16="","вкажіть тип",IF(E16="","призначте зону",IF(D16="потребує рішення","рішення поясніть на аркуші «Обґрунтування»",IF(IFERROR(VLOOKUP(D16,$H$5:$I$11,2,FALSE),"?")=E16,"ОК","тип пристрою не відповідає зоні"))))) -> призначте зону
A17: 13 | B17: Маршрутизатор і міжмережевий екран | C17: 2 | D17: мережеве обладнання | F17: =IF(C17="","",IF(D17="","вкажіть тип",IF(E17="","призначте зону",IF(D17="потребує рішення","рішення поясніть на аркуші «Обґрунтування»",IF(IFERROR(VLOOKUP(D17,$H$5:$I$11,2,FALSE),"?")=E17,"ОК","тип пристрою не відповідає зоні"))))) -> призначте зону
A18: 14 | B18: Станція адміністратора | C18: 1 | D18: мережеве обладнання | F18: =IF(C18="","",IF(D18="","вкажіть тип",IF(E18="","призначте зону",IF(D18="потребує рішення","рішення поясніть на аркуші «Обґрунтування»",IF(IFERROR(VLOOKUP(D18,$H$5:$I$11,2,FALSE),"?")=E18,"ОК","тип пристрою не відповідає зоні"))))) -> призначте зону
A19: 15 | B19: Ноутбуки підрядників, що налаштовують обладнання | C19: 2 | D19: потребує рішення | F19: =IF(C19="","",IF(D19="","вкажіть тип",IF(E19="","призначте зону",IF(D19="потребує рішення","рішення поясніть на аркуші «Обґрунтування»",IF(IFERROR(VLOOKUP(D19,$H$5:$I$11,2,FALSE),"?")=E19,"ОК","тип пристрою не відповідає зоні"))))) -> призначте зону
A20: 16 | B20: Термінал самообслуговування в залі (приймає картки) | C20: 1 | D20: потребує рішення | F20: =IF(C20="","",IF(D20="","вкажіть тип",IF(E20="","призначте зону",IF(D20="потребує рішення","рішення поясніть на аркуші «Обґрунтування»",IF(IFERROR(VLOOKUP(D20,$H$5:$I$11,2,FALSE),"?")=E20,"ОК","тип пристрою не відповідає зоні"))))) -> призначте зону
A21: 17 | F21: =IF(C21="","",IF(D21="","вкажіть тип",IF(E21="","призначте зону",IF(D21="потребує рішення","рішення поясніть на аркуші «Обґрунтування»",IF(IFERROR(VLOOKUP(D21,$H$5:$I$11,2,FALSE),"?")=E21,"ОК","тип пристрою не відповідає зоні")))))
A22: 18 | F22: =IF(C22="","",IF(D22="","вкажіть тип",IF(E22="","призначте зону",IF(D22="потребує рішення","рішення поясніть на аркуші «Обґрунтування»",IF(IFERROR(VLOOKUP(D22,$H$5:$I$11,2,FALSE),"?")=E22,"ОК","тип пристрою не відповідає зоні")))))
A23: 19 | F23: =IF(C23="","",IF(D23="","вкажіть тип",IF(E23="","призначте зону",IF(D23="потребує рішення","рішення поясніть на аркуші «Обґрунтування»",IF(IFERROR(VLOOKUP(D23,$H$5:$I$11,2,FALSE),"?")=E23,"ОК","тип пристрою не відповідає зоні")))))
A24: 20 | F24: =IF(C24="","",IF(D24="","вкажіть тип",IF(E24="","призначте зону",IF(D24="потребує рішення","рішення поясніть на аркуші «Обґрунтування»",IF(IFERROR(VLOOKUP(D24,$H$5:$I$11,2,FALSE),"?")=E24,"ОК","тип пристрою не відповідає зоні")))))
A25: 21 | F25: =IF(C25="","",IF(D25="","вкажіть тип",IF(E25="","призначте зону",IF(D25="потребує рішення","рішення поясніть на аркуші «Обґрунтування»",IF(IFERROR(VLOOKUP(D25,$H$5:$I$11,2,FALSE),"?")=E25,"ОК","тип пристрою не відповідає зоні")))))

Sheet В02 Чернетка колеги
A1: Чернетка адресної таблиці від колеги
A2: У ній три помилки. Знайдіть їх, запишіть у журнал і не переносьте у свій проєкт. Кількість адрес колега порахував правильно.
A4: № | B4: Зона | C4: Потрібно адрес | D4: VLAN | E4: Мережа | F4: Префікс | G4: Шлюз
A5: 1 | B5: Каси | C5: 8 | D5: 100 | E5: 10.178.120.0 | F5: /29 | G5: 10.178.120.6
A6: 2 | B6: Менеджери | C6: 7 | D6: 110 | E6: 10.178.110.0 | F6: /28 | G6: 10.178.110.14
A7: 3 | B7: Термінали АБС | C7: 5 | D7: 120 | E7: 10.178.120.0 | F7: /29 | G7: 10.178.120.6
A8: 4 | B8: Банкомати й POS | C8: 13 | D8: 1 | E8: 10.178.1.0 | F8: /28 | G8: 10.178.1.14
A9: 5 | B9: Інтернет речей | C9: 27 | D9: 140 | E9: 10.178.140.0 | F9: /27 | G9: 10.178.140.30
A10: 6 | B10: Гостьова Wi-Fi | C10: 94 | D10: 150 | E10: 10.178.150.64 | F10: /25 | G10: 10.178.150.65
A11: 7 | B11: Керування обладнанням | C11: 11 | D11: 160 | E11: 10.178.160.0 | F11: /28 | G11: 10.178.160.14
A13: Журнал виправлень
A14: Рядок | B14: Тип помилки | C14: Що не так і як виправити

Sheet В02 Зони й адреси
A1: Зони, VLAN і адресна таблиця
A2: Рядки NEW1 і NEW2 потрібні лише для нової обставини. Колонка «Перевірка» підказує, що виправити.
A4: Код зони | B4: Назва зони | C4: Пристроїв зараз | D4: Зростання за рік, % | E4: Потрібно адрес (ваш розрахунок) | F4: VLAN | G4: Назва VLAN | H4: Мережа | I4: Префікс (число) | J4: Шлюз | K4: Корисних адрес | L4: Перевірка
A5: KASA | B5: Каси | C5: =SUMIF('В02 Пристрої'!$E$5:$E$25,A5,'В02 Пристрої'!$C$5:$C$25) -> 0 | D5: 10 | K5: =IF(OR(I5="",NOT(ISNUMBER(I5))),"",2^(32-I5)-2) | N5: =IF(C5=0,0,ROUNDUP(ROUND(C5*(1+D5/100),6),0)+1) -> 0 | O5: =IF(N5=0,"",32-MAX(2,ROUNDUP(LOG(N5+2,2)-0.000001,0))) | P5: =IFERROR(VALUE(LEFT(H5,FIND(".",H5)-1)),-1) -> -1 | Q5: =IFERROR(VALUE(MID(H5,FIND(".",H5)+1,FIND("#",SUBSTITUTE(H5,".","#",2))-FIND(".",H5)-1)),-1) -> -1 | R5: =IFERROR(VALUE(MID(H5,FIND("#",SUBSTITUTE(H5,".","#",2))+1,FIND("#",SUBSTITUTE(H5,".","#",3))-FIND("#",SUBSTITUTE(H5,".","#",2))-1)),-1) -> -1 | S5: =IFERROR(VALUE(MID(H5,FIND("#",SUBSTITUTE(H5,".","#",3))+1,3)),-1) -> -1 | T5: =IFERROR(VALUE(MID(J5,FIND("#",SUBSTITUTE(J5,".","#",3))+1,3)),-1) -> -1 | U5: =IF(IFERROR(LEFT(H5,FIND("#",SUBSTITUTE(H5,".","#",3))),"")=IFERROR(LEFT(J5,FIND("#",SUBSTITUTE(J5,".","#",3))),""),1,0) -> 1
A6: MANAGERS | B6: Менеджери | C6: =SUMIF('В02 Пристрої'!$E$5:$E$25,A6,'В02 Пристрої'!$C$5:$C$25) -> 0 | D6: 20 | K6: =IF(OR(I6="",NOT(ISNUMBER(I6))),"",2^(32-I6)-2) | N6: =IF(C6=0,0,ROUNDUP(ROUND(C6*(1+D6/100),6),0)+1) -> 0 | O6: =IF(N6=0,"",32-MAX(2,ROUNDUP(LOG(N6+2,2)-0.000001,0))) | P6: =IFERROR(VALUE(LEFT(H6,FIND(".",H6)-1)),-1) -> -1 | Q6: =IFERROR(VALUE(MID(H6,FIND(".",H6)+1,FIND("#",SUBSTITUTE(H6,".","#",2))-FIND(".",H6)-1)),-1) -> -1 | R6: =IFERROR(VALUE(MID(H6,FIND("#",SUBSTITUTE(H6,".","#",2))+1,FIND("#",SUBSTITUTE(H6,".","#",3))-FIND("#",SUBSTITUTE(H6,".","#",2))-1)),-1) -> -1 | S6: =IFERROR(VALUE(MID(H6,FIND("#",SUBSTITUTE(H6,".","#",3))+1,3)),-1) -> -1 | T6: =IFERROR(VALUE(MID(J6,FIND("#",SUBSTITUTE(J6,".","#",3))+1,3)),-1) -> -1 | U6: =IF(IFERROR(LEFT(H6,FIND("#",SUBSTITUTE(H6,".","#",3))),"")=IFERROR(LEFT(J6,FIND("#",SUBSTITUTE(J6,".","#",3))),""),1,0) -> 1
A7: ABS | B7: Термінали АБС | C7: =SUMIF('В02 Пристрої'!$E$5:$E$25,A7,'В02 Пристрої'!$C$5:$C$25) -> 0 | D7: 30 | K7: =IF(OR(I7="",NOT(ISNUMBER(I7))),"",2^(32-I7)-2) | N7: =IF(C7=0,0,ROUNDUP(ROUND(C7*(1+D7/100),6),0)+1) -> 0 | O7: =IF(N7=0,"",32-MAX(2,ROUNDUP(LOG(N7+2,2)-0.000001,0))) | P7: =IFERROR(VALUE(LEFT(H7,FIND(".",H7)-1)),-1) -> -1 | Q7: =IFERROR(VALUE(MID(H7,FIND(".",H7)+1,FIND("#",SUBSTITUTE(H7,".","#",2))-FIND(".",H7)-1)),-1) -> -1 | R7: =IFERROR(VALUE(MID(H7,FIND("#",SUBSTITUTE(H7,".","#",2))+1,FIND("#",SUBSTITUTE(H7,".","#",3))-FIND("#",SUBSTITUTE(H7,".","#",2))-1)),-1) -> -1 | S7: =IFERROR(VALUE(MID(H7,FIND("#",SUBSTITUTE(H7,".","#",3))+1,3)),-1) -> -1 | T7: =IFERROR(VALUE(MID(J7,FIND("#",SUBSTITUTE(J7,".","#",3))+1,3)),-1) -> -1 | U7: =IF(IFERROR(LEFT(H7,FIND("#",SUBSTITUTE(H7,".","#",3))),"")=IFERROR(LEFT(J7,FIND("#",SUBSTITUTE(J7,".","#",3))),""),1,0) -> 1
A8: ATM_POS | B8: Банкомати й POS | C8: =SUMIF('В02 Пристрої'!$E$5:$E$25,A8,'В02 Пристрої'!$C$5:$C$25) -> 0 | D8: 30 | K8: =IF(OR(I8="",NOT(ISNUMBER(I8))),"",2^(32-I8)-2) | N8: =IF(C8=0,0,ROUNDUP(ROUND(C8*(1+D8/100),6),0)+1) -> 0 | O8: =IF(N8=0,"",32-MAX(2,ROUNDUP(LOG(N8+2,2)-0.000001,0))) | P8: =IFERROR(VALUE(LEFT(H8,FIND(".",H8)-1)),-1) -> -1 | Q8: =IFERROR(VALUE(MID(H8,FIND(".",H8)+1,FIND("#",SUBSTITUTE(H8,".","#",2))-FIND(".",H8)-1)),-1) -> -1 | R8: =IFERROR(VALUE(MID(H8,FIND("#",SUBSTITUTE(H8,".","#",2))+1,FIND("#",SUBSTITUTE(H8,".","#",3))-FIND("#",SUBSTITUTE(H8,".","#",2))-1)),-1) -> -1 | S8: =IFERROR(VALUE(MID(H8,FIND("#",SUBSTITUTE(H8,".","#",3))+1,3)),-1) -> -1 | T8: =IFERROR(VALUE(MID(J8,FIND("#",SUBSTITUTE(J8,".","#",3))+1,3)),-1) -> -1 | U8: =IF(IFERROR(LEFT(H8,FIND("#",SUBSTITUTE(H8,".","#",3))),"")=IFERROR(LEFT(J8,FIND("#",SUBSTITUTE(J8,".","#",3))),""),1,0) -> 1
A9: IOT | B9: Інтернет речей | C9: =SUMIF('В02 Пристрої'!$E$5:$E$25,A9,'В02 Пристрої'!$C$5:$C$25) -> 0 | D9: 50 | K9: =IF(OR(I9="",NOT(ISNUMBER(I9))),"",2^(32-I9)-2) | N9: =IF(C9=0,0,ROUNDUP(ROUND(C9*(1+D9/100),6),0)+1) -> 0 | O9: =IF(N9=0,"",32-MAX(2,ROUNDUP(LOG(N9+2,2)-0.000001,0))) | P9: =IFERROR(VALUE(LEFT(H9,FIND(".",H9)-1)),-1) -> -1 | Q9: =IFERROR(VALUE(MID(H9,FIND(".",H9)+1,FIND("#",SUBSTITUTE(H9,".","#",2))-FIND(".",H9)-1)),-1) -> -1 | R9: =IFERROR(VALUE(MID(H9,FIND("#",SUBSTITUTE(H9,".","#",2))+1,FIND("#",SUBSTITUTE(H9,".","#",3))-FIND("#",SUBSTITUTE(H9,".","#",2))-1)),-1) -> -1 | S9: =IFERROR(VALUE(MID(H9,FIND("#",SUBSTITUTE(H9,".","#",3))+1,3)),-1) -> -1 | T9: =IFERROR(VALUE(MID(J9,FIND("#",SUBSTITUTE(J9,".","#",3))+1,3)),-1) -> -1 | U9: =IF(IFERROR(LEFT(H9,FIND("#",SUBSTITUTE(H9,".","#",3))),"")=IFERROR(LEFT(J9,FIND("#",SUBSTITUTE(J9,".","#",3))),""),1,0) -> 1
A10: GUEST | B10: Гостьова Wi-Fi | C10: =SUMIF('В02 Пристрої'!$E$5:$E$25,A10,'В02 Пристрої'!$C$5:$C$25) -> 0 | D10: 50 | K10: =IF(OR(I10="",NOT(ISNUMBER(I10))),"",2^(32-I10)-2) | N10: =IF(C10=0,0,ROUNDUP(ROUND(C10*(1+D10/100),6),0)+1) -> 0 | O10: =IF(N10=0,"",32-MAX(2,ROUNDUP(LOG(N10+2,2)-0.000001,0))) | P10: =IFERROR(VALUE(LEFT(H10,FIND(".",H10)-1)),-1) -> -1 | Q10: =IFERROR(VALUE(MID(H10,FIND(".",H10)+1,FIND("#",SUBSTITUTE(H10,".","#",2))-FIND(".",H10)-1)),-1) -> -1 | R10: =IFERROR(VALUE(MID(H10,FIND("#",SUBSTITUTE(H10,".","#",2))+1,FIND("#",SUBSTITUTE(H10,".","#",3))-FIND("#",SUBSTITUTE(H10,".","#",2))-1)),-1) -> -1 | S10: =IFERROR(VALUE(MID(H10,FIND("#",SUBSTITUTE(H10,".","#",3))+1,3)),-1) -> -1 | T10: =IFERROR(VALUE(MID(J10,FIND("#",SUBSTITUTE(J10,".","#",3))+1,3)),-1) -> -1 | U10: =IF(IFERROR(LEFT(H10,FIND("#",SUBSTITUTE(H10,".","#",3))),"")=IFERROR(LEFT(J10,FIND("#",SUBSTITUTE(J10,".","#",3))),""),1,0) -> 1
A11: MGMT | B11: Керування обладнанням | C11: =SUMIF('В02 Пристрої'!$E$5:$E$25,A11,'В02 Пристрої'!$C$5:$C$25) -> 0 | D11: 25 | K11: =IF(OR(I11="",NOT(ISNUMBER(I11))),"",2^(32-I11)-2) | N11: =IF(C11=0,0,ROUNDUP(ROUND(C11*(1+D11/100),6),0)+1) -> 0 | O11: =IF(N11=0,"",32-MAX(2,ROUNDUP(LOG(N11+2,2)-0.000001,0))) | P11: =IFERROR(VALUE(LEFT(H11,FIND(".",H11)-1)),-1) -> -1 | Q11: =IFERROR(VALUE(MID(H11,FIND(".",H11)+1,FIND("#",SUBSTITUTE(H11,".","#",2))-FIND(".",H11)-1)),-1) -> -1 | R11: =IFERROR(VALUE(MID(H11,FIND("#",SUBSTITUTE(H11,".","#",2))+1,FIND("#",SUBSTITUTE(H11,".","#",3))-FIND("#",SUBSTITUTE(H11,".","#",2))-1)),-1) -> -1 | S11: =IFERROR(VALUE(MID(H11,FIND("#",SUBSTITUTE(H11,".","#",3))+1,3)),-1) -> -1 | T11: =IFERROR(VALUE(MID(J11,FIND("#",SUBSTITUTE(J11,".","#",3))+1,3)),-1) -> -1 | U11: =IF(IFERROR(LEFT(H11,FIND("#",SUBSTITUTE(H11,".","#",3))),"")=IFERROR(LEFT(J11,FIND("#",SUBSTITUTE(J11,".","#",3))),""),1,0) -> 1
A12: NEW1 | C12: =SUMIF('В02 Пристрої'!$E$5:$E$25,A12,'В02 Пристрої'!$C$5:$C$25) -> 0 | K12: =IF(OR(I12="",NOT(ISNUMBER(I12))),"",2^(32-I12)-2) | N12: =IF(C12=0,0,ROUNDUP(ROUND(C12*(1+D12/100),6),0)+1) -> 0 | O12: =IF(N12=0,"",32-MAX(2,ROUNDUP(LOG(N12+2,2)-0.000001,0))) | P12: =IFERROR(VALUE(LEFT(H12,FIND(".",H12)-1)),-1) -> -1 | Q12: =IFERROR(VALUE(MID(H12,FIND(".",H12)+1,FIND("#",SUBSTITUTE(H12,".","#",2))-FIND(".",H12)-1)),-1) -> -1 | R12: =IFERROR(VALUE(MID(H12,FIND("#",SUBSTITUTE(H12,".","#",2))+1,FIND("#",SUBSTITUTE(H12,".","#",3))-FIND("#",SUBSTITUTE(H12,".","#",2))-1)),-1) -> -1 | S12: =IFERROR(VALUE(MID(H12,FIND("#",SUBSTITUTE(H12,".","#",3))+1,3)),-1) -> -1 | T12: =IFERROR(VALUE(MID(J12,FIND("#",SUBSTITUTE(J12,".","#",3))+1,3)),-1) -> -1 | U12: =IF(IFERROR(LEFT(H12,FIND("#",SUBSTITUTE(H12,".","#",3))),"")=IFERROR(LEFT(J12,FIND("#",SUBSTITUTE(J12,".","#",3))),""),1,0) -> 1
A13: NEW2 | C13: =SUMIF('В02 Пристрої'!$E$5:$E$25,A13,'В02 Пристрої'!$C$5:$C$25) -> 0 | K13: =IF(OR(I13="",NOT(ISNUMBER(I13))),"",2^(32-I13)-2) | N13: =IF(C13=0,0,ROUNDUP(ROUND(C13*(1+D13/100),6),0)+1) -> 0 | O13: =IF(N13=0,"",32-MAX(2,ROUNDUP(LOG(N13+2,2)-0.000001,0))) | P13: =IFERROR(VALUE(LEFT(H13,FIND(".",H13)-1)),-1) -> -1 | Q13: =IFERROR(VALUE(MID(H13,FIND(".",H13)+1,FIND("#",SUBSTITUTE(H13,".","#",2))-FIND(".",H13)-1)),-1) -> -1 | R13: =IFERROR(VALUE(MID(H13,FIND("#",SUBSTITUTE(H13,".","#",2))+1,FIND("#",SUBSTITUTE(H13,".","#",3))-FIND("#",SUBSTITUTE(H13,".","#",2))-1)),-1) -> -1 | S13: =IFERROR(VALUE(MID(H13,FIND("#",SUBSTITUTE(H13,".","#",3))+1,3)),-1) -> -1 | T13: =IFERROR(VALUE(MID(J13,FIND("#",SUBSTITUTE(J13,".","#",3))+1,3)),-1) -> -1 | U13: =IF(IFERROR(LEFT(H13,FIND("#",SUBSTITUTE(H13,".","#",3))),"")=IFERROR(LEFT(J13,FIND("#",SUBSTITUTE(J13,".","#",3))),""),1,0) -> 1
B16: Обмеження головного офісу (заповніть лише якщо воно є в «Новій обставині»)
B17: Зарезервовані VLAN: від
B18: Зарезервовані VLAN: до
B20: Native VLAN (власний номер) | L20: =IF(C20="","заповніть native VLAN",IF(NOT(AND(ISNUMBER(C20),C20>=2,C20<=254,C20=INT(C20))),"ціле число від 2 до 254",IF(COUNTIF($F$5:$F$13,C20)>0,"native VLAN не має збігатися з VLAN зони",IF(AND(C17<>"",C18<>"",C20>=C17,C20<=C18),"native VLAN у зарезервованому діапазоні","ОК")))) -> заповніть native VLAN

Sheet В02 Підсумок
A1: Підсумок і самоперевірка
A2: Усе має бути нульовим перед здачею. Файл показує кількість, а не місце помилки: шукайте самі.
A4: Усього пристроїв | B4: =SUM('В02 Пристрої'!C5:C25) -> 110
A5: Груп пристроїв без зони | B5: =COUNTIFS('В02 Пристрої'!C5:C25,">0",'В02 Пристрої'!E5:E25,"") -> 16
A6: Груп, де тип пристрою не відповідає зоні | B6: =COUNTIF('В02 Пристрої'!F5:F25,"тип*") -> 0
A7: Зон із помилкою в адресній таблиці | B7: =COUNTIFS('В02 Зони й адреси'!L5:L13,"<>ОК",'В02 Зони й адреси'!C5:C13,">0") -> 0
A8: Помилка native VLAN (1 — є) | B8: =IF('В02 Зони й адреси'!L20="ОК",0,1) -> 1
A9: Особливих пристроїв без пояснення вибору | B9: =MAX(0,COUNTIF('В02 Пристрої'!D5:D25,"потребує рішення")-COUNTA('В02 Обґрунтування'!C5:C12)) -> 2
A10: Знайдено помилок у чернетці колеги (з 3) | B10: =COUNTA('В02 Чернетка колеги'!A15:A17) -> 0
A11: Висновок | B11: =IF(AND(B5=0,B6=0,B7=0,B8=0,B9=0,B10>=3),"Можна здавати","Є що виправити") -> Є що виправити

Sheet В02 Обґрунтування
A1: Обґрунтування
A2: Своїми словами. Для особливих пристроїв: яку зону обрали і що було б, якби пристрій поклали в іншу.
A4: Пристрій, що потребував рішення | B4: Зона | C4: Чому саме так (2–3 речення)
A5: Ноутбуки підрядників, що налаштовують обладнання
A6: Термінал самообслуговування в залі (приймає картки)
A15: Як ви нумерували VLAN і чому схема лишиться зрозумілою через рік?
A18: Нова обставина: що змінилось (було → стало) і чому решту зон ви не чіпали?
A21: Що ви знайшли під час самоперевірки й виправили до здачі?

Sheet В03 Інструкція
A1: ПР 3. Проєкт мережі відділення: зони, VLAN, адреси. Варіант 03
A2: Працюйте в жовтих комірках. Сірі комірки рахуються самі (захищені). Схему зон малюйте в PowerPoint-файлі варіанта.
A4: Порядок роботи
A5: 1. Зони (питання 1) | B5: На аркуші «Пристрої» для кожної групи пристроїв оберіть зону. Колонка «Перевірка» підкаже, якщо тип пристрою не відповідає зоні. Для пристроїв «потребує рішення» вирішуйте самі й поясніть вибір на аркуші «Обґрунтування».
A6: 2. Підмережі (питання 2) | B6: На аркуші «Зони й адреси» для кожної зони порахуйте, скільки адрес потрібно з запасом на зростання, оберіть префікс (від /24 до /30) і VLAN. Рахуйте на папері або в калькуляторі: файл лише перевіряє результат.
A7: 3. Адресна таблиця (питання 3) | B7: Запишіть адресу мережі й шлюз кожної зони, native VLAN. Колонка «Перевірка» має показувати «ОК» для всіх зон.
A8: 4. Чернетка колеги | B8: На аркуші «Чернетка колеги» знайдіть три помилки й запишіть у журнал. До свого проєкту їх не переносьте.
A9: 5. Нова обставина | B9: Коли завершите кроки 1–3, відкрийте окремий файл «Нова обставина» (не раніше). Оновіть таблицю й схему на другому слайді PowerPoint.
A10: 6. Обґрунтування і здача | B10: Заповніть аркуш «Обґрунтування», перевірте аркуш «Підсумок» і здайте два файли (Excel і PowerPoint).
A12: Формула запасу | B12: Потрібно адрес = пристроїв зараз × (1 + зростання за рік) + 1 адреса під шлюз, результат округлюється вгору.
A13: Місткість підмережі | B13: У підмережі /n корисних адрес 2^(32−n) − 2 (адреса мережі й адреса розсилки не видаються пристроям).
A14: Правило адрес | B14: Усе відділення використовує блок 10.A.0.0/16 (ваше A на аркуші «Картка»). Кожна зона має адресу вигляду 10.A.<VLAN>.x: третій октет дорівнює номеру VLAN.
A15: Правило VLAN | B15: Номер від 2 до 254; не 1; між номерами сусідніх зон лишайте проміжок не менше 5, щоб додавати зони без перенумерації. Native VLAN теж окремий номер, не збігається з VLAN зон.
A16: Шлюз | B16: Шлюз беріть за правилом варіанта (перша або остання корисна адреса підмережі).

Sheet В03 Картка
A1: Картка варіанта 03
A3: Студент (прізвище)
A4: Блок адрес відділення | B4: 10.45.0.0/16
A5: Значення A (другий октет) | B5: 45
A6: Правило шлюзу | B6: перша адреса підмережі
A7: Особливі пристрої (потребують вашого рішення) | B7: IP-телефони співробітників (8 шт.); Мережевий сейф з електронним замком і сигналізацією (1 шт.)
A8: Зростання за рік, % | B8: Каси 20 · Менеджери 20 · Термінали АБС 25 · Банкомати й POS 20 · Інтернет речей 30 · Гостьова Wi-Fi 40 · Керування обладнанням 20
A10: Легенда відділення
A11: 12 співробітників; два банкомати (один усередині, один на вулиці); POS-термінали; камери, електронні замки, датчики серверної; гостьова Wi-Fi; зв'язок з головним офісом через Інтернет. Усе описано в групах пристроїв на аркуші «Пристрої».

Sheet В03 Пристрої
A1: Пристрої відділення
A2: Для кожної групи оберіть зону. Нижні п'ять рядків (21–25) призначені для нової обставини.
H3: Типи пристроїв і зони
A4: № | B4: Пристрій | C4: Кількість | D4: Тип | E4: Зона (оберіть) | F4: Перевірка | H4: Тип | I4: Зона
A5: 1 | B5: Робочі місця кас | C5: 5 | D5: каса | F5: =IF(C5="","",IF(D5="","вкажіть тип",IF(E5="","призначте зону",IF(D5="потребує рішення","рішення поясніть на аркуші «Обґрунтування»",IF(IFERROR(VLOOKUP(D5,$H$5:$I$11,2,FALSE),"?")=E5,"ОК","тип пристрою не відповідає зоні"))))) -> призначте зону | H5: каса | I5: KASA
A6: 2 | B6: Принтери й сканери кас | C6: 1 | D6: каса | F6: =IF(C6="","",IF(D6="","вкажіть тип",IF(E6="","призначте зону",IF(D6="потребує рішення","рішення поясніть на аркуші «Обґрунтування»",IF(IFERROR(VLOOKUP(D6,$H$5:$I$11,2,FALSE),"?")=E6,"ОК","тип пристрою не відповідає зоні"))))) -> призначте зону | H6: менеджер | I6: MANAGERS
A7: 3 | B7: Робочі місця менеджерів і керівника | C7: 6 | D7: менеджер | F7: =IF(C7="","",IF(D7="","вкажіть тип",IF(E7="","призначте зону",IF(D7="потребує рішення","рішення поясніть на аркуші «Обґрунтування»",IF(IFERROR(VLOOKUP(D7,$H$5:$I$11,2,FALSE),"?")=E7,"ОК","тип пристрою не відповідає зоні"))))) -> призначте зону | H7: АБС | I7: ABS
A8: 4 | B8: Термінали АБС (операціоніст) | C8: 4 | D8: АБС | F8: =IF(C8="","",IF(D8="","вкажіть тип",IF(E8="","призначте зону",IF(D8="потребує рішення","рішення поясніть на аркуші «Обґрунтування»",IF(IFERROR(VLOOKUP(D8,$H$5:$I$11,2,FALSE),"?")=E8,"ОК","тип пристрою не відповідає зоні"))))) -> призначте зону | H8: платіжний пристрій | I8: ATM_POS
A9: 5 | B9: Банкомати (всередині й на вулиці) | C9: 2 | D9: платіжний пристрій | F9: =IF(C9="","",IF(D9="","вкажіть тип",IF(E9="","призначте зону",IF(D9="потребує рішення","рішення поясніть на аркуші «Обґрунтування»",IF(IFERROR(VLOOKUP(D9,$H$5:$I$11,2,FALSE),"?")=E9,"ОК","тип пристрою не відповідає зоні"))))) -> призначте зону | H9: без користувача | I9: IOT
A10: 6 | B10: POS-термінали | C10: 8 | D10: платіжний пристрій | F10: =IF(C10="","",IF(D10="","вкажіть тип",IF(E10="","призначте зону",IF(D10="потребує рішення","рішення поясніть на аркуші «Обґрунтування»",IF(IFERROR(VLOOKUP(D10,$H$5:$I$11,2,FALSE),"?")=E10,"ОК","тип пристрою не відповідає зоні"))))) -> призначте зону | H10: клієнтські пристрої | I10: GUEST
A11: 7 | B11: Камери відеоспостереження | C11: 12 | D11: без користувача | F11: =IF(C11="","",IF(D11="","вкажіть тип",IF(E11="","призначте зону",IF(D11="потребує рішення","рішення поясніть на аркуші «Обґрунтування»",IF(IFERROR(VLOOKUP(D11,$H$5:$I$11,2,FALSE),"?")=E11,"ОК","тип пристрою не відповідає зоні"))))) -> призначте зону | H11: мережеве обладнання | I11: MGMT
A12: 8 | B12: Контролери електронних замків | C12: 5 | D12: без користувача | F12: =IF(C12="","",IF(D12="","вкажіть тип",IF(E12="","призначте зону",IF(D12="потребує рішення","рішення поясніть на аркуші «Обґрунтування»",IF(IFERROR(VLOOKUP(D12,$H$5:$I$11,2,FALSE),"?")=E12,"ОК","тип пристрою не відповідає зоні"))))) -> призначте зону | H12: «потребує рішення»: зону обираєте самі
A13: 9 | B13: Датчики температури й диму в серверній | C13: 6 | D13: без користувача | F13: =IF(C13="","",IF(D13="","вкажіть тип",IF(E13="","призначте зону",IF(D13="потребує рішення","рішення поясніть на аркуші «Обґрунтування»",IF(IFERROR(VLOOKUP(D13,$H$5:$I$11,2,FALSE),"?")=E13,"ОК","тип пристрою не відповідає зоні"))))) -> призначте зону
A14: 10 | B14: Пристрої гостей Wi-Fi (одночасно) | C14: 70 | D14: клієнтські пристрої | F14: =IF(C14="","",IF(D14="","вкажіть тип",IF(E14="","призначте зону",IF(D14="потребує рішення","рішення поясніть на аркуші «Обґрунтування»",IF(IFERROR(VLOOKUP(D14,$H$5:$I$11,2,FALSE),"?")=E14,"ОК","тип пристрою не відповідає зоні"))))) -> призначте зону
A15: 11 | B15: Комутатори | C15: 3 | D15: мережеве обладнання | F15: =IF(C15="","",IF(D15="","вкажіть тип",IF(E15="","призначте зону",IF(D15="потребує рішення","рішення поясніть на аркуші «Обґрунтування»",IF(IFERROR(VLOOKUP(D15,$H$5:$I$11,2,FALSE),"?")=E15,"ОК","тип пристрою не відповідає зоні"))))) -> призначте зону
A16: 12 | B16: Точки доступу Wi-Fi | C16: 3 | D16: мережеве обладнання | F16: =IF(C16="","",IF(D16="","вкажіть тип",IF(E16="","призначте зону",IF(D16="потребує рішення","рішення поясніть на аркуші «Обґрунтування»",IF(IFERROR(VLOOKUP(D16,$H$5:$I$11,2,FALSE),"?")=E16,"ОК","тип пристрою не відповідає зоні"))))) -> призначте зону
A17: 13 | B17: Маршрутизатор і міжмережевий екран | C17: 2 | D17: мережеве обладнання | F17: =IF(C17="","",IF(D17="","вкажіть тип",IF(E17="","призначте зону",IF(D17="потребує рішення","рішення поясніть на аркуші «Обґрунтування»",IF(IFERROR(VLOOKUP(D17,$H$5:$I$11,2,FALSE),"?")=E17,"ОК","тип пристрою не відповідає зоні"))))) -> призначте зону
A18: 14 | B18: Станція адміністратора | C18: 2 | D18: мережеве обладнання | F18: =IF(C18="","",IF(D18="","вкажіть тип",IF(E18="","призначте зону",IF(D18="потребує рішення","рішення поясніть на аркуші «Обґрунтування»",IF(IFERROR(VLOOKUP(D18,$H$5:$I$11,2,FALSE),"?")=E18,"ОК","тип пристрою не відповідає зоні"))))) -> призначте зону
A19: 15 | B19: IP-телефони співробітників | C19: 8 | D19: потребує рішення | F19: =IF(C19="","",IF(D19="","вкажіть тип",IF(E19="","призначте зону",IF(D19="потребує рішення","рішення поясніть на аркуші «Обґрунтування»",IF(IFERROR(VLOOKUP(D19,$H$5:$I$11,2,FALSE),"?")=E19,"ОК","тип пристрою не відповідає зоні"))))) -> призначте зону
A20: 16 | B20: Мережевий сейф з електронним замком і сигналізацією | C20: 1 | D20: потребує рішення | F20: =IF(C20="","",IF(D20="","вкажіть тип",IF(E20="","призначте зону",IF(D20="потребує рішення","рішення поясніть на аркуші «Обґрунтування»",IF(IFERROR(VLOOKUP(D20,$H$5:$I$11,2,FALSE),"?")=E20,"ОК","тип пристрою не відповідає зоні"))))) -> призначте зону
A21: 17 | F21: =IF(C21="","",IF(D21="","вкажіть тип",IF(E21="","призначте зону",IF(D21="потребує рішення","рішення поясніть на аркуші «Обґрунтування»",IF(IFERROR(VLOOKUP(D21,$H$5:$I$11,2,FALSE),"?")=E21,"ОК","тип пристрою не відповідає зоні")))))
A22: 18 | F22: =IF(C22="","",IF(D22="","вкажіть тип",IF(E22="","призначте зону",IF(D22="потребує рішення","рішення поясніть на аркуші «Обґрунтування»",IF(IFERROR(VLOOKUP(D22,$H$5:$I$11,2,FALSE),"?")=E22,"ОК","тип пристрою не відповідає зоні")))))
A23: 19 | F23: =IF(C23="","",IF(D23="","вкажіть тип",IF(E23="","призначте зону",IF(D23="потребує рішення","рішення поясніть на аркуші «Обґрунтування»",IF(IFERROR(VLOOKUP(D23,$H$5:$I$11,2,FALSE),"?")=E23,"ОК","тип пристрою не відповідає зоні")))))
A24: 20 | F24: =IF(C24="","",IF(D24="","вкажіть тип",IF(E24="","призначте зону",IF(D24="потребує рішення","рішення поясніть на аркуші «Обґрунтування»",IF(IFERROR(VLOOKUP(D24,$H$5:$I$11,2,FALSE),"?")=E24,"ОК","тип пристрою не відповідає зоні")))))
A25: 21 | F25: =IF(C25="","",IF(D25="","вкажіть тип",IF(E25="","призначте зону",IF(D25="потребує рішення","рішення поясніть на аркуші «Обґрунтування»",IF(IFERROR(VLOOKUP(D25,$H$5:$I$11,2,FALSE),"?")=E25,"ОК","тип пристрою не відповідає зоні")))))

Sheet В03 Чернетка колеги
A1: Чернетка адресної таблиці від колеги
A2: У ній три помилки. Знайдіть їх, запишіть у журнал і не переносьте у свій проєкт. Кількість адрес колега порахував правильно.
A4: № | B4: Зона | C4: Потрібно адрес | D4: VLAN | E4: Мережа | F4: Префікс | G4: Шлюз
A5: 1 | B5: Каси | C5: 9 | D5: 30 | E5: 10.45.30.0 | F5: /28 | G5: 10.45.30.1
A6: 2 | B6: Менеджери | C6: 18 | D6: 40 | E6: 10.45.40.0 | F6: /29 | G6: 10.45.40.1
A7: 3 | B7: Термінали АБС | C7: 6 | D7: 50 | E7: 10.45.50.0 | F7: /29 | G7: 10.45.50.1
A8: 4 | B8: Банкомати й POS | C8: 13 | D8: 60 | E8: 10.45.60.0 | F8: /28 | G8: 10.45.60.1
A9: 5 | B9: Інтернет речей | C9: 33 | D9: 70 | E9: 10.45.70.0 | F9: /26 | G9: 10.45.70.63
A10: 6 | B10: Гостьова Wi-Fi | C10: 99 | D10: 80 | E10: 10.45.80.0 | F10: /25 | G10: 10.45.80.1
A11: 7 | B11: Керування обладнанням | C11: 13 | D11: 50 | E11: 10.45.50.0 | F11: /28 | G11: 10.45.50.1
A13: Журнал виправлень
A14: Рядок | B14: Тип помилки | C14: Що не так і як виправити

Sheet В03 Зони й адреси
A1: Зони, VLAN і адресна таблиця
A2: Рядки NEW1 і NEW2 потрібні лише для нової обставини. Колонка «Перевірка» підказує, що виправити.
A4: Код зони | B4: Назва зони | C4: Пристроїв зараз | D4: Зростання за рік, % | E4: Потрібно адрес (ваш розрахунок) | F4: VLAN | G4: Назва VLAN | H4: Мережа | I4: Префікс (число) | J4: Шлюз | K4: Корисних адрес | L4: Перевірка
A5: KASA | B5: Каси | C5: =SUMIF('В03 Пристрої'!$E$5:$E$25,A5,'В03 Пристрої'!$C$5:$C$25) -> 0 | D5: 20 | K5: =IF(OR(I5="",NOT(ISNUMBER(I5))),"",2^(32-I5)-2) | N5: =IF(C5=0,0,ROUNDUP(ROUND(C5*(1+D5/100),6),0)+1) -> 0 | O5: =IF(N5=0,"",32-MAX(2,ROUNDUP(LOG(N5+2,2)-0.000001,0))) | P5: =IFERROR(VALUE(LEFT(H5,FIND(".",H5)-1)),-1) -> -1 | Q5: =IFERROR(VALUE(MID(H5,FIND(".",H5)+1,FIND("#",SUBSTITUTE(H5,".","#",2))-FIND(".",H5)-1)),-1) -> -1 | R5: =IFERROR(VALUE(MID(H5,FIND("#",SUBSTITUTE(H5,".","#",2))+1,FIND("#",SUBSTITUTE(H5,".","#",3))-FIND("#",SUBSTITUTE(H5,".","#",2))-1)),-1) -> -1 | S5: =IFERROR(VALUE(MID(H5,FIND("#",SUBSTITUTE(H5,".","#",3))+1,3)),-1) -> -1 | T5: =IFERROR(VALUE(MID(J5,FIND("#",SUBSTITUTE(J5,".","#",3))+1,3)),-1) -> -1 | U5: =IF(IFERROR(LEFT(H5,FIND("#",SUBSTITUTE(H5,".","#",3))),"")=IFERROR(LEFT(J5,FIND("#",SUBSTITUTE(J5,".","#",3))),""),1,0) -> 1
A6: MANAGERS | B6: Менеджери | C6: =SUMIF('В03 Пристрої'!$E$5:$E$25,A6,'В03 Пристрої'!$C$5:$C$25) -> 0 | D6: 20 | K6: =IF(OR(I6="",NOT(ISNUMBER(I6))),"",2^(32-I6)-2) | N6: =IF(C6=0,0,ROUNDUP(ROUND(C6*(1+D6/100),6),0)+1) -> 0 | O6: =IF(N6=0,"",32-MAX(2,ROUNDUP(LOG(N6+2,2)-0.000001,0))) | P6: =IFERROR(VALUE(LEFT(H6,FIND(".",H6)-1)),-1) -> -1 | Q6: =IFERROR(VALUE(MID(H6,FIND(".",H6)+1,FIND("#",SUBSTITUTE(H6,".","#",2))-FIND(".",H6)-1)),-1) -> -1 | R6: =IFERROR(VALUE(MID(H6,FIND("#",SUBSTITUTE(H6,".","#",2))+1,FIND("#",SUBSTITUTE(H6,".","#",3))-FIND("#",SUBSTITUTE(H6,".","#",2))-1)),-1) -> -1 | S6: =IFERROR(VALUE(MID(H6,FIND("#",SUBSTITUTE(H6,".","#",3))+1,3)),-1) -> -1 | T6: =IFERROR(VALUE(MID(J6,FIND("#",SUBSTITUTE(J6,".","#",3))+1,3)),-1) -> -1 | U6: =IF(IFERROR(LEFT(H6,FIND("#",SUBSTITUTE(H6,".","#",3))),"")=IFERROR(LEFT(J6,FIND("#",SUBSTITUTE(J6,".","#",3))),""),1,0) -> 1
A7: ABS | B7: Термінали АБС | C7: =SUMIF('В03 Пристрої'!$E$5:$E$25,A7,'В03 Пристрої'!$C$5:$C$25) -> 0 | D7: 25 | K7: =IF(OR(I7="",NOT(ISNUMBER(I7))),"",2^(32-I7)-2) | N7: =IF(C7=0,0,ROUNDUP(ROUND(C7*(1+D7/100),6),0)+1) -> 0 | O7: =IF(N7=0,"",32-MAX(2,ROUNDUP(LOG(N7+2,2)-0.000001,0))) | P7: =IFERROR(VALUE(LEFT(H7,FIND(".",H7)-1)),-1) -> -1 | Q7: =IFERROR(VALUE(MID(H7,FIND(".",H7)+1,FIND("#",SUBSTITUTE(H7,".","#",2))-FIND(".",H7)-1)),-1) -> -1 | R7: =IFERROR(VALUE(MID(H7,FIND("#",SUBSTITUTE(H7,".","#",2))+1,FIND("#",SUBSTITUTE(H7,".","#",3))-FIND("#",SUBSTITUTE(H7,".","#",2))-1)),-1) -> -1 | S7: =IFERROR(VALUE(MID(H7,FIND("#",SUBSTITUTE(H7,".","#",3))+1,3)),-1) -> -1 | T7: =IFERROR(VALUE(MID(J7,FIND("#",SUBSTITUTE(J7,".","#",3))+1,3)),-1) -> -1 | U7: =IF(IFERROR(LEFT(H7,FIND("#",SUBSTITUTE(H7,".","#",3))),"")=IFERROR(LEFT(J7,FIND("#",SUBSTITUTE(J7,".","#",3))),""),1,0) -> 1
A8: ATM_POS | B8: Банкомати й POS | C8: =SUMIF('В03 Пристрої'!$E$5:$E$25,A8,'В03 Пристрої'!$C$5:$C$25) -> 0 | D8: 20 | K8: =IF(OR(I8="",NOT(ISNUMBER(I8))),"",2^(32-I8)-2) | N8: =IF(C8=0,0,ROUNDUP(ROUND(C8*(1+D8/100),6),0)+1) -> 0 | O8: =IF(N8=0,"",32-MAX(2,ROUNDUP(LOG(N8+2,2)-0.000001,0))) | P8: =IFERROR(VALUE(LEFT(H8,FIND(".",H8)-1)),-1) -> -1 | Q8: =IFERROR(VALUE(MID(H8,FIND(".",H8)+1,FIND("#",SUBSTITUTE(H8,".","#",2))-FIND(".",H8)-1)),-1) -> -1 | R8: =IFERROR(VALUE(MID(H8,FIND("#",SUBSTITUTE(H8,".","#",2))+1,FIND("#",SUBSTITUTE(H8,".","#",3))-FIND("#",SUBSTITUTE(H8,".","#",2))-1)),-1) -> -1 | S8: =IFERROR(VALUE(MID(H8,FIND("#",SUBSTITUTE(H8,".","#",3))+1,3)),-1) -> -1 | T8: =IFERROR(VALUE(MID(J8,FIND("#",SUBSTITUTE(J8,".","#",3))+1,3)),-1) -> -1 | U8: =IF(IFERROR(LEFT(H8,FIND("#",SUBSTITUTE(H8,".","#",3))),"")=IFERROR(LEFT(J8,FIND("#",SUBSTITUTE(J8,".","#",3))),""),1,0) -> 1
A9: IOT | B9: Інтернет речей | C9: =SUMIF('В03 Пристрої'!$E$5:$E$25,A9,'В03 Пристрої'!$C$5:$C$25) -> 0 | D9: 30 | K9: =IF(OR(I9="",NOT(ISNUMBER(I9))),"",2^(32-I9)-2) | N9: =IF(C9=0,0,ROUNDUP(ROUND(C9*(1+D9/100),6),0)+1) -> 0 | O9: =IF(N9=0,"",32-MAX(2,ROUNDUP(LOG(N9+2,2)-0.000001,0))) | P9: =IFERROR(VALUE(LEFT(H9,FIND(".",H9)-1)),-1) -> -1 | Q9: =IFERROR(VALUE(MID(H9,FIND(".",H9)+1,FIND("#",SUBSTITUTE(H9,".","#",2))-FIND(".",H9)-1)),-1) -> -1 | R9: =IFERROR(VALUE(MID(H9,FIND("#",SUBSTITUTE(H9,".","#",2))+1,FIND("#",SUBSTITUTE(H9,".","#",3))-FIND("#",SUBSTITUTE(H9,".","#",2))-1)),-1) -> -1 | S9: =IFERROR(VALUE(MID(H9,FIND("#",SUBSTITUTE(H9,".","#",3))+1,3)),-1) -> -1 | T9: =IFERROR(VALUE(MID(J9,FIND("#",SUBSTITUTE(J9,".","#",3))+1,3)),-1) -> -1 | U9: =IF(IFERROR(LEFT(H9,FIND("#",SUBSTITUTE(H9,".","#",3))),"")=IFERROR(LEFT(J9,FIND("#",SUBSTITUTE(J9,".","#",3))),""),1,0) -> 1
