Workbook

Sheet Зміст
A1: Усі варіанти в одному файлі
A2: Кожен варіант має власні аркуші з префіксом «В01», «В02» тощо й свій колір вкладок. Натисніть на посилання, щоб перейти до варіанта.
A4: Варіант | B4: Перехід
A5: Варіант 01 | B5: Відкрити аркуші варіанта 01
A6: Варіант 02 | B6: Відкрити аркуші варіанта 02
A7: Варіант 03 | B7: Відкрити аркуші варіанта 03
A8: Варіант 04 | B8: Відкрити аркуші варіанта 04
A9: Варіант 05 | B9: Відкрити аркуші варіанта 05
A10: Варіант 06 | B10: Відкрити аркуші варіанта 06
A11: Варіант 07 | B11: Відкрити аркуші варіанта 07
A12: Варіант 08 | B12: Відкрити аркуші варіанта 08
A13: Варіант 09 | B13: Відкрити аркуші варіанта 09
A14: Варіант 10 | B14: Відкрити аркуші варіанта 10

Sheet В01 Інструкція
A1: ПР 2. Модель загроз: шлях платіжної картки. Варіант 01
A2: Працюйте в жовтих комірках. Сірі комірки рахуються самі (захищені). Схему малюйте у файлі PowerPoint.
A4: Порядок роботи
A5: 1. Схема (питання 1) | B5: У файлі PowerPoint домалюйте стрілки потоків, підпишіть, що передається, і проведіть межі довіри M1–M6. Межі запишіть також на аркуші «Картка».
A6: 2. Загрози (питання 2) | B6: Для кожної межі знайдіть загрози за STRIDE (≥ 12 загроз; усі шість меж і всі шість літер). Знайдіть три помилки в аркуші «Чернетка колеги».
A7: 3. Заходи (питання 3) | B7: Позначте 8 найсерйозніших загроз («Так» у «Топ-8»), оберіть захід із «Каталогу» і напишіть, де саме в мережі він працює. Якщо мережа загрозу не закриває, оберіть захід «Поза курсом» і поясніть.
A8: 4. Нова обставина | B8: Коли завершите кроки 1–3, відкрийте окремий файл «Нова обставина» (не раніше). Додайте межу M7 і ≥ 2 нові загрози з заходами, поправте схему й запишіть, що змінилось (аркуш «Обґрунтування»).
A9: 5. Обґрунтування | B9: Власними словами поясніть вибір для 2–3 загроз (аркуш «Обґрунтування»).
A11: STRIDE | B11: S — підміна (хтось видає себе за іншого) · T — зміна даних · R — відмова від дій (немає доказів, хто що зробив) · I — витік (хтось читає чуже) · D — відмова в обслуговуванні · E — підвищення прав (хтось отримує більше прав, ніж мав би)
A12: Серйозність загрози | B12: 1 — незначна: без збитків для грошей і даних карток. 2 — суттєва: обмежені збитки або тимчасова зупинка. 3 — серйозна: масова компрометація карток, значні гроші або зупинка платежів.
A13: Природа загрози | B13: мережева — закривається налаштуванням мережі; фізична — потрібен доступ до пристрою; організаційна — залежить від процедур і договорів.
A14: Перевірка заходу | B14: Лабораторний захід має діяти на вашу літеру STRIDE (див. «Каталог»). Мережевий захід не закриває фізичну загрозу. Для мережевої загрози потрібен захід з лабораторних. Для решти допустимі заходи «Поза курсом».
A15: Зв'язок із ПР 1 | B15: У колонці «Категорія ризику з ПР 1» вкажіть, до якого ризику з вашого реєстру ПР 1 належить загроза.

Sheet В01 Картка
A1: Картка варіанта 01
A3: Студент (прізвище)
A4: Точка прийому | B4: вуличний банкомат
A5: Підключення точки до мережі | B5: Ethernet-кабель, прокладений зовні будівлі
A6: Зв'язок відділення зі шлюзом | B6: звичайний Інтернет без VPN
A7: Особливий учасник | B7: підрядник інкасації: сервісний доступ до банкомата (замки, сервісний порт)
A8: Платіжний шлюз | B8: у центрі обробки; після нього АБС (головний офіс)
A9: Шлях картки | B9: клієнт → точка прийому → мережа відділення → зовнішній канал → платіжний шлюз → АБС
A11: Межі довіри на шляху: опишіть, між чим і чим проходить кожна межа
A12: На шляху шість меж довіри (M1–M6), якщо рахувати й особливого учасника. M7 з'явиться після нової обставини.
A13: M1 | C13: =A13&". "&B13
A14: M2 | C14: =A14&". "&B14
A15: M3 | C15: =A15&". "&B15
A16: M4 | C16: =A16&". "&B16
A17: M5 | C17: =A17&". "&B17
A18: M6 | C18: =A18&". "&B18
A19: M7 | C19: =A19&". "&B19

Sheet В01 Каталог
A1: Каталог заходів
A2: Лабораторні заходи вивчатимете далі в курсі. Літери показують, які типи STRIDE захід закриває. Заходи «Поза курсом» теж допустимі, але лише там, де мережа не допоможе.
A4: Код | B4: Назва заходу | C4: Тип | D4: Діє на STRIDE | E4: Лабораторна
A5: L1 | B5: ЛР1. Сегментація VLAN і маршрутизація між ними | C5: Лабораторна | D5: I E | E5: ЛР 1
A6: L2 | B6: ЛР2. Port Security на портах комутатора | C6: Лабораторна | D6: S | E6: ЛР 2
A7: L3 | B7: ЛР3. DHCP Snooping | C7: Лабораторна | D7: S T | E7: ЛР 3
A8: L4 | B8: ЛР4. Списки доступу (ACL) між зонами | C8: Лабораторна | D8: E I T | E8: ЛР 4
A9: L5 | B9: ЛР5. Міжмережевий екран ASA: зони й NAT | C9: Лабораторна | D9: E I S | E9: ЛР 5
A10: L6 | B10: ЛР6. DMZ для вебсайту й ДБО | C10: Лабораторна | D10: E I | E10: ЛР 6
A11: L7 | B11: ЛР7. IPsec VPN між відділенням і головним офісом | C11: Лабораторна | D11: S T I | E11: ЛР 7
A12: L8 | B12: ЛР8. Окремий VLAN для пристроїв і захищена Wi-Fi (WPA2) | C12: Лабораторна | D12: S E I | E12: ЛР 8
A13: L9 | B13: ЛР9. SSH, AAA і RADIUS, ролі адміністраторів | C13: Лабораторна | D13: S E R | E13: ЛР 9
A14: L10 | B14: ЛР10. Syslog, NTP і моніторинг (лише виявляє) | C14: Лабораторна | D14: R D | E14: ЛР 10
A15: O1 | B15: Поза курсом: навчання й інструктаж персоналу | C15: Поза курсом | E15: —
A16: O2 | B16: Поза курсом: договір, регламент, журнал відвідувань підрядника | C16: Поза курсом | E16: —
A17: O3 | B17: Поза курсом: антискімінгові накладки, пломби, замки, огляд пристрою | C17: Поза курсом | E17: —
A18: O4 | B18: Поза курсом: резервний канал і угода про рівень обслуговування | C18: Поза курсом | E18: —
A19: O5 | B19: Поза курсом: подвійний контроль і звірка інкасації | C19: Поза курсом | E19: —

Sheet В01 Чернетка колеги
A1: Чернетка таблиці загроз від колеги
A2: У ній три помилки. Знайдіть їх, запишіть у журнал і не переносьте у свою таблицю без виправлення.
A4: № | B4: Межа | C4: STRIDE | D4: Загроза | E4: Природа | F4: Серйозність | G4: Захід
A5: 1 | B5: M4 | C5: T — зміна даних | D5: Перехоплення платіжного трафіку в каналі: зловмисник читає передані дані | E5: мережева | F5: 3 | G5: ЛР7. IPsec VPN між відділенням і головним офісом
A6: 2 | B6: M1 | C6: T — зміна даних | D6: Скімер на вуличного банкомата: копіює дані картки | E6: фізична | F6: 3 | G6: ЛР1. Сегментація VLAN і маршрутизація між ними
A7: 3 | B7: M5 | C7: R — відмова від дій | D7: Шлюз не зберігає журнал: після шахрайства неможливо відновити послідовність подій | E7: мережева | F7: 2 | G7: ЛР10. Syslog, NTP і моніторинг (лише виявляє)
A8: 4 | B8: M1 | C8: R — відмова від дій | D8: Клієнт заперечує операцію, а повного журналу з точним часом немає | E8: організаційна | F8: 2 | G8: ЛР10. Syslog, NTP і моніторинг (лише виявляє)
A9: 5 | B9: M2 | C9: T — зміна даних | D9: Підробний DHCP-сервер видає терміналу чужий шлюз і перехоплює платіжний трафік | E9: мережева | F9: 2 | G9: ЛР3. DHCP Snooping
A10: 6 | B10: M3 | C10: T — зміна даних | D10: Встановити IPsec VPN і міжмережевий екран між відділенням і шлюзом | E10: мережева | F10: 3 | G10: ЛР7. IPsec VPN між відділенням і головним офісом
A11: 7 | B11: M5 | C11: S — підміна | D11: Підроблений запит до АБС від зламаного шлюзу чи від ПК відділення | E11: мережева | F11: 3 | G11: ЛР5. Міжмережевий екран ASA: зони й NAT
A13: Журнал виправлень
A14: Рядок | B14: Тип помилки | C14: Що не так і як виправити

Sheet В01 Загрози і заходи
A1: Загрози за STRIDE і заходи (питання 2 і 3)
A2: Один рядок: межа + літера STRIDE + загроза. Топ-8: для кожної обов'язково захід і де в мережі.
A4: № | B4: Межа довіри | C4: Що передається чи що під загрозою | D4: STRIDE | E4: Загроза: хто, що робить, що втрачаємо | F4: Природа | G4: Серйозність 1–3 | H4: Категорія ризику з ПР 1 | I4: Топ-8 | J4: Захід (з Каталогу) | K4: Де в мережі: пристрій, зона, що налаштувати | L4: Перевірка | M4: Лабораторна | N4: Тип заходу | O4: Примітка
A5: 1 | L5: =IF(I5<>"Так","",IF(J5="","Оберіть захід",IF(K5="","Вкажіть, де в мережі",IF(D5="","Оберіть літеру STRIDE",IF(F5="","Вкажіть природу",IF(AND(INDEX('В01 Каталог'!$C$5:$C$19,MATCH(J5,'В01 Каталог'!$B$5:$B$19,0))="Лабораторна",F5="фізична",INDEX('В01 Каталог'!$A$5:$A$19,MATCH(J5,'В01 Каталог'!$B$5:$B$19,0))<>"L10"),"Мережевий захід не закриває фізичну загрозу",IF(AND(INDEX('В01 Каталог'!$C$5:$C$19,MATCH(J5,'В01 Каталог'!$B$5:$B$19,0))="Лабораторна",ISERROR(SEARCH(LEFT(D5,1),INDEX('В01 Каталог'!$D$5:$D$19,MATCH(J5,'В01 Каталог'!$B$5:$B$19,0))))),"Захід не діє на цей тип загрози",IF(AND(INDEX('В01 Каталог'!$C$5:$C$19,MATCH(J5,'В01 Каталог'!$B$5:$B$19,0))="Поза курсом",F5="мережева"),"Для мережевої загрози потрібен захід з лабораторних","ОК")))))))) | M5: =IF(J5="","",IFERROR(INDEX('В01 Каталог'!$E$5:$E$19,MATCH(J5,'В01 Каталог'!$B$5:$B$19,0)),"")) | N5: =IF(J5="","",IFERROR(INDEX('В01 Каталог'!$C$5:$C$19,MATCH(J5,'В01 Каталог'!$B$5:$B$19,0)),""))
A6: 2 | L6: =IF(I6<>"Так","",IF(J6="","Оберіть захід",IF(K6="","Вкажіть, де в мережі",IF(D6="","Оберіть літеру STRIDE",IF(F6="","Вкажіть природу",IF(AND(INDEX('В01 Каталог'!$C$5:$C$19,MATCH(J6,'В01 Каталог'!$B$5:$B$19,0))="Лабораторна",F6="фізична",INDEX('В01 Каталог'!$A$5:$A$19,MATCH(J6,'В01 Каталог'!$B$5:$B$19,0))<>"L10"),"Мережевий захід не закриває фізичну загрозу",IF(AND(INDEX('В01 Каталог'!$C$5:$C$19,MATCH(J6,'В01 Каталог'!$B$5:$B$19,0))="Лабораторна",ISERROR(SEARCH(LEFT(D6,1),INDEX('В01 Каталог'!$D$5:$D$19,MATCH(J6,'В01 Каталог'!$B$5:$B$19,0))))),"Захід не діє на цей тип загрози",IF(AND(INDEX('В01 Каталог'!$C$5:$C$19,MATCH(J6,'В01 Каталог'!$B$5:$B$19,0))="Поза курсом",F6="мережева"),"Для мережевої загрози потрібен захід з лабораторних","ОК")))))))) | M6: =IF(J6="","",IFERROR(INDEX('В01 Каталог'!$E$5:$E$19,MATCH(J6,'В01 Каталог'!$B$5:$B$19,0)),"")) | N6: =IF(J6="","",IFERROR(INDEX('В01 Каталог'!$C$5:$C$19,MATCH(J6,'В01 Каталог'!$B$5:$B$19,0)),""))
A7: 3 | L7: =IF(I7<>"Так","",IF(J7="","Оберіть захід",IF(K7="","Вкажіть, де в мережі",IF(D7="","Оберіть літеру STRIDE",IF(F7="","Вкажіть природу",IF(AND(INDEX('В01 Каталог'!$C$5:$C$19,MATCH(J7,'В01 Каталог'!$B$5:$B$19,0))="Лабораторна",F7="фізична",INDEX('В01 Каталог'!$A$5:$A$19,MATCH(J7,'В01 Каталог'!$B$5:$B$19,0))<>"L10"),"Мережевий захід не закриває фізичну загрозу",IF(AND(INDEX('В01 Каталог'!$C$5:$C$19,MATCH(J7,'В01 Каталог'!$B$5:$B$19,0))="Лабораторна",ISERROR(SEARCH(LEFT(D7,1),INDEX('В01 Каталог'!$D$5:$D$19,MATCH(J7,'В01 Каталог'!$B$5:$B$19,0))))),"Захід не діє на цей тип загрози",IF(AND(INDEX('В01 Каталог'!$C$5:$C$19,MATCH(J7,'В01 Каталог'!$B$5:$B$19,0))="Поза курсом",F7="мережева"),"Для мережевої загрози потрібен захід з лабораторних","ОК")))))))) | M7: =IF(J7="","",IFERROR(INDEX('В01 Каталог'!$E$5:$E$19,MATCH(J7,'В01 Каталог'!$B$5:$B$19,0)),"")) | N7: =IF(J7="","",IFERROR(INDEX('В01 Каталог'!$C$5:$C$19,MATCH(J7,'В01 Каталог'!$B$5:$B$19,0)),""))
A8: 4 | L8: =IF(I8<>"Так","",IF(J8="","Оберіть захід",IF(K8="","Вкажіть, де в мережі",IF(D8="","Оберіть літеру STRIDE",IF(F8="","Вкажіть природу",IF(AND(INDEX('В01 Каталог'!$C$5:$C$19,MATCH(J8,'В01 Каталог'!$B$5:$B$19,0))="Лабораторна",F8="фізична",INDEX('В01 Каталог'!$A$5:$A$19,MATCH(J8,'В01 Каталог'!$B$5:$B$19,0))<>"L10"),"Мережевий захід не закриває фізичну загрозу",IF(AND(INDEX('В01 Каталог'!$C$5:$C$19,MATCH(J8,'В01 Каталог'!$B$5:$B$19,0))="Лабораторна",ISERROR(SEARCH(LEFT(D8,1),INDEX('В01 Каталог'!$D$5:$D$19,MATCH(J8,'В01 Каталог'!$B$5:$B$19,0))))),"Захід не діє на цей тип загрози",IF(AND(INDEX('В01 Каталог'!$C$5:$C$19,MATCH(J8,'В01 Каталог'!$B$5:$B$19,0))="Поза курсом",F8="мережева"),"Для мережевої загрози потрібен захід з лабораторних","ОК")))))))) | M8: =IF(J8="","",IFERROR(INDEX('В01 Каталог'!$E$5:$E$19,MATCH(J8,'В01 Каталог'!$B$5:$B$19,0)),"")) | N8: =IF(J8="","",IFERROR(INDEX('В01 Каталог'!$C$5:$C$19,MATCH(J8,'В01 Каталог'!$B$5:$B$19,0)),""))
A9: 5 | L9: =IF(I9<>"Так","",IF(J9="","Оберіть захід",IF(K9="","Вкажіть, де в мережі",IF(D9="","Оберіть літеру STRIDE",IF(F9="","Вкажіть природу",IF(AND(INDEX('В01 Каталог'!$C$5:$C$19,MATCH(J9,'В01 Каталог'!$B$5:$B$19,0))="Лабораторна",F9="фізична",INDEX('В01 Каталог'!$A$5:$A$19,MATCH(J9,'В01 Каталог'!$B$5:$B$19,0))<>"L10"),"Мережевий захід не закриває фізичну загрозу",IF(AND(INDEX('В01 Каталог'!$C$5:$C$19,MATCH(J9,'В01 Каталог'!$B$5:$B$19,0))="Лабораторна",ISERROR(SEARCH(LEFT(D9,1),INDEX('В01 Каталог'!$D$5:$D$19,MATCH(J9,'В01 Каталог'!$B$5:$B$19,0))))),"Захід не діє на цей тип загрози",IF(AND(INDEX('В01 Каталог'!$C$5:$C$19,MATCH(J9,'В01 Каталог'!$B$5:$B$19,0))="Поза курсом",F9="мережева"),"Для мережевої загрози потрібен захід з лабораторних","ОК")))))))) | M9: =IF(J9="","",IFERROR(INDEX('В01 Каталог'!$E$5:$E$19,MATCH(J9,'В01 Каталог'!$B$5:$B$19,0)),"")) | N9: =IF(J9="","",IFERROR(INDEX('В01 Каталог'!$C$5:$C$19,MATCH(J9,'В01 Каталог'!$B$5:$B$19,0)),""))
A10: 6 | L10: =IF(I10<>"Так","",IF(J10="","Оберіть захід",IF(K10="","Вкажіть, де в мережі",IF(D10="","Оберіть літеру STRIDE",IF(F10="","Вкажіть природу",IF(AND(INDEX('В01 Каталог'!$C$5:$C$19,MATCH(J10,'В01 Каталог'!$B$5:$B$19,0))="Лабораторна",F10="фізична",INDEX('В01 Каталог'!$A$5:$A$19,MATCH(J10,'В01 Каталог'!$B$5:$B$19,0))<>"L10"),"Мережевий захід не закриває фізичну загрозу",IF(AND(INDEX('В01 Каталог'!$C$5:$C$19,MATCH(J10,'В01 Каталог'!$B$5:$B$19,0))="Лабораторна",ISERROR(SEARCH(LEFT(D10,1),INDEX('В01 Каталог'!$D$5:$D$19,MATCH(J10,'В01 Каталог'!$B$5:$B$19,0))))),"Захід не діє на цей тип загрози",IF(AND(INDEX('В01 Каталог'!$C$5:$C$19,MATCH(J10,'В01 Каталог'!$B$5:$B$19,0))="Поза курсом",F10="мережева"),"Для мережевої загрози потрібен захід з лабораторних","ОК")))))))) | M10: =IF(J10="","",IFERROR(INDEX('В01 Каталог'!$E$5:$E$19,MATCH(J10,'В01 Каталог'!$B$5:$B$19,0)),"")) | N10: =IF(J10="","",IFERROR(INDEX('В01 Каталог'!$C$5:$C$19,MATCH(J10,'В01 Каталог'!$B$5:$B$19,0)),""))
A11: 7 | L11: =IF(I11<>"Так","",IF(J11="","Оберіть захід",IF(K11="","Вкажіть, де в мережі",IF(D11="","Оберіть літеру STRIDE",IF(F11="","Вкажіть природу",IF(AND(INDEX('В01 Каталог'!$C$5:$C$19,MATCH(J11,'В01 Каталог'!$B$5:$B$19,0))="Лабораторна",F11="фізична",INDEX('В01 Каталог'!$A$5:$A$19,MATCH(J11,'В01 Каталог'!$B$5:$B$19,0))<>"L10"),"Мережевий захід не закриває фізичну загрозу",IF(AND(INDEX('В01 Каталог'!$C$5:$C$19,MATCH(J11,'В01 Каталог'!$B$5:$B$19,0))="Лабораторна",ISERROR(SEARCH(LEFT(D11,1),INDEX('В01 Каталог'!$D$5:$D$19,MATCH(J11,'В01 Каталог'!$B$5:$B$19,0))))),"Захід не діє на цей тип загрози",IF(AND(INDEX('В01 Каталог'!$C$5:$C$19,MATCH(J11,'В01 Каталог'!$B$5:$B$19,0))="Поза курсом",F11="мережева"),"Для мережевої загрози потрібен захід з лабораторних","ОК")))))))) | M11: =IF(J11="","",IFERROR(INDEX('В01 Каталог'!$E$5:$E$19,MATCH(J11,'В01 Каталог'!$B$5:$B$19,0)),"")) | N11: =IF(J11="","",IFERROR(INDEX('В01 Каталог'!$C$5:$C$19,MATCH(J11,'В01 Каталог'!$B$5:$B$19,0)),""))
A12: 8 | L12: =IF(I12<>"Так","",IF(J12="","Оберіть захід",IF(K12="","Вкажіть, де в мережі",IF(D12="","Оберіть літеру STRIDE",IF(F12="","Вкажіть природу",IF(AND(INDEX('В01 Каталог'!$C$5:$C$19,MATCH(J12,'В01 Каталог'!$B$5:$B$19,0))="Лабораторна",F12="фізична",INDEX('В01 Каталог'!$A$5:$A$19,MATCH(J12,'В01 Каталог'!$B$5:$B$19,0))<>"L10"),"Мережевий захід не закриває фізичну загрозу",IF(AND(INDEX('В01 Каталог'!$C$5:$C$19,MATCH(J12,'В01 Каталог'!$B$5:$B$19,0))="Лабораторна",ISERROR(SEARCH(LEFT(D12,1),INDEX('В01 Каталог'!$D$5:$D$19,MATCH(J12,'В01 Каталог'!$B$5:$B$19,0))))),"Захід не діє на цей тип загрози",IF(AND(INDEX('В01 Каталог'!$C$5:$C$19,MATCH(J12,'В01 Каталог'!$B$5:$B$19,0))="Поза курсом",F12="мережева"),"Для мережевої загрози потрібен захід з лабораторних","ОК")))))))) | M12: =IF(J12="","",IFERROR(INDEX('В01 Каталог'!$E$5:$E$19,MATCH(J12,'В01 Каталог'!$B$5:$B$19,0)),"")) | N12: =IF(J12="","",IFERROR(INDEX('В01 Каталог'!$C$5:$C$19,MATCH(J12,'В01 Каталог'!$B$5:$B$19,0)),""))
A13: 9 | L13: =IF(I13<>"Так","",IF(J13="","Оберіть захід",IF(K13="","Вкажіть, де в мережі",IF(D13="","Оберіть літеру STRIDE",IF(F13="","Вкажіть природу",IF(AND(INDEX('В01 Каталог'!$C$5:$C$19,MATCH(J13,'В01 Каталог'!$B$5:$B$19,0))="Лабораторна",F13="фізична",INDEX('В01 Каталог'!$A$5:$A$19,MATCH(J13,'В01 Каталог'!$B$5:$B$19,0))<>"L10"),"Мережевий захід не закриває фізичну загрозу",IF(AND(INDEX('В01 Каталог'!$C$5:$C$19,MATCH(J13,'В01 Каталог'!$B$5:$B$19,0))="Лабораторна",ISERROR(SEARCH(LEFT(D13,1),INDEX('В01 Каталог'!$D$5:$D$19,MATCH(J13,'В01 Каталог'!$B$5:$B$19,0))))),"Захід не діє на цей тип загрози",IF(AND(INDEX('В01 Каталог'!$C$5:$C$19,MATCH(J13,'В01 Каталог'!$B$5:$B$19,0))="Поза курсом",F13="мережева"),"Для мережевої загрози потрібен захід з лабораторних","ОК")))))))) | M13: =IF(J13="","",IFERROR(INDEX('В01 Каталог'!$E$5:$E$19,MATCH(J13,'В01 Каталог'!$B$5:$B$19,0)),"")) | N13: =IF(J13="","",IFERROR(INDEX('В01 Каталог'!$C$5:$C$19,MATCH(J13,'В01 Каталог'!$B$5:$B$19,0)),""))
A14: 10 | L14: =IF(I14<>"Так","",IF(J14="","Оберіть захід",IF(K14="","Вкажіть, де в мережі",IF(D14="","Оберіть літеру STRIDE",IF(F14="","Вкажіть природу",IF(AND(INDEX('В01 Каталог'!$C$5:$C$19,MATCH(J14,'В01 Каталог'!$B$5:$B$19,0))="Лабораторна",F14="фізична",INDEX('В01 Каталог'!$A$5:$A$19,MATCH(J14,'В01 Каталог'!$B$5:$B$19,0))<>"L10"),"Мережевий захід не закриває фізичну загрозу",IF(AND(INDEX('В01 Каталог'!$C$5:$C$19,MATCH(J14,'В01 Каталог'!$B$5:$B$19,0))="Лабораторна",ISERROR(SEARCH(LEFT(D14,1),INDEX('В01 Каталог'!$D$5:$D$19,MATCH(J14,'В01 Каталог'!$B$5:$B$19,0))))),"Захід не діє на цей тип загрози",IF(AND(INDEX('В01 Каталог'!$C$5:$C$19,MATCH(J14,'В01 Каталог'!$B$5:$B$19,0))="Поза курсом",F14="мережева"),"Для мережевої загрози потрібен захід з лабораторних","ОК")))))))) | M14: =IF(J14="","",IFERROR(INDEX('В01 Каталог'!$E$5:$E$19,MATCH(J14,'В01 Каталог'!$B$5:$B$19,0)),"")) | N14: =IF(J14="","",IFERROR(INDEX('В01 Каталог'!$C$5:$C$19,MATCH(J14,'В01 Каталог'!$B$5:$B$19,0)),""))
A15: 11 | L15: =IF(I15<>"Так","",IF(J15="","Оберіть захід",IF(K15="","Вкажіть, де в мережі",IF(D15="","Оберіть літеру STRIDE",IF(F15="","Вкажіть природу",IF(AND(INDEX('В01 Каталог'!$C$5:$C$19,MATCH(J15,'В01 Каталог'!$B$5:$B$19,0))="Лабораторна",F15="фізична",INDEX('В01 Каталог'!$A$5:$A$19,MATCH(J15,'В01 Каталог'!$B$5:$B$19,0))<>"L10"),"Мережевий захід не закриває фізичну загрозу",IF(AND(INDEX('В01 Каталог'!$C$5:$C$19,MATCH(J15,'В01 Каталог'!$B$5:$B$19,0))="Лабораторна",ISERROR(SEARCH(LEFT(D15,1),INDEX('В01 Каталог'!$D$5:$D$19,MATCH(J15,'В01 Каталог'!$B$5:$B$19,0))))),"Захід не діє на цей тип загрози",IF(AND(INDEX('В01 Каталог'!$C$5:$C$19,MATCH(J15,'В01 Каталог'!$B$5:$B$19,0))="Поза курсом",F15="мережева"),"Для мережевої загрози потрібен захід з лабораторних","ОК")))))))) | M15: =IF(J15="","",IFERROR(INDEX('В01 Каталог'!$E$5:$E$19,MATCH(J15,'В01 Каталог'!$B$5:$B$19,0)),"")) | N15: =IF(J15="","",IFERROR(INDEX('В01 Каталог'!$C$5:$C$19,MATCH(J15,'В01 Каталог'!$B$5:$B$19,0)),""))
A16: 12 | L16: =IF(I16<>"Так","",IF(J16="","Оберіть захід",IF(K16="","Вкажіть, де в мережі",IF(D16="","Оберіть літеру STRIDE",IF(F16="","Вкажіть природу",IF(AND(INDEX('В01 Каталог'!$C$5:$C$19,MATCH(J16,'В01 Каталог'!$B$5:$B$19,0))="Лабораторна",F16="фізична",INDEX('В01 Каталог'!$A$5:$A$19,MATCH(J16,'В01 Каталог'!$B$5:$B$19,0))<>"L10"),"Мережевий захід не закриває фізичну загрозу",IF(AND(INDEX('В01 Каталог'!$C$5:$C$19,MATCH(J16,'В01 Каталог'!$B$5:$B$19,0))="Лабораторна",ISERROR(SEARCH(LEFT(D16,1),INDEX('В01 Каталог'!$D$5:$D$19,MATCH(J16,'В01 Каталог'!$B$5:$B$19,0))))),"Захід не діє на цей тип загрози",IF(AND(INDEX('В01 Каталог'!$C$5:$C$19,MATCH(J16,'В01 Каталог'!$B$5:$B$19,0))="Поза курсом",F16="мережева"),"Для мережевої загрози потрібен захід з лабораторних","ОК")))))))) | M16: =IF(J16="","",IFERROR(INDEX('В01 Каталог'!$E$5:$E$19,MATCH(J16,'В01 Каталог'!$B$5:$B$19,0)),"")) | N16: =IF(J16="","",IFERROR(INDEX('В01 Каталог'!$C$5:$C$19,MATCH(J16,'В01 Каталог'!$B$5:$B$19,0)),""))
... A34: 30 | L34: =IF(I34<>"Так","",IF(J34="","Оберіть захід",IF(K34="","Вкажіть, де в мережі",IF(D34="","Оберіть літеру STRIDE",IF(F34="","Вкажіть природу",IF(AND(INDEX('В01 Каталог'!$C$5:$C$19,MATCH(J34,'В01 Каталог'!$B$5:$B$19,0))="Лабораторна",F34="фізична",INDEX('В01 Каталог'!$A$5:$A$19,MATCH(J34,'В01 Каталог'!$B$5:$B$19,0))<>"L10"),"Мережевий захід не закриває фізичну загрозу",IF(AND(INDEX('В01 Каталог'!$C$5:$C$19,MATCH(J34,'В01 Каталог'!$B$5:$B$19,0))="Лабораторна",ISERROR(SEARCH(LEFT(D34,1),INDEX('В01 Каталог'!$D$5:$D$19,MATCH(J34,'В01 Каталог'!$B$5:$B$19,0))))),"Захід не діє на цей тип загрози",IF(AND(INDEX('В01 Каталог'!$C$5:$C$19,MATCH(J34,'В01 Каталог'!$B$5:$B$19,0))="Поза курсом",F34="мережева"),"Для мережевої загрози потрібен захід з лабораторних","ОК")))))))) | M34: =IF(J34="","",IFERROR(INDEX('В01 Каталог'!$E$5:$E$19,MATCH(J34,'В01 Каталог'!$B$5:$B$19,0)),"")) | N34: =IF(J34="","",IFERROR(INDEX('В01 Каталог'!$C$5:$C$19,MATCH(J34,'В01 Каталог'!$B$5:$B$19,0)),""))

Sheet В01 Підсумок
A1: Підсумок і самоперевірка
A4: Загроз у таблиці | B4: =COUNTA('В01 Загрози і заходи'!E5:E34) | C4: =IF(B4>=12,"достатньо","потрібно щонайменше 12")
A5: Загроз на межі M1 | B5: =COUNTIF('В01 Загрози і заходи'!B5:B34,"M1*") | C5: =IF(B5>=1,"є","немає: поверніться до питання 2")
A6: Загроз на межі M2 | B6: =COUNTIF('В01 Загрози і заходи'!B5:B34,"M2*") | C6: =IF(B6>=1,"є","немає: поверніться до питання 2")
A7: Загроз на межі M3 | B7: =COUNTIF('В01 Загрози і заходи'!B5:B34,"M3*") | C7: =IF(B7>=1,"є","немає: поверніться до питання 2")
A8: Загроз на межі M4 | B8: =COUNTIF('В01 Загрози і заходи'!B5:B34,"M4*") | C8: =IF(B8>=1,"є","немає: поверніться до питання 2")
A9: Загроз на межі M5 | B9: =COUNTIF('В01 Загрози і заходи'!B5:B34,"M5*") | C9: =IF(B9>=1,"є","немає: поверніться до питання 2")
A10: Загроз на межі M6 | B10: =COUNTIF('В01 Загрози і заходи'!B5:B34,"M6*") | C10: =IF(B10>=1,"є","немає: поверніться до питання 2")
A11: Загроз типу S | B11: =COUNTIF('В01 Загрози і заходи'!D5:D34,"S —*") | C11: =IF(B11>=1,"є","немає: подумайте, які загрози типу S є на шляху")
A12: Загроз типу T | B12: =COUNTIF('В01 Загрози і заходи'!D5:D34,"T —*") | C12: =IF(B12>=1,"є","немає: подумайте, які загрози типу T є на шляху")
A13: Загроз типу R | B13: =COUNTIF('В01 Загрози і заходи'!D5:D34,"R —*") | C13: =IF(B13>=1,"є","немає: подумайте, які загрози типу R є на шляху")
A14: Загроз типу I | B14: =COUNTIF('В01 Загрози і заходи'!D5:D34,"I —*") | C14: =IF(B14>=1,"є","немає: подумайте, які загрози типу I є на шляху")
A15: Загроз типу D | B15: =COUNTIF('В01 Загрози і заходи'!D5:D34,"D —*") | C15: =IF(B15>=1,"є","немає: подумайте, які загрози типу D є на шляху")
A16: Загроз типу E | B16: =COUNTIF('В01 Загрози і заходи'!D5:D34,"E —*") | C16: =IF(B16>=1,"є","немає: подумайте, які загрози типу E є на шляху")
A17: Позначено «Топ-8» | B17: =COUNTIF('В01 Загрози і заходи'!I5:I34,"Так") | C17: =IF(B17=8,"рівно 8","має бути рівно 8")
A18: Топ-8: що не так у перевірці | B18: =SUMPRODUCT(('В01 Загрози і заходи'!I5:I34="Так")*('В01 Загрози і заходи'!L5:L34<>"ОК")) | C18: =IF(B18=0,"усе узгоджено","дивіться колонку «Перевірка»")
A19: З топ-8 не закриваються мережею (поза курсом) | B19: =COUNTIFS('В01 Загрози і заходи'!I5:I34,"Так",'В01 Загрози і заходи'!N5:N34,"Поза курсом") | C19: це нормально, якщо загроза фізична чи організаційна
A20: Нових загроз на межі M7 (після інжекту) | B20: =COUNTIF('В01 Загрози і заходи'!B5:B34,"M7*") | C20: =IF(B20>=2,"достатньо","потрібно щонайменше 2")

Sheet В01 Обґрунтування
A1: Обґрунтування вибору
A2: Пишіть власні пояснення для 2–3 загроз із топ-8 своїми словами (2–3 речення). Викладач може попросити пояснити їх усно.
A4: Хто (А/Б, прізвище) | B4: № загрози | C4: Чому така серйозність і чому саме ця межа | D4: Чому саме цей захід (і чому не інший), де він стоїть
A12: Нова обставина: що сказано у файлі «Нова обставина» і що саме ви змінили (межа M7, нові рядки, зміни у схемі):

Sheet В02 Інструкція
A1: ПР 2. Модель загроз: шлях платіжної картки. Варіант 02
A2: Працюйте в жовтих комірках. Сірі комірки рахуються самі (захищені). Схему малюйте у файлі PowerPoint.
A4: Порядок роботи
A5: 1. Схема (питання 1) | B5: У файлі PowerPoint домалюйте стрілки потоків, підпишіть, що передається, і проведіть межі довіри M1–M6. Межі запишіть також на аркуші «Картка».
A6: 2. Загрози (питання 2) | B6: Для кожної межі знайдіть загрози за STRIDE (≥ 12 загроз; усі шість меж і всі шість літер). Знайдіть три помилки в аркуші «Чернетка колеги».
A7: 3. Заходи (питання 3) | B7: Позначте 8 найсерйозніших загроз («Так» у «Топ-8»), оберіть захід із «Каталогу» і напишіть, де саме в мережі він працює. Якщо мережа загрозу не закриває, оберіть захід «Поза курсом» і поясніть.
A8: 4. Нова обставина | B8: Коли завершите кроки 1–3, відкрийте окремий файл «Нова обставина» (не раніше). Додайте межу M7 і ≥ 2 нові загрози з заходами, поправте схему й запишіть, що змінилось (аркуш «Обґрунтування»).
A9: 5. Обґрунтування | B9: Власними словами поясніть вибір для 2–3 загроз (аркуш «Обґрунтування»).
A11: STRIDE | B11: S — підміна (хтось видає себе за іншого) · T — зміна даних · R — відмова від дій (немає доказів, хто що зробив) · I — витік (хтось читає чуже) · D — відмова в обслуговуванні · E — підвищення прав (хтось отримує більше прав, ніж мав би)
A12: Серйозність загрози | B12: 1 — незначна: без збитків для грошей і даних карток. 2 — суттєва: обмежені збитки або тимчасова зупинка. 3 — серйозна: масова компрометація карток, значні гроші або зупинка платежів.
A13: Природа загрози | B13: мережева — закривається налаштуванням мережі; фізична — потрібен доступ до пристрою; організаційна — залежить від процедур і договорів.
A14: Перевірка заходу | B14: Лабораторний захід має діяти на вашу літеру STRIDE (див. «Каталог»). Мережевий захід не закриває фізичну загрозу. Для мережевої загрози потрібен захід з лабораторних. Для решти допустимі заходи «Поза курсом».
A15: Зв'язок із ПР 1 | B15: У колонці «Категорія ризику з ПР 1» вкажіть, до якого ризику з вашого реєстру ПР 1 належить загроза.

Sheet В02 Картка
A1: Картка варіанта 02
A3: Студент (прізвище)
A4: Точка прийому | B4: банкомат у залі обслуговування
A5: Підключення точки до мережі | B5: Ethernet-кабель усередині будівлі
A6: Зв'язок відділення зі шлюзом | B6: виділена лінія до головного офісу
A7: Особливий учасник | B7: оператор зв'язку: обладнання й канал на стороні оператора
A8: Платіжний шлюз | B8: у центрі обробки; після нього АБС (головний офіс)
A9: Шлях картки | B9: клієнт → точка прийому → мережа відділення → зовнішній канал → платіжний шлюз → АБС
A11: Межі довіри на шляху: опишіть, між чим і чим проходить кожна межа
A12: На шляху шість меж довіри (M1–M6), якщо рахувати й особливого учасника. M7 з'явиться після нової обставини.
A13: M1 | C13: =A13&". "&B13
A14: M2 | C14: =A14&". "&B14
A15: M3 | C15: =A15&". "&B15
A16: M4 | C16: =A16&". "&B16
A17: M5 | C17: =A17&". "&B17
A18: M6 | C18: =A18&". "&B18
A19: M7 | C19: =A19&". "&B19

Sheet В02 Каталог
A1: Каталог заходів
A2: Лабораторні заходи вивчатимете далі в курсі. Літери показують, які типи STRIDE захід закриває. Заходи «Поза курсом» теж допустимі, але лише там, де мережа не допоможе.
A4: Код | B4: Назва заходу | C4: Тип | D4: Діє на STRIDE | E4: Лабораторна
A5: L1 | B5: ЛР1. Сегментація VLAN і маршрутизація між ними | C5: Лабораторна | D5: I E | E5: ЛР 1
A6: L2 | B6: ЛР2. Port Security на портах комутатора | C6: Лабораторна | D6: S | E6: ЛР 2
A7: L3 | B7: ЛР3. DHCP Snooping | C7: Лабораторна | D7: S T | E7: ЛР 3
A8: L4 | B8: ЛР4. Списки доступу (ACL) між зонами | C8: Лабораторна | D8: E I T | E8: ЛР 4
A9: L5 | B9: ЛР5. Міжмережевий екран ASA: зони й NAT | C9: Лабораторна | D9: E I S | E9: ЛР 5
A10: L6 | B10: ЛР6. DMZ для вебсайту й ДБО | C10: Лабораторна | D10: E I | E10: ЛР 6
A11: L7 | B11: ЛР7. IPsec VPN між відділенням і головним офісом | C11: Лабораторна | D11: S T I | E11: ЛР 7
A12: L8 | B12: ЛР8. Окремий VLAN для пристроїв і захищена Wi-Fi (WPA2) | C12: Лабораторна | D12: S E I | E12: ЛР 8
A13: L9 | B13: ЛР9. SSH, AAA і RADIUS, ролі адміністраторів | C13: Лабораторна | D13: S E R | E13: ЛР 9
A14: L10 | B14: ЛР10. Syslog, NTP і моніторинг (лише виявляє) | C14: Лабораторна | D14: R D | E14: ЛР 10
A15: O1 | B15: Поза курсом: навчання й інструктаж персоналу | C15: Поза курсом | E15: —
A16: O2 | B16: Поза курсом: договір, регламент, журнал відвідувань підрядника | C16: Поза курсом | E16: —
A17: O3 | B17: Поза курсом: антискімінгові накладки, пломби, замки, огляд пристрою | C17: Поза курсом | E17: —
A18: O4 | B18: Поза курсом: резервний канал і угода про рівень обслуговування | C18: Поза курсом | E18: —
A19: O5 | B19: Поза курсом: подвійний контроль і звірка інкасації | C19: Поза курсом | E19: —

Sheet В02 Чернетка колеги
A1: Чернетка таблиці загроз від колеги
A2: У ній три помилки. Знайдіть їх, запишіть у журнал і не переносьте у свою таблицю без виправлення.
A4: № | B4: Межа | C4: STRIDE | D4: Загроза | E4: Природа | F4: Серйозність | G4: Захід
A5: 1 | B5: M1 | C5: R — відмова від дій | D5: Клієнт заперечує операцію, а повного журналу з точним часом немає | E5: організаційна | F5: 2 | G5: ЛР10. Syslog, NTP і моніторинг (лише виявляє)
A6: 2 | B6: M2 | C6: T — зміна даних | D6: Підробний DHCP-сервер видає терміналу чужий шлюз і перехоплює платіжний трафік | E6: мережева | F6: 2 | G6: ЛР3. DHCP Snooping
A7: 3 | B7: M3 | C7: T — зміна даних | D7: Встановити IPsec VPN і міжмережевий екран між відділенням і шлюзом | E7: мережева | F7: 3 | G7: ЛР7. IPsec VPN між відділенням і головним офісом
A8: 4 | B8: M5 | C8: S — підміна | D8: Підроблений запит до АБС від зламаного шлюзу чи від ПК відділення | E8: мережева | F8: 3 | G8: ЛР5. Міжмережевий екран ASA: зони й NAT
A9: 5 | B9: M4 | C9: T — зміна даних | D9: Перехоплення платіжного трафіку в каналі: зловмисник читає передані дані | E9: мережева | F9: 3 | G9: ЛР7. IPsec VPN між відділенням і головним офісом
A10: 6 | B10: M1 | C10: T — зміна даних | D10: Скімер на банкомата в залі: копіює дані картки | E10: фізична | F10: 3 | G10: ЛР1. Сегментація VLAN і маршрутизація між ними
A11: 7 | B11: M5 | C11: R — відмова від дій | D11: Шлюз не зберігає журнал: після шахрайства неможливо відновити послідовність подій | E11: мережева | F11: 2 | G11: ЛР10. Syslog, NTP і моніторинг (лише виявляє)
A13: Журнал виправлень
A14: Рядок | B14: Тип помилки | C14: Що не так і як виправити

Sheet В02 Загрози і заходи
A1: Загрози за STRIDE і заходи (питання 2 і 3)
A2: Один рядок: межа + літера STRIDE + загроза. Топ-8: для кожної обов'язково захід і де в мережі.
A4: № | B4: Межа довіри | C4: Що передається чи що під загрозою | D4: STRIDE | E4: Загроза: хто, що робить, що втрачаємо | F4: Природа | G4: Серйозність 1–3 | H4: Категорія ризику з ПР 1 | I4: Топ-8 | J4: Захід (з Каталогу) | K4: Де в мережі: пристрій, зона, що налаштувати | L4: Перевірка | M4: Лабораторна | N4: Тип заходу | O4: Примітка
A5: 1 | L5: =IF(I5<>"Так","",IF(J5="","Оберіть захід",IF(K5="","Вкажіть, де в мережі",IF(D5="","Оберіть літеру STRIDE",IF(F5="","Вкажіть природу",IF(AND(INDEX('В02 Каталог'!$C$5:$C$19,MATCH(J5,'В02 Каталог'!$B$5:$B$19,0))="Лабораторна",F5="фізична",INDEX('В02 Каталог'!$A$5:$A$19,MATCH(J5,'В02 Каталог'!$B$5:$B$19,0))<>"L10"),"Мережевий захід не закриває фізичну загрозу",IF(AND(INDEX('В02 Каталог'!$C$5:$C$19,MATCH(J5,'В02 Каталог'!$B$5:$B$19,0))="Лабораторна",ISERROR(SEARCH(LEFT(D5,1),INDEX('В02 Каталог'!$D$5:$D$19,MATCH(J5,'В02 Каталог'!$B$5:$B$19,0))))),"Захід не діє на цей тип загрози",IF(AND(INDEX('В02 Каталог'!$C$5:$C$19,MATCH(J5,'В02 Каталог'!$B$5:$B$19,0))="Поза курсом",F5="мережева"),"Для мережевої загрози потрібен захід з лабораторних","ОК")))))))) | M5: =IF(J5="","",IFERROR(INDEX('В02 Каталог'!$E$5:$E$19,MATCH(J5,'В02 Каталог'!$B$5:$B$19,0)),"")) | N5: =IF(J5="","",IFERROR(INDEX('В02 Каталог'!$C$5:$C$19,MATCH(J5,'В02 Каталог'!$B$5:$B$19,0)),""))
A6: 2 | L6: =IF(I6<>"Так","",IF(J6="","Оберіть захід",IF(K6="","Вкажіть, де в мережі",IF(D6="","Оберіть літеру STRIDE",IF(F6="","Вкажіть природу",IF(AND(INDEX('В02 Каталог'!$C$5:$C$19,MATCH(J6,'В02 Каталог'!$B$5:$B$19,0))="Лабораторна",F6="фізична",INDEX('В02 Каталог'!$A$5:$A$19,MATCH(J6,'В02 Каталог'!$B$5:$B$19,0))<>"L10"),"Мережевий захід не закриває фізичну загрозу",IF(AND(INDEX('В02 Каталог'!$C$5:$C$19,MATCH(J6,'В02 Каталог'!$B$5:$B$19,0))="Лабораторна",ISERROR(SEARCH(LEFT(D6,1),INDEX('В02 Каталог'!$D$5:$D$19,MATCH(J6,'В02 Каталог'!$B$5:$B$19,0))))),"Захід не діє на цей тип загрози",IF(AND(INDEX('В02 Каталог'!$C$5:$C$19,MATCH(J6,'В02 Каталог'!$B$5:$B$19,0))="Поза курсом",F6="мережева"),"Для мережевої загрози потрібен захід з лабораторних","ОК")))))))) | M6: =IF(J6="","",IFERROR(INDEX('В02 Каталог'!$E$5:$E$19,MATCH(J6,'В02 Каталог'!$B$5:$B$19,0)),"")) | N6: =IF(J6="","",IFERROR(INDEX('В02 Каталог'!$C$5:$C$19,MATCH(J6,'В02 Каталог'!$B$5:$B$19,0)),""))
A7: 3 | L7: =IF(I7<>"Так","",IF(J7="","Оберіть захід",IF(K7="","Вкажіть, де в мережі",IF(D7="","Оберіть літеру STRIDE",IF(F7="","Вкажіть природу",IF(AND(INDEX('В02 Каталог'!$C$5:$C$19,MATCH(J7,'В02 Каталог'!$B$5:$B$19,0))="Лабораторна",F7="фізична",INDEX('В02 Каталог'!$A$5:$A$19,MATCH(J7,'В02 Каталог'!$B$5:$B$19,0))<>"L10"),"Мережевий захід не закриває фізичну загрозу",IF(AND(INDEX('В02 Каталог'!$C$5:$C$19,MATCH(J7,'В02 Каталог'!$B$5:$B$19,0))="Лабораторна",ISERROR(SEARCH(LEFT(D7,1),INDEX('В02 Каталог'!$D$5:$D$19,MATCH(J7,'В02 Каталог'!$B$5:$B$19,0))))),"Захід не діє на цей тип загрози",IF(AND(INDEX('В02 Каталог'!$C$5:$C$19,MATCH(J7,'В02 Каталог'!$B$5:$B$19,0))="Поза курсом",F7="мережева"),"Для мережевої загрози потрібен захід з лабораторних","ОК")))))))) | M7: =IF(J7="","",IFERROR(INDEX('В02 Каталог'!$E$5:$E$19,MATCH(J7,'В02 Каталог'!$B$5:$B$19,0)),"")) | N7: =IF(J7="","",IFERROR(INDEX('В02 Каталог'!$C$5:$C$19,MATCH(J7,'В02 Каталог'!$B$5:$B$19,0)),""))
A8: 4 | L8: =IF(I8<>"Так","",IF(J8="","Оберіть захід",IF(K8="","Вкажіть, де в мережі",IF(D8="","Оберіть літеру STRIDE",IF(F8="","Вкажіть природу",IF(AND(INDEX('В02 Каталог'!$C$5:$C$19,MATCH(J8,'В02 Каталог'!$B$5:$B$19,0))="Лабораторна",F8="фізична",INDEX('В02 Каталог'!$A$5:$A$19,MATCH(J8,'В02 Каталог'!$B$5:$B$19,0))<>"L10"),"Мережевий захід не закриває фізичну загрозу",IF(AND(INDEX('В02 Каталог'!$C$5:$C$19,MATCH(J8,'В02 Каталог'!$B$5:$B$19,0))="Лабораторна",ISERROR(SEARCH(LEFT(D8,1),INDEX('В02 Каталог'!$D$5:$D$19,MATCH(J8,'В02 Каталог'!$B$5:$B$19,0))))),"Захід не діє на цей тип загрози",IF(AND(INDEX('В02 Каталог'!$C$5:$C$19,MATCH(J8,'В02 Каталог'!$B$5:$B$19,0))="Поза курсом",F8="мережева"),"Для мережевої загрози потрібен захід з лабораторних","ОК")))))))) | M8: =IF(J8="","",IFERROR(INDEX('В02 Каталог'!$E$5:$E$19,MATCH(J8,'В02 Каталог'!$B$5:$B$19,0)),"")) | N8: =IF(J8="","",IFERROR(INDEX('В02 Каталог'!$C$5:$C$19,MATCH(J8,'В02 Каталог'!$B$5:$B$19,0)),""))
A9: 5 | L9: =IF(I9<>"Так","",IF(J9="","Оберіть захід",IF(K9="","Вкажіть, де в мережі",IF(D9="","Оберіть літеру STRIDE",IF(F9="","Вкажіть природу",IF(AND(INDEX('В02 Каталог'!$C$5:$C$19,MATCH(J9,'В02 Каталог'!$B$5:$B$19,0))="Лабораторна",F9="фізична",INDEX('В02 Каталог'!$A$5:$A$19,MATCH(J9,'В02 Каталог'!$B$5:$B$19,0))<>"L10"),"Мережевий захід не закриває фізичну загрозу",IF(AND(INDEX('В02 Каталог'!$C$5:$C$19,MATCH(J9,'В02 Каталог'!$B$5:$B$19,0))="Лабораторна",ISERROR(SEARCH(LEFT(D9,1),INDEX('В02 Каталог'!$D$5:$D$19,MATCH(J9,'В02 Каталог'!$B$5:$B$19,0))))),"Захід не діє на цей тип загрози",IF(AND(INDEX('В02 Каталог'!$C$5:$C$19,MATCH(J9,'В02 Каталог'!$B$5:$B$19,0))="Поза курсом",F9="мережева"),"Для мережевої загрози потрібен захід з лабораторних","ОК")))))))) | M9: =IF(J9="","",IFERROR(INDEX('В02 Каталог'!$E$5:$E$19,MATCH(J9,'В02 Каталог'!$B$5:$B$19,0)),"")) | N9: =IF(J9="","",IFERROR(INDEX('В02 Каталог'!$C$5:$C$19,MATCH(J9,'В02 Каталог'!$B$5:$B$19,0)),""))
A10: 6 | L10: =IF(I10<>"Так","",IF(J10="","Оберіть захід",IF(K10="","Вкажіть, де в мережі",IF(D10="","Оберіть літеру STRIDE",IF(F10="","Вкажіть природу",IF(AND(INDEX('В02 Каталог'!$C$5:$C$19,MATCH(J10,'В02 Каталог'!$B$5:$B$19,0))="Лабораторна",F10="фізична",INDEX('В02 Каталог'!$A$5:$A$19,MATCH(J10,'В02 Каталог'!$B$5:$B$19,0))<>"L10"),"Мережевий захід не закриває фізичну загрозу",IF(AND(INDEX('В02 Каталог'!$C$5:$C$19,MATCH(J10,'В02 Каталог'!$B$5:$B$19,0))="Лабораторна",ISERROR(SEARCH(LEFT(D10,1),INDEX('В02 Каталог'!$D$5:$D$19,MATCH(J10,'В02 Каталог'!$B$5:$B$19,0))))),"Захід не діє на цей тип загрози",IF(AND(INDEX('В02 Каталог'!$C$5:$C$19,MATCH(J10,'В02 Каталог'!$B$5:$B$19,0))="Поза курсом",F10="мережева"),"Для мережевої загрози потрібен захід з лабораторних","ОК")))))))) | M10: =IF(J10="","",IFERROR(INDEX('В02 Каталог'!$E$5:$E$19,MATCH(J10,'В02 Каталог'!$B$5:$B$19,0)),"")) | N10: =IF(J10="","",IFERROR(INDEX('В02 Каталог'!$C$5:$C$19,MATCH(J10,'В02 Каталог'!$B$5:$B$19,0)),""))
A11: 7 | L11: =IF(I11<>"Так","",IF(J11="","Оберіть захід",IF(K11="","Вкажіть, де в мережі",IF(D11="","Оберіть літеру STRIDE",IF(F11="","Вкажіть природу",IF(AND(INDEX('В02 Каталог'!$C$5:$C$19,MATCH(J11,'В02 Каталог'!$B$5:$B$19,0))="Лабораторна",F11="фізична",INDEX('В02 Каталог'!$A$5:$A$19,MATCH(J11,'В02 Каталог'!$B$5:$B$19,0))<>"L10"),"Мережевий захід не закриває фізичну загрозу",IF(AND(INDEX('В02 Каталог'!$C$5:$C$19,MATCH(J11,'В02 Каталог'!$B$5:$B$19,0))="Лабораторна",ISERROR(SEARCH(LEFT(D11,1),INDEX('В02 Каталог'!$D$5:$D$19,MATCH(J11,'В02 Каталог'!$B$5:$B$19,0))))),"Захід не діє на цей тип загрози",IF(AND(INDEX('В02 Каталог'!$C$5:$C$19,MATCH(J11,'В02 Каталог'!$B$5:$B$19,0))="Поза курсом",F11="мережева"),"Для мережевої загрози потрібен захід з лабораторних","ОК")))))))) | M11: =IF(J11="","",IFERROR(INDEX('В02 Каталог'!$E$5:$E$19,MATCH(J11,'В02 Каталог'!$B$5:$B$19,0)),"")) | N11: =IF(J11="","",IFERROR(INDEX('В02 Каталог'!$C$5:$C$19,MATCH(J11,'В02 Каталог'!$B$5:$B$19,0)),""))
A12: 8 | L12: =IF(I12<>"Так","",IF(J12="","Оберіть захід",IF(K12="","Вкажіть, де в мережі",IF(D12="","Оберіть літеру STRIDE",IF(F12="","Вкажіть природу",IF(AND(INDEX('В02 Каталог'!$C$5:$C$19,MATCH(J12,'В02 Каталог'!$B$5:$B$19,0))="Лабораторна",F12="фізична",INDEX('В02 Каталог'!$A$5:$A$19,MATCH(J12,'В02 Каталог'!$B$5:$B$19,0))<>"L10"),"Мережевий захід не закриває фізичну загрозу",IF(AND(INDEX('В02 Каталог'!$C$5:$C$19,MATCH(J12,'В02 Каталог'!$B$5:$B$19,0))="Лабораторна",ISERROR(SEARCH(LEFT(D12,1),INDEX('В02 Каталог'!$D$5:$D$19,MATCH(J12,'В02 Каталог'!$B$5:$B$19,0))))),"Захід не діє на цей тип загрози",IF(AND(INDEX('В02 Каталог'!$C$5:$C$19,MATCH(J12,'В02 Каталог'!$B$5:$B$19,0))="Поза курсом",F12="мережева"),"Для мережевої загрози потрібен захід з лабораторних","ОК")))))))) | M12: =IF(J12="","",IFERROR(INDEX('В02 Каталог'!$E$5:$E$19,MATCH(J12,'В02 Каталог'!$B$5:$B$19,0)),"")) | N12: =IF(J12="","",IFERROR(INDEX('В02 Каталог'!$C$5:$C$19,MATCH(J12,'В02 Каталог'!$B$5:$B$19,0)),""))
A13: 9 | L13: =IF(I13<>"Так","",IF(J13="","Оберіть захід",IF(K13="","Вкажіть, де в мережі",IF(D13="","Оберіть літеру STRIDE",IF(F13="","Вкажіть природу",IF(AND(INDEX('В02 Каталог'!$C$5:$C$19,MATCH(J13,'В02 Каталог'!$B$5:$B$19,0))="Лабораторна",F13="фізична",INDEX('В02 Каталог'!$A$5:$A$19,MATCH(J13,'В02 Каталог'!$B$5:$B$19,0))<>"L10"),"Мережевий захід не закриває фізичну загрозу",IF(AND(INDEX('В02 Каталог'!$C$5:$C$19,MATCH(J13,'В02 Каталог'!$B$5:$B$19,0))="Лабораторна",ISERROR(SEARCH(LEFT(D13,1),INDEX('В02 Каталог'!$D$5:$D$19,MATCH(J13,'В02 Каталог'!$B$5:$B$19,0))))),"Захід не діє на цей тип загрози",IF(AND(INDEX('В02 Каталог'!$C$5:$C$19,MATCH(J13,'В02 Каталог'!$B$5:$B$19,0))="Поза курсом",F13="мережева"),"Для мережевої загрози потрібен захід з лабораторних","ОК")))))))) | M13: =IF(J13="","",IFERROR(INDEX('В02 Каталог'!$E$5:$E$19,MATCH(J13,'В02 Каталог'!$B$5:$B$19,0)),"")) | N13: =IF(J13="","",IFERROR(INDEX('В02 Каталог'!$C$5:$C$19,MATCH(J13,'В02 Каталог'!$B$5:$B$19,0)),""))
A14: 10 | L14: =IF(I14<>"Так","",IF(J14="","Оберіть захід",IF(K14="","Вкажіть, де в мережі",IF(D14="","Оберіть літеру STRIDE",IF(F14="","Вкажіть природу",IF(AND(INDEX('В02 Каталог'!$C$5:$C$19,MATCH(J14,'В02 Каталог'!$B$5:$B$19,0))="Лабораторна",F14="фізична",INDEX('В02 Каталог'!$A$5:$A$19,MATCH(J14,'В02 Каталог'!$B$5:$B$19,0))<>"L10"),"Мережевий захід не закриває фізичну загрозу",IF(AND(INDEX('В02 Каталог'!$C$5:$C$19,MATCH(J14,'В02 Каталог'!$B$5:$B$19,0))="Лабораторна",ISERROR(SEARCH(LEFT(D14,1),INDEX('В02 Каталог'!$D$5:$D$19,MATCH(J14,'В02 Каталог'!$B$5:$B$19,0))))),"Захід не діє на цей тип загрози",IF(AND(INDEX('В02 Каталог'!$C$5:$C$19,MATCH(J14,'В02 Каталог'!$B$5:$B$19,0))="Поза курсом",F14="мережева"),"Для мережевої загрози потрібен захід з лабораторних","ОК")))))))) | M14: =IF(J14="","",IFERROR(INDEX('В02 Каталог'!$E$5:$E$19,MATCH(J14,'В02 Каталог'!$B$5:$B$19,0)),"")) | N14: =IF(J14="","",IFERROR(INDEX('В02 Каталог'!$C$5:$C$19,MATCH(J14,'В02 Каталог'!$B$5:$B$19,0)),""))
A15: 11 | L15: =IF(I15<>"Так","",IF(J15="","Оберіть захід",IF(K15="","Вкажіть, де в мережі",IF(D15="","Оберіть літеру STRIDE",IF(F15="","Вкажіть природу",IF(AND(INDEX('В02 Каталог'!$C$5:$C$19,MATCH(J15,'В02 Каталог'!$B$5:$B$19,0))="Лабораторна",F15="фізична",INDEX('В02 Каталог'!$A$5:$A$19,MATCH(J15,'В02 Каталог'!$B$5:$B$19,0))<>"L10"),"Мережевий захід не закриває фізичну загрозу",IF(AND(INDEX('В02 Каталог'!$C$5:$C$19,MATCH(J15,'В02 Каталог'!$B$5:$B$19,0))="Лабораторна",ISERROR(SEARCH(LEFT(D15,1),INDEX('В02 Каталог'!$D$5:$D$19,MATCH(J15,'В02 Каталог'!$B$5:$B$19,0))))),"Захід не діє на цей тип загрози",IF(AND(INDEX('В02 Каталог'!$C$5:$C$19,MATCH(J15,'В02 Каталог'!$B$5:$B$19,0))="Поза курсом",F15="мережева"),"Для мережевої загрози потрібен захід з лабораторних","ОК")))))))) | M15: =IF(J15="","",IFERROR(INDEX('В02 Каталог'!$E$5:$E$19,MATCH(J15,'В02 Каталог'!$B$5:$B$19,0)),"")) | N15: =IF(J15="","",IFERROR(INDEX('В02 Каталог'!$C$5:$C$19,MATCH(J15,'В02 Каталог'!$B$5:$B$19,0)),""))
A16: 12 | L16: =IF(I16<>"Так","",IF(J16="","Оберіть захід",IF(K16="","Вкажіть, де в мережі",IF(D16="","Оберіть літеру STRIDE",IF(F16="","Вкажіть природу",IF(AND(INDEX('В02 Каталог'!$C$5:$C$19,MATCH(J16,'В02 Каталог'!$B$5:$B$19,0))="Лабораторна",F16="фізична",INDEX('В02 Каталог'!$A$5:$A$19,MATCH(J16,'В02 Каталог'!$B$5:$B$19,0))<>"L10"),"Мережевий захід не закриває фізичну загрозу",IF(AND(INDEX('В02 Каталог'!$C$5:$C$19,MATCH(J16,'В02 Каталог'!$B$5:$B$19,0))="Лабораторна",ISERROR(SEARCH(LEFT(D16,1),INDEX('В02 Каталог'!$D$5:$D$19,MATCH(J16,'В02 Каталог'!$B$5:$B$19,0))))),"Захід не діє на цей тип загрози",IF(AND(INDEX('В02 Каталог'!$C$5:$C$19,MATCH(J16,'В02 Каталог'!$B$5:$B$19,0))="Поза курсом",F16="мережева"),"Для мережевої загрози потрібен захід з лабораторних","ОК")))))))) | M16: =IF(J16="","",IFERROR(INDEX('В02 Каталог'!$E$5:$E$19,MATCH(J16,'В02 Каталог'!$B$5:$B$19,0)),"")) | N16: =IF(J16="","",IFERROR(INDEX('В02 Каталог'!$C$5:$C$19,MATCH(J16,'В02 Каталог'!$B$5:$B$19,0)),""))
... A34: 30 | L34: =IF(I34<>"Так","",IF(J34="","Оберіть захід",IF(K34="","Вкажіть, де в мережі",IF(D34="","Оберіть літеру STRIDE",IF(F34="","Вкажіть природу",IF(AND(INDEX('В02 Каталог'!$C$5:$C$19,MATCH(J34,'В02 Каталог'!$B$5:$B$19,0))="Лабораторна",F34="фізична",INDEX('В02 Каталог'!$A$5:$A$19,MATCH(J34,'В02 Каталог'!$B$5:$B$19,0))<>"L10"),"Мережевий захід не закриває фізичну загрозу",IF(AND(INDEX('В02 Каталог'!$C$5:$C$19,MATCH(J34,'В02 Каталог'!$B$5:$B$19,0))="Лабораторна",ISERROR(SEARCH(LEFT(D34,1),INDEX('В02 Каталог'!$D$5:$D$19,MATCH(J34,'В02 Каталог'!$B$5:$B$19,0))))),"Захід не діє на цей тип загрози",IF(AND(INDEX('В02 Каталог'!$C$5:$C$19,MATCH(J34,'В02 Каталог'!$B$5:$B$19,0))="Поза курсом",F34="мережева"),"Для мережевої загрози потрібен захід з лабораторних","ОК")))))))) | M34: =IF(J34="","",IFERROR(INDEX('В02 Каталог'!$E$5:$E$19,MATCH(J34,'В02 Каталог'!$B$5:$B$19,0)),"")) | N34: =IF(J34="","",IFERROR(INDEX('В02 Каталог'!$C$5:$C$19,MATCH(J34,'В02 Каталог'!$B$5:$B$19,0)),""))

Sheet В02 Підсумок
A1: Підсумок і самоперевірка
A4: Загроз у таблиці | B4: =COUNTA('В02 Загрози і заходи'!E5:E34) | C4: =IF(B4>=12,"достатньо","потрібно щонайменше 12")
A5: Загроз на межі M1 | B5: =COUNTIF('В02 Загрози і заходи'!B5:B34,"M1*") | C5: =IF(B5>=1,"є","немає: поверніться до питання 2")
A6: Загроз на межі M2 | B6: =COUNTIF('В02 Загрози і заходи'!B5:B34,"M2*") | C6: =IF(B6>=1,"є","немає: поверніться до питання 2")
A7: Загроз на межі M3 | B7: =COUNTIF('В02 Загрози і заходи'!B5:B34,"M3*") | C7: =IF(B7>=1,"є","немає: поверніться до питання 2")
A8: Загроз на межі M4 | B8: =COUNTIF('В02 Загрози і заходи'!B5:B34,"M4*") | C8: =IF(B8>=1,"є","немає: поверніться до питання 2")
A9: Загроз на межі M5 | B9: =COUNTIF('В02 Загрози і заходи'!B5:B34,"M5*") | C9: =IF(B9>=1,"є","немає: поверніться до питання 2")
A10: Загроз на межі M6 | B10: =COUNTIF('В02 Загрози і заходи'!B5:B34,"M6*") | C10: =IF(B10>=1,"є","немає: поверніться до питання 2")
A11: Загроз типу S | B11: =COUNTIF('В02 Загрози і заходи'!D5:D34,"S —*") | C11: =IF(B11>=1,"є","немає: подумайте, які загрози типу S є на шляху")
A12: Загроз типу T | B12: =COUNTIF('В02 Загрози і заходи'!D5:D34,"T —*") | C12: =IF(B12>=1,"є","немає: подумайте, які загрози типу T є на шляху")
A13: Загроз типу R | B13: =COUNTIF('В02 Загрози і заходи'!D5:D34,"R —*") | C13: =IF(B13>=1,"є","немає: подумайте, які загрози типу R є на шляху")
A14: Загроз типу I | B14: =COUNTIF('В02 Загрози і заходи'!D5:D34,"I —*") | C14: =IF(B14>=1,"є","немає: подумайте, які загрози типу I є на шляху")
A15: Загроз типу D | B15: =COUNTIF('В02 Загрози і заходи'!D5:D34,"D —*") | C15: =IF(B15>=1,"є","немає: подумайте, які загрози типу D є на шляху")
A16: Загроз типу E | B16: =COUNTIF('В02 Загрози і заходи'!D5:D34,"E —*") | C16: =IF(B16>=1,"є","немає: подумайте, які загрози типу E є на шляху")
A17: Позначено «Топ-8» | B17: =COUNTIF('В02 Загрози і заходи'!I5:I34,"Так") | C17: =IF(B17=8,"рівно 8","має бути рівно 8")
A18: Топ-8: що не так у перевірці | B18: =SUMPRODUCT(('В02 Загрози і заходи'!I5:I34="Так")*('В02 Загрози і заходи'!L5:L34<>"ОК")) | C18: =IF(B18=0,"усе узгоджено","дивіться колонку «Перевірка»")
A19: З топ-8 не закриваються мережею (поза курсом) | B19: =COUNTIFS('В02 Загрози і заходи'!I5:I34,"Так",'В02 Загрози і заходи'!N5:N34,"Поза курсом") | C19: це нормально, якщо загроза фізична чи організаційна
A20: Нових загроз на межі M7 (після інжекту) | B20: =COUNTIF('В02 Загрози і заходи'!B5:B34,"M7*") | C20: =IF(B20>=2,"достатньо","потрібно щонайменше 2")

Sheet В02 Обґрунтування
A1: Обґрунтування вибору
A2: Пишіть власні пояснення для 2–3 загроз із топ-8 своїми словами (2–3 речення). Викладач може попросити пояснити їх усно.
A4: Хто (А/Б, прізвище) | B4: № загрози | C4: Чому така серйозність і чому саме ця межа | D4: Чому саме цей захід (і чому не інший), де він стоїть
A12: Нова обставина: що сказано у файлі «Нова обставина» і що саме ви змінили (межа M7, нові рядки, зміни у схемі):

Sheet В03 Інструкція
A1: ПР 2. Модель загроз: шлях платіжної картки. Варіант 03
A2: Працюйте в жовтих комірках. Сірі комірки рахуються самі (захищені). Схему малюйте у файлі PowerPoint.
A4: Порядок роботи
A5: 1. Схема (питання 1) | B5: У файлі PowerPoint домалюйте стрілки потоків, підпишіть, що передається, і проведіть межі довіри M1–M6. Межі запишіть також на аркуші «Картка».
A6: 2. Загрози (питання 2) | B6: Для кожної межі знайдіть загрози за STRIDE (≥ 12 загроз; усі шість меж і всі шість літер). Знайдіть три помилки в аркуші «Чернетка колеги».
A7: 3. Заходи (питання 3) | B7: Позначте 8 найсерйозніших загроз («Так» у «Топ-8»), оберіть захід із «Каталогу» і напишіть, де саме в мережі він працює. Якщо мережа загрозу не закриває, оберіть захід «Поза курсом» і поясніть.
A8: 4. Нова обставина | B8: Коли завершите кроки 1–3, відкрийте окремий файл «Нова обставина» (не раніше). Додайте межу M7 і ≥ 2 нові загрози з заходами, поправте схему й запишіть, що змінилось (аркуш «Обґрунтування»).
A9: 5. Обґрунтування | B9: Власними словами поясніть вибір для 2–3 загроз (аркуш «Обґрунтування»).
A11: STRIDE | B11: S — підміна (хтось видає себе за іншого) · T — зміна даних · R — відмова від дій (немає доказів, хто що зробив) · I — витік (хтось читає чуже) · D — відмова в обслуговуванні · E — підвищення прав (хтось отримує більше прав, ніж мав би)
A12: Серйозність загрози | B12: 1 — незначна: без збитків для грошей і даних карток. 2 — суттєва: обмежені збитки або тимчасова зупинка. 3 — серйозна: масова компрометація карток, значні гроші або зупинка платежів.
A13: Природа загрози | B13: мережева — закривається налаштуванням мережі; фізична — потрібен доступ до пристрою; організаційна — залежить від процедур і договорів.
A14: Перевірка заходу | B14: Лабораторний захід має діяти на вашу літеру STRIDE (див. «Каталог»). Мережевий захід не закриває фізичну загрозу. Для мережевої загрози потрібен захід з лабораторних. Для решти допустимі заходи «Поза курсом».
A15: Зв'язок із ПР 1 | B15: У колонці «Категорія ризику з ПР 1» вкажіть, до якого ризику з вашого реєстру ПР 1 належить загроза.

Sheet В03 Картка
A1: Картка варіанта 03
A3: Студент (прізвище)
A4: Точка прийому | B4: стаціонарний POS-термінал на касі
A5: Підключення точки до мережі | B5: Ethernet-кабель усередині будівлі
A6: Зв'язок відділення зі шлюзом | B6: Інтернет із налаштованим IPsec VPN
A7: Особливий учасник | B7: сервісна компанія терміналів: віддалене оновлення прошивки й діагностика
A8: Платіжний шлюз | B8: у центрі обробки; після нього АБС (головний офіс)
A9: Шлях картки | B9: клієнт → точка прийому → мережа відділення → зовнішній канал → платіжний шлюз → АБС
A11: Межі довіри на шляху: опишіть, між чим і чим проходить кожна межа
A12: На шляху шість меж довіри (M1–M6), якщо рахувати й особливого учасника. M7 з'явиться після нової обставини.
A13: M1 | C13: =A13&". "&B13
A14: M2 | C14: =A14&". "&B14
A15: M3 | C15: =A15&". "&B15
A16: M4 | C16: =A16&". "&B16
A17: M5 | C17: =A17&". "&B17
A18: M6 | C18: =A18&". "&B18
A19: M7 | C19: =A19&". "&B19

Sheet В03 Каталог
A1: Каталог заходів
A2: Лабораторні заходи вивчатимете далі в курсі. Літери показують, які типи STRIDE захід закриває. Заходи «Поза курсом» теж допустимі, але лише там, де мережа не допоможе.
A4: Код | B4: Назва заходу | C4: Тип | D4: Діє на STRIDE | E4: Лабораторна
A5: L1 | B5: ЛР1. Сегментація VLAN і маршрутизація між ними | C5: Лабораторна | D5: I E | E5: ЛР 1
A6: L2 | B6: ЛР2. Port Security на портах комутатора | C6: Лабораторна | D6: S | E6: ЛР 2
A7: L3 | B7: ЛР3. DHCP Snooping | C7: Лабораторна | D7: S T | E7: ЛР 3
A8: L4 | B8: ЛР4. Списки доступу (ACL) між зонами | C8: Лабораторна | D8: E I T | E8: ЛР 4
A9: L5 | B9: ЛР5. Міжмережевий екран ASA: зони й NAT | C9: Лабораторна | D9: E I S | E9: ЛР 5
A10: L6 | B10: ЛР6. DMZ для вебсайту й ДБО | C10: Лабораторна | D10: E I | E10: ЛР 6
A11: L7 | B11: ЛР7. IPsec VPN між відділенням і головним офісом | C11: Лабораторна | D11: S T I | E11: ЛР 7
A12: L8 | B12: ЛР8. Окремий VLAN для пристроїв і захищена Wi-Fi (WPA2) | C12: Лабораторна | D12: S E I | E12: ЛР 8
A13: L9 | B13: ЛР9. SSH, AAA і RADIUS, ролі адміністраторів | C13: Лабораторна | D13: S E R | E13: ЛР 9
A14: L10 | B14: ЛР10. Syslog, NTP і моніторинг (лише виявляє) | C14: Лабораторна | D14: R D | E14: ЛР 10
A15: O1 | B15: Поза курсом: навчання й інструктаж персоналу | C15: Поза курсом | E15: —
A16: O2 | B16: Поза курсом: договір, регламент, журнал відвідувань підрядника | C16: Поза курсом | E16: —
A17: O3 | B17: Поза курсом: антискімінгові накладки, пломби, замки, огляд пристрою | C17: Поза курсом | E17: —
A18: O4 | B18: Поза курсом: резервний канал і угода про рівень обслуговування | C18: Поза курсом | E18: —
A19: O5 | B19: Поза курсом: подвійний контроль і звірка інкасації | C19: Поза курсом | E19: —

Sheet В03 Чернетка колеги
A1: Чернетка таблиці загроз від колеги
A2: У ній три помилки. Знайдіть їх, запишіть у журнал і не переносьте у свою таблицю без виправлення.
A4: № | B4: Межа | C4: STRIDE | D4: Загроза | E4: Природа | F4: Серйозність | G4: Захід
A5: 1 | B5: M5 | C5: S — підміна | D5: Підроблений запит до АБС від зламаного шлюзу чи від ПК відділення | E5: мережева | F5: 3 | G5: ЛР5. Міжмережевий екран ASA: зони й NAT
A6: 2 | B6: M4 | C6: T — зміна даних | D6: Перехоплення платіжного трафіку в каналі: зловмисник читає передані дані | E6: мережева | F6: 3 | G6: ЛР7. IPsec VPN між відділенням і головним офісом
A7: 3 | B7: M1 | C7: T — зміна даних | D7: Скімер на POS-термінала на касі: копіює дані картки | E7: фізична | F7: 3 | G7: ЛР1. Сегментація VLAN і маршрутизація між ними
A8: 4 | B8: M5 | C8: R — відмова від дій | D8: Шлюз не зберігає журнал: після шахрайства неможливо відновити послідовність подій | E8: мережева | F8: 2 | G8: ЛР10. Syslog, NTP і моніторинг (лише виявляє)
A9: 5 | B9: M1 | C9: R — відмова від дій | D9: Клієнт заперечує операцію, а повного журналу з точним часом немає | E9: організаційна | F9: 2 | G9: ЛР10. Syslog, NTP і моніторинг (лише виявляє)
A10: 6 | B10: M2 | C10: T — зміна даних | D10: Підробний DHCP-сервер видає терміналу чужий шлюз і перехоплює платіжний трафік | E10: мережева | F10: 2 | G10: ЛР3. DHCP Snooping
A11: 7 | B11: M3 | C11: T — зміна даних | D11: Встановити IPsec VPN і міжмережевий екран між відділенням і шлюзом | E11: мережева | F11: 3 | G11: ЛР7. IPsec VPN між відділенням і головним офісом
A13: Журнал виправлень
A14: Рядок | B14: Тип помилки | C14: Що не так і як виправити

Sheet В03 Загрози і заходи
A1: Загрози за STRIDE і заходи (питання 2 і 3)
A2: Один рядок: межа + літера STRIDE + загроза. Топ-8: для кожної обов'язково захід і де в мережі.
A4: № | B4: Межа довіри | C4: Що передається чи що під загрозою | D4: STRIDE | E4: Загроза: хто, що робить, що втрачаємо | F4: Природа | G4: Серйозність 1–3 | H4: Категорія ризику з ПР 1 | I4: Топ-8 | J4: Захід (з Каталогу) | K4: Де в мережі: пристрій, зона, що налаштувати | L4: Перевірка | M4: Лабораторна | N4: Тип заходу | O4: Примітка
A5: 1 | L5: =IF(I5<>"Так","",IF(J5="","Оберіть захід",IF(K5="","Вкажіть, де в мережі",IF(D5="","Оберіть літеру STRIDE",IF(F5="","Вкажіть природу",IF(AND(INDEX('В03 Каталог'!$C$5:$C$19,MATCH(J5,'В03 Каталог'!$B$5:$B$19,0))="Лабораторна",F5="фізична",INDEX('В03 Каталог'!$A$5:$A$19,MATCH(J5,'В03 Каталог'!$B$5:$B$19,0))<>"L10"),"Мережевий захід не закриває фізичну загрозу",IF(AND(INDEX('В03 Каталог'!$C$5:$C$19,MATCH(J5,'В03 Каталог'!$B$5:$B$19,0))="Лабораторна",ISERROR(SEARCH(LEFT(D5,1),INDEX('В03 Каталог'!$D$5:$D$19,MATCH(J5,'В03 Каталог'!$B$5:$B$19,0))))),"Захід не діє на цей тип загрози",IF(AND(INDEX('В03 Каталог'!$C$5:$C$19,MATCH(J5,'В03 Каталог'!$B$5:$B$19,0))="Поза курсом",F5="мережева"),"Для мережевої загрози потрібен захід з лабораторних","ОК")))))))) | M5: =IF(J5="","",IFERROR(INDEX('В03 Каталог'!$E$5:$E$19,MATCH(J5,'В03 Каталог'!$B$5:$B$19,0)),"")) | N5: =IF(J5="","",IFERROR(INDEX('В03 Каталог'!$C$5:$C$19,MATCH(J5,'В03 Каталог'!$B$5:$B$19,0)),""))
A6: 2 | L6: =IF(I6<>"Так","",IF(J6="","Оберіть захід",IF(K6="","Вкажіть, де в мережі",IF(D6="","Оберіть літеру STRIDE",IF(F6="","Вкажіть природу",IF(AND(INDEX('В03 Каталог'!$C$5:$C$19,MATCH(J6,'В03 Каталог'!$B$5:$B$19,0))="Лабораторна",F6="фізична",INDEX('В03 Каталог'!$A$5:$A$19,MATCH(J6,'В03 Каталог'!$B$5:$B$19,0))<>"L10"),"Мережевий захід не закриває фізичну загрозу",IF(AND(INDEX('В03 Каталог'!$C$5:$C$19,MATCH(J6,'В03 Каталог'!$B$5:$B$19,0))="Лабораторна",ISERROR(SEARCH(LEFT(D6,1),INDEX('В03 Каталог'!$D$5:$D$19,MATCH(J6,'В03 Каталог'!$B$5:$B$19,0))))),"Захід не діє на цей тип загрози",IF(AND(INDEX('В03 Каталог'!$C$5:$C$19,MATCH(J6,'В03 Каталог'!$B$5:$B$19,0))="Поза курсом",F6="мережева"),"Для мережевої загрози потрібен захід з лабораторних","ОК")))))))) | M6: =IF(J6="","",IFERROR(INDEX('В03 Каталог'!$E$5:$E$19,MATCH(J6,'В03 Каталог'!$B$5:$B$19,0)),"")) | N6: =IF(J6="","",IFERROR(INDEX('В03 Каталог'!$C$5:$C$19,MATCH(J6,'В03 Каталог'!$B$5:$B$19,0)),""))
A7: 3 | L7: =IF(I7<>"Так","",IF(J7="","Оберіть захід",IF(K7="","Вкажіть, де в мережі",IF(D7="","Оберіть літеру STRIDE",IF(F7="","Вкажіть природу",IF(AND(INDEX('В03 Каталог'!$C$5:$C$19,MATCH(J7,'В03 Каталог'!$B$5:$B$19,0))="Лабораторна",F7="фізична",INDEX('В03 Каталог'!$A$5:$A$19,MATCH(J7,'В03 Каталог'!$B$5:$B$19,0))<>"L10"),"Мережевий захід не закриває фізичну загрозу",IF(AND(INDEX('В03 Каталог'!$C$5:$C$19,MATCH(J7,'В03 Каталог'!$B$5:$B$19,0))="Лабораторна",ISERROR(SEARCH(LEFT(D7,1),INDEX('В03 Каталог'!$D$5:$D$19,MATCH(J7,'В03 Каталог'!$B$5:$B$19,0))))),"Захід не діє на цей тип загрози",IF(AND(INDEX('В03 Каталог'!$C$5:$C$19,MATCH(J7,'В03 Каталог'!$B$5:$B$19,0))="Поза курсом",F7="мережева"),"Для мережевої загрози потрібен захід з лабораторних","ОК")))))))) | M7: =IF(J7="","",IFERROR(INDEX('В03 Каталог'!$E$5:$E$19,MATCH(J7,'В03 Каталог'!$B$5:$B$19,0)),"")) | N7: =IF(J7="","",IFERROR(INDEX('В03 Каталог'!$C$5:$C$19,MATCH(J7,'В03 Каталог'!$B$5:$B$19,0)),""))
A8: 4 | L8: =IF(I8<>"Так","",IF(J8="","Оберіть захід",IF(K8="","Вкажіть, де в мережі",IF(D8="","Оберіть літеру STRIDE",IF(F8="","Вкажіть природу",IF(AND(INDEX('В03 Каталог'!$C$5:$C$19,MATCH(J8,'В03 Каталог'!$B$5:$B$19,0))="Лабораторна",F8="фізична",INDEX('В03 Каталог'!$A$5:$A$19,MATCH(J8,'В03 Каталог'!$B$5:$B$19,0))<>"L10"),"Мережевий захід не закриває фізичну загрозу",IF(AND(INDEX('В03 Каталог'!$C$5:$C$19,MATCH(J8,'В03 Каталог'!$B$5:$B$19,0))="Лабораторна",ISERROR(SEARCH(LEFT(D8,1),INDEX('В03 Каталог'!$D$5:$D$19,MATCH(J8,'В03 Каталог'!$B$5:$B$19,0))))),"Захід не діє на цей тип загрози",IF(AND(INDEX('В03 Каталог'!$C$5:$C$19,MATCH(J8,'В03 Каталог'!$B$5:$B$19,0))="Поза курсом",F8="мережева"),"Для мережевої загрози потрібен захід з лабораторних","ОК")))))))) | M8: =IF(J8="","",IFERROR(INDEX('В03 Каталог'!$E$5:$E$19,MATCH(J8,'В03 Каталог'!$B$5:$B$19,0)),"")) | N8: =IF(J8="","",IFERROR(INDEX('В03 Каталог'!$C$5:$C$19,MATCH(J8,'В03 Каталог'!$B$5:$B$19,0)),""))
A9: 5 | L9: =IF(I9<>"Так","",IF(J9="","Оберіть захід",IF(K9="","Вкажіть, де в мережі",IF(D9="","Оберіть літеру STRIDE",IF(F9="","Вкажіть природу",IF(AND(INDEX('В03 Каталог'!$C$5:$C$19,MATCH(J9,'В03 Каталог'!$B$5:$B$19,0))="Лабораторна",F9="фізична",INDEX('В03 Каталог'!$A$5:$A$19,MATCH(J9,'В03 Каталог'!$B$5:$B$19,0))<>"L10"),"Мережевий захід не закриває фізичну загрозу",IF(AND(INDEX('В03 Каталог'!$C$5:$C$19,MATCH(J9,'В03 Каталог'!$B$5:$B$19,0))="Лабораторна",ISERROR(SEARCH(LEFT(D9,1),INDEX('В03 Каталог'!$D$5:$D$19,MATCH(J9,'В03 Каталог'!$B$5:$B$19,0))))),"Захід не діє на цей тип загрози",IF(AND(INDEX('В03 Каталог'!$C$5:$C$19,MATCH(J9,'В03 Каталог'!$B$5:$B$19,0))="Поза курсом",F9="мережева"),"Для мережевої загрози потрібен захід з лабораторних","ОК")))))))) | M9: =IF(J9="","",IFERROR(INDEX('В03 Каталог'!$E$5:$E$19,MATCH(J9,'В03 Каталог'!$B$5:$B$19,0)),"")) | N9: =IF(J9="","",IFERROR(INDEX('В03 Каталог'!$C$5:$C$19,MATCH(J9,'В03 Каталог'!$B$5:$B$19,0)),""))
A10: 6 | L10: =IF(I10<>"Так","",IF(J10="","Оберіть захід",IF(K10="","Вкажіть, де в мережі",IF(D10="","Оберіть літеру STRIDE",IF(F10="","Вкажіть природу",IF(AND(INDEX('В03 Каталог'!$C$5:$C$19,MATCH(J10,'В03 Каталог'!$B$5:$B$19,0))="Лабораторна",F10="фізична",INDEX('В03 Каталог'!$A$5:$A$19,MATCH(J10,'В03 Каталог'!$B$5:$B$19,0))<>"L10"),"Мережевий захід не закриває фізичну загрозу",IF(AND(INDEX('В03 Каталог'!$C$5:$C$19,MATCH(J10,'В03 Каталог'!$B$5:$B$19,0))="Лабораторна",ISERROR(SEARCH(LEFT(D10,1),INDEX('В03 Каталог'!$D$5:$D$19,MATCH(J10,'В03 Каталог'!$B$5:$B$19,0))))),"Захід не діє на цей тип загрози",IF(AND(INDEX('В03 Каталог'!$C$5:$C$19,MATCH(J10,'В03 Каталог'!$B$5:$B$19,0))="Поза курсом",F10="мережева"),"Для мережевої загрози потрібен захід з лабораторних","ОК")))))))) | M10: =IF(J10="","",IFERROR(INDEX('В03 Каталог'!$E$5:$E$19,MATCH(J10,'В03 Каталог'!$B$5:$B$19,0)),"")) | N10: =IF(J10="","",IFERROR(INDEX('В03 Каталог'!$C$5:$C$19,MATCH(J10,'В03 Каталог'!$B$5:$B$19,0)),""))
A11: 7 | L11: =IF(I11<>"Так","",IF(J11="","Оберіть захід",IF(K11="","Вкажіть, де в мережі",IF(D11="","Оберіть літеру STRIDE",IF(F11="","Вкажіть природу",IF(AND(INDEX('В03 Каталог'!$C$5:$C$19,MATCH(J11,'В03 Каталог'!$B$5:$B$19,0))="Лабораторна",F11="фізична",INDEX('В03 Каталог'!$A$5:$A$19,MATCH(J11,'В03 Каталог'!$B$5:$B$19,0))<>"L10"),"Мережевий захід не закриває фізичну загрозу",IF(AND(INDEX('В03 Каталог'!$C$5:$C$19,MATCH(J11,'В03 Каталог'!$B$5:$B$19,0))="Лабораторна",ISERROR(SEARCH(LEFT(D11,1),INDEX('В03 Каталог'!$D$5:$D$19,MATCH(J11,'В03 Каталог'!$B$5:$B$19,0))))),"Захід не діє на цей тип загрози",IF(AND(INDEX('В03 Каталог'!$C$5:$C$19,MATCH(J11,'В03 Каталог'!$B$5:$B$19,0))="Поза курсом",F11="мережева"),"Для мережевої загрози потрібен захід з лабораторних","ОК")))))))) | M11: =IF(J11="","",IFERROR(INDEX('В03 Каталог'!$E$5:$E$19,MATCH(J11,'В03 Каталог'!$B$5:$B$19,0)),"")) | N11: =IF(J11="","",IFERROR(INDEX('В03 Каталог'!$C$5:$C$19,MATCH(J11,'В03 Каталог'!$B$5:$B$19,0)),""))
