Workbook

Sheet Зміст
A1: Усі варіанти в одному файлі
A2: Кожен варіант має власні аркуші з префіксом «В01», «В02» тощо й свій колір вкладок. Натисніть на посилання, щоб перейти до варіанта.
A4: Варіант | B4: Перехід
A5: Варіант 01 | B5: Відкрити аркуші варіанта 01
A6: Варіант 02 | B6: Відкрити аркуші варіанта 02
A7: Варіант 03 | B7: Відкрити аркуші варіанта 03
A8: Варіант 04 | B8: Відкрити аркуші варіанта 04
A9: Варіант 05 | B9: Відкрити аркуші варіанта 05
A10: Варіант 06 | B10: Відкрити аркуші варіанта 06
A11: Варіант 07 | B11: Відкрити аркуші варіанта 07
A12: Варіант 08 | B12: Відкрити аркуші варіанта 08
A13: Варіант 09 | B13: Відкрити аркуші варіанта 09
A14: Варіант 10 | B14: Відкрити аркуші варіанта 10

Sheet В01 Інструкція
A1: ПР 1. Оцінка ризиків для відділення «Банку N». Варіант 01
A2: Працюйте в жовтих комірках. Сірі комірки рахуються самі (захищені).
A4: Порядок роботи
A5: 1. Профіль | B5: Прочитайте аркуш «Профіль»: факти про ваше відділення.
A6: 2. Активи (питання 1) | B6: Складіть перелік активів (не менше 10) і оцініть цінність 1–5. Одночасно перегляньте аркуш «Чернетка»: у ній 3 помилки колеги. Запишіть їх у журнал виправлень.
A7: 3. Ризики (питання 2) | B7: Для активів запишіть ризики (не менше 12): актив, загроза, вразливість, категорія, ймовірність P та наслідки C за шкалою 1–5. Рівень і зона рахуються самі.
A8: 4. Матриця й заходи (питання 3) | B8: Аркуш «Матриця» будується автоматично. Позначте топ-5 ризиків («Так» у колонці «Топ-5»), оберіть стратегію й захід із «Каталогу». Бюджет перевіряється на аркуші «Бюджет».
A9: 5. Обґрунтування | B9: На аркуші «Обґрунтування» власними словами поясніть вибір для 2–3 ризиків із топ-5.
A10: 6. Нова обставина | B10: Коли завершите кроки 1–4, відкрийте окремий файл «Нова обставина» (не раніше). Оновіть таблицю й запишіть, що змінилось (аркуш «Обґрунтування», рядок «Інжект»).
A12: Шкала ймовірності P | B12: 1 — рідше ніж раз на 5 років · 2 — раз на 2–5 років · 3 — раз на 1–2 роки · 4 — кілька разів на рік · 5 — щомісяця і частіше
A13: Шкала наслідків C | B13: 1 — збитки до 10 тис. грн, без зупинки · 2 — 10–50 тис. грн · 3 — 50–250 тис. грн або зупинка відділення до кількох годин · 4 — 250 тис. – 1 млн грн, або зупинка на добу, або увага регулятора · 5 — понад 1 млн грн, тривала зупинка, витік даних клієнтів, серйозна репутаційна шкода
A14: Рівень ризику | B14: Рівень = P × C. 1–4 низький · 5–9 середній · 10–16 високий · 17–25 критичний
A15: Правила стратегій | B15: Критичний ризик (17–25) не приймають. «Приймати» — без заходу. «Передавати» — лише через захід «Страхування». «Уникати» — через захід «Призупинити сервіс чи функцію». «Зменшувати» — захід, що діє на категорію ризику.
A16: Бюджет | B16: 100 умовних одиниць (якщо бюджет зміниться, поправте комірку B4 на аркуші «Бюджет»). Кожен захід оплачується один раз, навіть якщо ним закрито кілька ризиків.

Sheet В01 Профіль
A1: Профіль відділення. Варіант 01
A3: Номер варіанта | B3: 01
A4: Студент (прізвище)
A5: Кількість працівників | B5: 12 (три каси, двоє менеджерів, керівник, операціоніст та інші)
A6: Банкомати | B6: 2: один у залі, один на вулиці
A7: POS-термінали | B7: 4
A8: Вуличний банкомат: освітлення | B8: погане
A9: Вуличний банкомат: камера | B9: немає
A10: Готівка у вуличному банкоматі | B10: до 340 тис. грн
A11: Транзакцій на добу на вуличному банкоматі | B11: 210
A12: Резервне живлення | B12: лише ДБЖ
A13: Відключення електроенергії | B13: у середньому 4 год на добу
A14: Канал зв'язку з головним офісом | B14: один провайдер
A15: Спроб вішингу за останній рік (внутрішній облік) | B15: 2
A16: Особливий актив відділення | B16: Хмарний сервіс ДБО для малого бізнесу (доступ через браузер)
... A18: Захід, недоступний у цьому кварталі | B18: немає

Sheet В01 Каталог
A1: Каталог заходів безпеки
A2: Вартість в умовних одиницях. ΔP і ΔC: на скільки балів захід знижує ймовірність і наслідки (лише для зазначених категорій).
A4: Код | B4: Назва заходу | C4: Вартість | D4: Діє на категорії ризику | E4: ΔP | F4: ΔC | G4: Оплачено | H4: Доступний
A5: M1 | B5: Навчання персоналу з фішингу та вішингу | C5: 10 | D5: Соціальна інженерія | E5: 1 | F5: 0 | G5: =IF(COUNTIF('В01 Ризики'!$L$5:$L$24,B5)>0,C5,0) | H5: Так
A6: M2 | B6: Багатофакторна автентифікація для адміністраторів і ДБО | C6: 15 | D6: Мережа/ІТ; Соціальна інженерія | E6: 2 | F6: 0 | G6: =IF(COUNTIF('В01 Ризики'!$L$5:$L$24,B6)>0,C6,0) | H6: Так
A7: M3 | B7: Антискімінгові накладки та датчик відкриття корпусу банкомата | C7: 12 | D7: Шахрайство з картками | E7: 2 | F7: 0 | G7: =IF(COUNTIF('В01 Ризики'!$L$5:$L$24,B7)>0,C7,0) | H7: Так
A8: M4 | B8: Освітлення та камера біля вуличного банкомата | C8: 8 | D8: Фізичний доступ; Шахрайство з картками | E8: 1 | F8: 0 | G8: =IF(COUNTIF('В01 Ризики'!$L$5:$L$24,B8)>0,C8,0) | H8: Так
A9: M5 | B9: Резервний канал зв'язку (LTE) | C9: 14 | D9: Живлення і зв'язок | E9: 2 | F9: 0 | G9: =IF(COUNTIF('В01 Ризики'!$L$5:$L$24,B9)>0,C9,0) | H9: Так
A10: M6 | B10: Генератор і ДБЖ | C10: 18 | D10: Живлення і зв'язок | E10: 2 | F10: 1 | G10: =IF(COUNTIF('В01 Ризики'!$L$5:$L$24,B10)>0,C10,0) | H10: Так
A11: M7 | B11: Сегментація мережі (VLAN, списки доступу) | C11: 16 | D11: Мережа/ІТ | E11: 1 | F11: 2 | G11: =IF(COUNTIF('В01 Ризики'!$L$5:$L$24,B11)>0,C11,0) | H11: Так
A12: M8 | B12: Резервні копії з перевіркою відновлення | C12: 12 | D12: Мережа/ІТ; Живлення і зв'язок | E12: 0 | F12: 2 | G12: =IF(COUNTIF('В01 Ризики'!$L$5:$L$24,B12)>0,C12,0) | H12: Так
A13: M9 | B13: Оновлення ПЗ за графіком | C13: 9 | D13: Мережа/ІТ | E13: 1 | F13: 0 | G13: =IF(COUNTIF('В01 Ризики'!$L$5:$L$24,B13)>0,C13,0) | H13: Так
A14: M10 | B14: Страхування готівки та кіберризиків | C14: 20 | D14: Фізичний доступ; Шахрайство з картками; Мережа/ІТ | E14: 0 | F14: 2 | G14: =IF(COUNTIF('В01 Ризики'!$L$5:$L$24,B14)>0,C14,0) | H14: Так
A15: M11 | B15: Електронні замки та журнал входу в серверну | C15: 10 | D15: Фізичний доступ; Персонал і процеси | E15: 1 | F15: 1 | G15: =IF(COUNTIF('В01 Ризики'!$L$5:$L$24,B15)>0,C15,0) | H15: Так
A16: M12 | B16: Захист від DDoS (послуга оператора) | C16: 17 | D16: Мережа/ІТ | E16: 2 | F16: 1 | G16: =IF(COUNTIF('В01 Ризики'!$L$5:$L$24,B16)>0,C16,0) | H16: Так
... A19: M15 | B19: Призупинити сервіс чи функцію (уникнення, втрата бізнесу) | C19: 6 | D19: Соціальна інженерія; Фізичний доступ; Шахрайство з картками; Мережа/ІТ; Живлення і зв'язок; Персонал і процеси | E19: 3 | F19: 0 | G19: =IF(COUNTIF('В01 Ризики'!$L$5:$L$24,B19)>0,C19,0) | H19: Так
B20: Разом | C20: =SUM(C5:C18) | G20: =SUM(G5:G19)
B21: Разом у рядку «Разом» вартість M1–M14 (без уникнення)

Sheet В01 Активи
A1: Активи відділення (питання 1)
A2: Не менше 10 активів. Цінність: 1 — незначна, 5 — критична для роботи банку.
A4: № | B4: Актив | C4: Група | D4: Власник (роль) | E4: Цінність 1–5 | F4: Чому цінний
A5: 1
A6: 2
A7: 3
A8: 4
A9: 5
A10: 6
A11: 7
A12: 8
A13: 9
A14: 10
A15: 11
A16: 12
... A24: 20

Sheet В01 Чернетка
A1: Чернетка таблиці ризиків від колеги
A2: У ній є три помилки. Знайдіть їх, запишіть у журнал виправлень (нижче) і не переносьте у свою таблицю без виправлення.
A4: № | B4: Актив | C4: Ризик | D4: Вразливість | E4: P | F4: C | G4: Коментар колеги
A5: 1 | B5: Серверна | C5: Пожежа в серверній | D5: немає автоматичного пожежогасіння | E5: 5 | F5: 5 | G5: За останні сім років було лише один такий випадок у нашій мережі
A6: 2 | B6: Вуличний банкомат (готівка) | C6: Крадіжка готівки з вуличного банкомата | D6: камери немає, освітлення погане | E6: 4 | F6: 4 | G6: перший з двох записів про одне й те саме
A7: 3 | B7: Серверна й обладнання відділення | C7: Зловживання правами недобросовісним співробітником | D7: права адміністратора в кількох працівників, журнали не переглядають | E7: 2 | F7: 4 | G7: оцінено за політикою доступу
A8: 4 | B8: Вуличний банкомат (готівка) | C8: Злам банкомата з метою вилучення готівки | D8: камери немає, освітлення погане | E8: 4 | F8: 4 | G8: другий запис, інші слова
A9: 5 | B9: Вуличний банкомат (картки клієнтів) | C9: Встановлення скімера й масове копіювання карток | D9: камери немає, освітлення погане | E9: 4 | F9: 4 | G9: оцінено за даними профілю
A10: 6 | C10: Фішинг | E10: 4 | F10: 4 | G10: Дуже небезпечно, треба бачити
A11: 7 | B11: Канал зв'язку з головним офісом | C11: Відмова каналу до головного офісу | D11: один провайдер | E11: 3 | F11: 4 | G11: оцінено за даними профілю
A13: Журнал виправлень
A14: Рядок | B14: Тип помилки | C14: Що не так і як виправлено

Sheet В01 Ризики
A1: Реєстр ризиків (питання 2 і 3)
A2: Один ризик = актив + загроза + вразливість. P і C за шкалами з аркуша «Інструкція».
A4: № | B4: Актив | C4: Загроза (що може статися) | D4: Вразливість | E4: Категорія | F4: P | G4: C | H4: Рівень | I4: Зона | J4: Топ-5 | K4: Стратегія | L4: Захід (з Каталогу) | M4: ΔP | N4: ΔC | O4: P після | P4: C після | Q4: Залишковий рівень | R4: Перевірка | S4: Примітка
A5: 1 | H5: =IF(OR(F5="",G5=""),"",F5*G5) | I5: =IF(H5="","",IF(H5<=4,"Низький",IF(H5<=9,"Середній",IF(H5<=16,"Високий","Критичний")))) | M5: =IF(L5="",0,IFERROR(IF(ISNUMBER(SEARCH(E5,INDEX('В01 Каталог'!$D$5:$D$19,MATCH(L5,'В01 Каталог'!$B$5:$B$19,0)))),INDEX('В01 Каталог'!$E$5:$E$19,MATCH(L5,'В01 Каталог'!$B$5:$B$19,0)),0),0)) | N5: =IF(L5="",0,IFERROR(IF(ISNUMBER(SEARCH(E5,INDEX('В01 Каталог'!$D$5:$D$19,MATCH(L5,'В01 Каталог'!$B$5:$B$19,0)))),INDEX('В01 Каталог'!$F$5:$F$19,MATCH(L5,'В01 Каталог'!$B$5:$B$19,0)),0),0)) | O5: =IF(F5="","",MAX(1,F5-M5)) | P5: =IF(G5="","",MAX(1,G5-N5)) | Q5: =IF(O5="","",O5*P5) | R5: =IF(J5<>"Так","",IF(K5="","Оберіть стратегію",IF(AND(K5="Приймати",H5>=17),"Критичний ризик не приймають",IF(AND(K5="Приймати",L5<>""),"Приймання: заходу не потрібно",IF(AND(K5<>"Приймати",L5=""),"Оберіть захід",IF(AND(K5="Передавати",L5<>"Страхування готівки та кіберризиків"),"Передача: оберіть страхування",IF(AND(K5="Уникати",L5<>"Призупинити сервіс чи функцію (уникнення, втрата бізнесу)"),"Уникнення: оберіть призупинення",IF(AND(L5<>"",M5+N5=0),"Захід не діє на цю категорію",IF(AND(L5<>"",INDEX('В01 Каталог'!$H$5:$H$19,MATCH(L5,'В01 Каталог'!$B$5:$B$19,0))="Ні"),"Захід недоступний","ОК")))))))))
A6: 2 | H6: =IF(OR(F6="",G6=""),"",F6*G6) | I6: =IF(H6="","",IF(H6<=4,"Низький",IF(H6<=9,"Середній",IF(H6<=16,"Високий","Критичний")))) | M6: =IF(L6="",0,IFERROR(IF(ISNUMBER(SEARCH(E6,INDEX('В01 Каталог'!$D$5:$D$19,MATCH(L6,'В01 Каталог'!$B$5:$B$19,0)))),INDEX('В01 Каталог'!$E$5:$E$19,MATCH(L6,'В01 Каталог'!$B$5:$B$19,0)),0),0)) | N6: =IF(L6="",0,IFERROR(IF(ISNUMBER(SEARCH(E6,INDEX('В01 Каталог'!$D$5:$D$19,MATCH(L6,'В01 Каталог'!$B$5:$B$19,0)))),INDEX('В01 Каталог'!$F$5:$F$19,MATCH(L6,'В01 Каталог'!$B$5:$B$19,0)),0),0)) | O6: =IF(F6="","",MAX(1,F6-M6)) | P6: =IF(G6="","",MAX(1,G6-N6)) | Q6: =IF(O6="","",O6*P6) | R6: =IF(J6<>"Так","",IF(K6="","Оберіть стратегію",IF(AND(K6="Приймати",H6>=17),"Критичний ризик не приймають",IF(AND(K6="Приймати",L6<>""),"Приймання: заходу не потрібно",IF(AND(K6<>"Приймати",L6=""),"Оберіть захід",IF(AND(K6="Передавати",L6<>"Страхування готівки та кіберризиків"),"Передача: оберіть страхування",IF(AND(K6="Уникати",L6<>"Призупинити сервіс чи функцію (уникнення, втрата бізнесу)"),"Уникнення: оберіть призупинення",IF(AND(L6<>"",M6+N6=0),"Захід не діє на цю категорію",IF(AND(L6<>"",INDEX('В01 Каталог'!$H$5:$H$19,MATCH(L6,'В01 Каталог'!$B$5:$B$19,0))="Ні"),"Захід недоступний","ОК")))))))))
A7: 3 | H7: =IF(OR(F7="",G7=""),"",F7*G7) | I7: =IF(H7="","",IF(H7<=4,"Низький",IF(H7<=9,"Середній",IF(H7<=16,"Високий","Критичний")))) | M7: =IF(L7="",0,IFERROR(IF(ISNUMBER(SEARCH(E7,INDEX('В01 Каталог'!$D$5:$D$19,MATCH(L7,'В01 Каталог'!$B$5:$B$19,0)))),INDEX('В01 Каталог'!$E$5:$E$19,MATCH(L7,'В01 Каталог'!$B$5:$B$19,0)),0),0)) | N7: =IF(L7="",0,IFERROR(IF(ISNUMBER(SEARCH(E7,INDEX('В01 Каталог'!$D$5:$D$19,MATCH(L7,'В01 Каталог'!$B$5:$B$19,0)))),INDEX('В01 Каталог'!$F$5:$F$19,MATCH(L7,'В01 Каталог'!$B$5:$B$19,0)),0),0)) | O7: =IF(F7="","",MAX(1,F7-M7)) | P7: =IF(G7="","",MAX(1,G7-N7)) | Q7: =IF(O7="","",O7*P7) | R7: =IF(J7<>"Так","",IF(K7="","Оберіть стратегію",IF(AND(K7="Приймати",H7>=17),"Критичний ризик не приймають",IF(AND(K7="Приймати",L7<>""),"Приймання: заходу не потрібно",IF(AND(K7<>"Приймати",L7=""),"Оберіть захід",IF(AND(K7="Передавати",L7<>"Страхування готівки та кіберризиків"),"Передача: оберіть страхування",IF(AND(K7="Уникати",L7<>"Призупинити сервіс чи функцію (уникнення, втрата бізнесу)"),"Уникнення: оберіть призупинення",IF(AND(L7<>"",M7+N7=0),"Захід не діє на цю категорію",IF(AND(L7<>"",INDEX('В01 Каталог'!$H$5:$H$19,MATCH(L7,'В01 Каталог'!$B$5:$B$19,0))="Ні"),"Захід недоступний","ОК")))))))))
A8: 4 | H8: =IF(OR(F8="",G8=""),"",F8*G8) | I8: =IF(H8="","",IF(H8<=4,"Низький",IF(H8<=9,"Середній",IF(H8<=16,"Високий","Критичний")))) | M8: =IF(L8="",0,IFERROR(IF(ISNUMBER(SEARCH(E8,INDEX('В01 Каталог'!$D$5:$D$19,MATCH(L8,'В01 Каталог'!$B$5:$B$19,0)))),INDEX('В01 Каталог'!$E$5:$E$19,MATCH(L8,'В01 Каталог'!$B$5:$B$19,0)),0),0)) | N8: =IF(L8="",0,IFERROR(IF(ISNUMBER(SEARCH(E8,INDEX('В01 Каталог'!$D$5:$D$19,MATCH(L8,'В01 Каталог'!$B$5:$B$19,0)))),INDEX('В01 Каталог'!$F$5:$F$19,MATCH(L8,'В01 Каталог'!$B$5:$B$19,0)),0),0)) | O8: =IF(F8="","",MAX(1,F8-M8)) | P8: =IF(G8="","",MAX(1,G8-N8)) | Q8: =IF(O8="","",O8*P8) | R8: =IF(J8<>"Так","",IF(K8="","Оберіть стратегію",IF(AND(K8="Приймати",H8>=17),"Критичний ризик не приймають",IF(AND(K8="Приймати",L8<>""),"Приймання: заходу не потрібно",IF(AND(K8<>"Приймати",L8=""),"Оберіть захід",IF(AND(K8="Передавати",L8<>"Страхування готівки та кіберризиків"),"Передача: оберіть страхування",IF(AND(K8="Уникати",L8<>"Призупинити сервіс чи функцію (уникнення, втрата бізнесу)"),"Уникнення: оберіть призупинення",IF(AND(L8<>"",M8+N8=0),"Захід не діє на цю категорію",IF(AND(L8<>"",INDEX('В01 Каталог'!$H$5:$H$19,MATCH(L8,'В01 Каталог'!$B$5:$B$19,0))="Ні"),"Захід недоступний","ОК")))))))))
A9: 5 | H9: =IF(OR(F9="",G9=""),"",F9*G9) | I9: =IF(H9="","",IF(H9<=4,"Низький",IF(H9<=9,"Середній",IF(H9<=16,"Високий","Критичний")))) | M9: =IF(L9="",0,IFERROR(IF(ISNUMBER(SEARCH(E9,INDEX('В01 Каталог'!$D$5:$D$19,MATCH(L9,'В01 Каталог'!$B$5:$B$19,0)))),INDEX('В01 Каталог'!$E$5:$E$19,MATCH(L9,'В01 Каталог'!$B$5:$B$19,0)),0),0)) | N9: =IF(L9="",0,IFERROR(IF(ISNUMBER(SEARCH(E9,INDEX('В01 Каталог'!$D$5:$D$19,MATCH(L9,'В01 Каталог'!$B$5:$B$19,0)))),INDEX('В01 Каталог'!$F$5:$F$19,MATCH(L9,'В01 Каталог'!$B$5:$B$19,0)),0),0)) | O9: =IF(F9="","",MAX(1,F9-M9)) | P9: =IF(G9="","",MAX(1,G9-N9)) | Q9: =IF(O9="","",O9*P9) | R9: =IF(J9<>"Так","",IF(K9="","Оберіть стратегію",IF(AND(K9="Приймати",H9>=17),"Критичний ризик не приймають",IF(AND(K9="Приймати",L9<>""),"Приймання: заходу не потрібно",IF(AND(K9<>"Приймати",L9=""),"Оберіть захід",IF(AND(K9="Передавати",L9<>"Страхування готівки та кіберризиків"),"Передача: оберіть страхування",IF(AND(K9="Уникати",L9<>"Призупинити сервіс чи функцію (уникнення, втрата бізнесу)"),"Уникнення: оберіть призупинення",IF(AND(L9<>"",M9+N9=0),"Захід не діє на цю категорію",IF(AND(L9<>"",INDEX('В01 Каталог'!$H$5:$H$19,MATCH(L9,'В01 Каталог'!$B$5:$B$19,0))="Ні"),"Захід недоступний","ОК")))))))))
A10: 6 | H10: =IF(OR(F10="",G10=""),"",F10*G10) | I10: =IF(H10="","",IF(H10<=4,"Низький",IF(H10<=9,"Середній",IF(H10<=16,"Високий","Критичний")))) | M10: =IF(L10="",0,IFERROR(IF(ISNUMBER(SEARCH(E10,INDEX('В01 Каталог'!$D$5:$D$19,MATCH(L10,'В01 Каталог'!$B$5:$B$19,0)))),INDEX('В01 Каталог'!$E$5:$E$19,MATCH(L10,'В01 Каталог'!$B$5:$B$19,0)),0),0)) | N10: =IF(L10="",0,IFERROR(IF(ISNUMBER(SEARCH(E10,INDEX('В01 Каталог'!$D$5:$D$19,MATCH(L10,'В01 Каталог'!$B$5:$B$19,0)))),INDEX('В01 Каталог'!$F$5:$F$19,MATCH(L10,'В01 Каталог'!$B$5:$B$19,0)),0),0)) | O10: =IF(F10="","",MAX(1,F10-M10)) | P10: =IF(G10="","",MAX(1,G10-N10)) | Q10: =IF(O10="","",O10*P10) | R10: =IF(J10<>"Так","",IF(K10="","Оберіть стратегію",IF(AND(K10="Приймати",H10>=17),"Критичний ризик не приймають",IF(AND(K10="Приймати",L10<>""),"Приймання: заходу не потрібно",IF(AND(K10<>"Приймати",L10=""),"Оберіть захід",IF(AND(K10="Передавати",L10<>"Страхування готівки та кіберризиків"),"Передача: оберіть страхування",IF(AND(K10="Уникати",L10<>"Призупинити сервіс чи функцію (уникнення, втрата бізнесу)"),"Уникнення: оберіть призупинення",IF(AND(L10<>"",M10+N10=0),"Захід не діє на цю категорію",IF(AND(L10<>"",INDEX('В01 Каталог'!$H$5:$H$19,MATCH(L10,'В01 Каталог'!$B$5:$B$19,0))="Ні"),"Захід недоступний","ОК")))))))))
A11: 7 | H11: =IF(OR(F11="",G11=""),"",F11*G11) | I11: =IF(H11="","",IF(H11<=4,"Низький",IF(H11<=9,"Середній",IF(H11<=16,"Високий","Критичний")))) | M11: =IF(L11="",0,IFERROR(IF(ISNUMBER(SEARCH(E11,INDEX('В01 Каталог'!$D$5:$D$19,MATCH(L11,'В01 Каталог'!$B$5:$B$19,0)))),INDEX('В01 Каталог'!$E$5:$E$19,MATCH(L11,'В01 Каталог'!$B$5:$B$19,0)),0),0)) | N11: =IF(L11="",0,IFERROR(IF(ISNUMBER(SEARCH(E11,INDEX('В01 Каталог'!$D$5:$D$19,MATCH(L11,'В01 Каталог'!$B$5:$B$19,0)))),INDEX('В01 Каталог'!$F$5:$F$19,MATCH(L11,'В01 Каталог'!$B$5:$B$19,0)),0),0)) | O11: =IF(F11="","",MAX(1,F11-M11)) | P11: =IF(G11="","",MAX(1,G11-N11)) | Q11: =IF(O11="","",O11*P11) | R11: =IF(J11<>"Так","",IF(K11="","Оберіть стратегію",IF(AND(K11="Приймати",H11>=17),"Критичний ризик не приймають",IF(AND(K11="Приймати",L11<>""),"Приймання: заходу не потрібно",IF(AND(K11<>"Приймати",L11=""),"Оберіть захід",IF(AND(K11="Передавати",L11<>"Страхування готівки та кіберризиків"),"Передача: оберіть страхування",IF(AND(K11="Уникати",L11<>"Призупинити сервіс чи функцію (уникнення, втрата бізнесу)"),"Уникнення: оберіть призупинення",IF(AND(L11<>"",M11+N11=0),"Захід не діє на цю категорію",IF(AND(L11<>"",INDEX('В01 Каталог'!$H$5:$H$19,MATCH(L11,'В01 Каталог'!$B$5:$B$19,0))="Ні"),"Захід недоступний","ОК")))))))))
A12: 8 | H12: =IF(OR(F12="",G12=""),"",F12*G12) | I12: =IF(H12="","",IF(H12<=4,"Низький",IF(H12<=9,"Середній",IF(H12<=16,"Високий","Критичний")))) | M12: =IF(L12="",0,IFERROR(IF(ISNUMBER(SEARCH(E12,INDEX('В01 Каталог'!$D$5:$D$19,MATCH(L12,'В01 Каталог'!$B$5:$B$19,0)))),INDEX('В01 Каталог'!$E$5:$E$19,MATCH(L12,'В01 Каталог'!$B$5:$B$19,0)),0),0)) | N12: =IF(L12="",0,IFERROR(IF(ISNUMBER(SEARCH(E12,INDEX('В01 Каталог'!$D$5:$D$19,MATCH(L12,'В01 Каталог'!$B$5:$B$19,0)))),INDEX('В01 Каталог'!$F$5:$F$19,MATCH(L12,'В01 Каталог'!$B$5:$B$19,0)),0),0)) | O12: =IF(F12="","",MAX(1,F12-M12)) | P12: =IF(G12="","",MAX(1,G12-N12)) | Q12: =IF(O12="","",O12*P12) | R12: =IF(J12<>"Так","",IF(K12="","Оберіть стратегію",IF(AND(K12="Приймати",H12>=17),"Критичний ризик не приймають",IF(AND(K12="Приймати",L12<>""),"Приймання: заходу не потрібно",IF(AND(K12<>"Приймати",L12=""),"Оберіть захід",IF(AND(K12="Передавати",L12<>"Страхування готівки та кіберризиків"),"Передача: оберіть страхування",IF(AND(K12="Уникати",L12<>"Призупинити сервіс чи функцію (уникнення, втрата бізнесу)"),"Уникнення: оберіть призупинення",IF(AND(L12<>"",M12+N12=0),"Захід не діє на цю категорію",IF(AND(L12<>"",INDEX('В01 Каталог'!$H$5:$H$19,MATCH(L12,'В01 Каталог'!$B$5:$B$19,0))="Ні"),"Захід недоступний","ОК")))))))))
A13: 9 | H13: =IF(OR(F13="",G13=""),"",F13*G13) | I13: =IF(H13="","",IF(H13<=4,"Низький",IF(H13<=9,"Середній",IF(H13<=16,"Високий","Критичний")))) | M13: =IF(L13="",0,IFERROR(IF(ISNUMBER(SEARCH(E13,INDEX('В01 Каталог'!$D$5:$D$19,MATCH(L13,'В01 Каталог'!$B$5:$B$19,0)))),INDEX('В01 Каталог'!$E$5:$E$19,MATCH(L13,'В01 Каталог'!$B$5:$B$19,0)),0),0)) | N13: =IF(L13="",0,IFERROR(IF(ISNUMBER(SEARCH(E13,INDEX('В01 Каталог'!$D$5:$D$19,MATCH(L13,'В01 Каталог'!$B$5:$B$19,0)))),INDEX('В01 Каталог'!$F$5:$F$19,MATCH(L13,'В01 Каталог'!$B$5:$B$19,0)),0),0)) | O13: =IF(F13="","",MAX(1,F13-M13)) | P13: =IF(G13="","",MAX(1,G13-N13)) | Q13: =IF(O13="","",O13*P13) | R13: =IF(J13<>"Так","",IF(K13="","Оберіть стратегію",IF(AND(K13="Приймати",H13>=17),"Критичний ризик не приймають",IF(AND(K13="Приймати",L13<>""),"Приймання: заходу не потрібно",IF(AND(K13<>"Приймати",L13=""),"Оберіть захід",IF(AND(K13="Передавати",L13<>"Страхування готівки та кіберризиків"),"Передача: оберіть страхування",IF(AND(K13="Уникати",L13<>"Призупинити сервіс чи функцію (уникнення, втрата бізнесу)"),"Уникнення: оберіть призупинення",IF(AND(L13<>"",M13+N13=0),"Захід не діє на цю категорію",IF(AND(L13<>"",INDEX('В01 Каталог'!$H$5:$H$19,MATCH(L13,'В01 Каталог'!$B$5:$B$19,0))="Ні"),"Захід недоступний","ОК")))))))))
A14: 10 | H14: =IF(OR(F14="",G14=""),"",F14*G14) | I14: =IF(H14="","",IF(H14<=4,"Низький",IF(H14<=9,"Середній",IF(H14<=16,"Високий","Критичний")))) | M14: =IF(L14="",0,IFERROR(IF(ISNUMBER(SEARCH(E14,INDEX('В01 Каталог'!$D$5:$D$19,MATCH(L14,'В01 Каталог'!$B$5:$B$19,0)))),INDEX('В01 Каталог'!$E$5:$E$19,MATCH(L14,'В01 Каталог'!$B$5:$B$19,0)),0),0)) | N14: =IF(L14="",0,IFERROR(IF(ISNUMBER(SEARCH(E14,INDEX('В01 Каталог'!$D$5:$D$19,MATCH(L14,'В01 Каталог'!$B$5:$B$19,0)))),INDEX('В01 Каталог'!$F$5:$F$19,MATCH(L14,'В01 Каталог'!$B$5:$B$19,0)),0),0)) | O14: =IF(F14="","",MAX(1,F14-M14)) | P14: =IF(G14="","",MAX(1,G14-N14)) | Q14: =IF(O14="","",O14*P14) | R14: =IF(J14<>"Так","",IF(K14="","Оберіть стратегію",IF(AND(K14="Приймати",H14>=17),"Критичний ризик не приймають",IF(AND(K14="Приймати",L14<>""),"Приймання: заходу не потрібно",IF(AND(K14<>"Приймати",L14=""),"Оберіть захід",IF(AND(K14="Передавати",L14<>"Страхування готівки та кіберризиків"),"Передача: оберіть страхування",IF(AND(K14="Уникати",L14<>"Призупинити сервіс чи функцію (уникнення, втрата бізнесу)"),"Уникнення: оберіть призупинення",IF(AND(L14<>"",M14+N14=0),"Захід не діє на цю категорію",IF(AND(L14<>"",INDEX('В01 Каталог'!$H$5:$H$19,MATCH(L14,'В01 Каталог'!$B$5:$B$19,0))="Ні"),"Захід недоступний","ОК")))))))))
A15: 11 | H15: =IF(OR(F15="",G15=""),"",F15*G15) | I15: =IF(H15="","",IF(H15<=4,"Низький",IF(H15<=9,"Середній",IF(H15<=16,"Високий","Критичний")))) | M15: =IF(L15="",0,IFERROR(IF(ISNUMBER(SEARCH(E15,INDEX('В01 Каталог'!$D$5:$D$19,MATCH(L15,'В01 Каталог'!$B$5:$B$19,0)))),INDEX('В01 Каталог'!$E$5:$E$19,MATCH(L15,'В01 Каталог'!$B$5:$B$19,0)),0),0)) | N15: =IF(L15="",0,IFERROR(IF(ISNUMBER(SEARCH(E15,INDEX('В01 Каталог'!$D$5:$D$19,MATCH(L15,'В01 Каталог'!$B$5:$B$19,0)))),INDEX('В01 Каталог'!$F$5:$F$19,MATCH(L15,'В01 Каталог'!$B$5:$B$19,0)),0),0)) | O15: =IF(F15="","",MAX(1,F15-M15)) | P15: =IF(G15="","",MAX(1,G15-N15)) | Q15: =IF(O15="","",O15*P15) | R15: =IF(J15<>"Так","",IF(K15="","Оберіть стратегію",IF(AND(K15="Приймати",H15>=17),"Критичний ризик не приймають",IF(AND(K15="Приймати",L15<>""),"Приймання: заходу не потрібно",IF(AND(K15<>"Приймати",L15=""),"Оберіть захід",IF(AND(K15="Передавати",L15<>"Страхування готівки та кіберризиків"),"Передача: оберіть страхування",IF(AND(K15="Уникати",L15<>"Призупинити сервіс чи функцію (уникнення, втрата бізнесу)"),"Уникнення: оберіть призупинення",IF(AND(L15<>"",M15+N15=0),"Захід не діє на цю категорію",IF(AND(L15<>"",INDEX('В01 Каталог'!$H$5:$H$19,MATCH(L15,'В01 Каталог'!$B$5:$B$19,0))="Ні"),"Захід недоступний","ОК")))))))))
A16: 12 | H16: =IF(OR(F16="",G16=""),"",F16*G16) | I16: =IF(H16="","",IF(H16<=4,"Низький",IF(H16<=9,"Середній",IF(H16<=16,"Високий","Критичний")))) | M16: =IF(L16="",0,IFERROR(IF(ISNUMBER(SEARCH(E16,INDEX('В01 Каталог'!$D$5:$D$19,MATCH(L16,'В01 Каталог'!$B$5:$B$19,0)))),INDEX('В01 Каталог'!$E$5:$E$19,MATCH(L16,'В01 Каталог'!$B$5:$B$19,0)),0),0)) | N16: =IF(L16="",0,IFERROR(IF(ISNUMBER(SEARCH(E16,INDEX('В01 Каталог'!$D$5:$D$19,MATCH(L16,'В01 Каталог'!$B$5:$B$19,0)))),INDEX('В01 Каталог'!$F$5:$F$19,MATCH(L16,'В01 Каталог'!$B$5:$B$19,0)),0),0)) | O16: =IF(F16="","",MAX(1,F16-M16)) | P16: =IF(G16="","",MAX(1,G16-N16)) | Q16: =IF(O16="","",O16*P16) | R16: =IF(J16<>"Так","",IF(K16="","Оберіть стратегію",IF(AND(K16="Приймати",H16>=17),"Критичний ризик не приймають",IF(AND(K16="Приймати",L16<>""),"Приймання: заходу не потрібно",IF(AND(K16<>"Приймати",L16=""),"Оберіть захід",IF(AND(K16="Передавати",L16<>"Страхування готівки та кіберризиків"),"Передача: оберіть страхування",IF(AND(K16="Уникати",L16<>"Призупинити сервіс чи функцію (уникнення, втрата бізнесу)"),"Уникнення: оберіть призупинення",IF(AND(L16<>"",M16+N16=0),"Захід не діє на цю категорію",IF(AND(L16<>"",INDEX('В01 Каталог'!$H$5:$H$19,MATCH(L16,'В01 Каталог'!$B$5:$B$19,0))="Ні"),"Захід недоступний","ОК")))))))))
... A24: 20 | H24: =IF(OR(F24="",G24=""),"",F24*G24) | I24: =IF(H24="","",IF(H24<=4,"Низький",IF(H24<=9,"Середній",IF(H24<=16,"Високий","Критичний")))) | M24: =IF(L24="",0,IFERROR(IF(ISNUMBER(SEARCH(E24,INDEX('В01 Каталог'!$D$5:$D$19,MATCH(L24,'В01 Каталог'!$B$5:$B$19,0)))),INDEX('В01 Каталог'!$E$5:$E$19,MATCH(L24,'В01 Каталог'!$B$5:$B$19,0)),0),0)) | N24: =IF(L24="",0,IFERROR(IF(ISNUMBER(SEARCH(E24,INDEX('В01 Каталог'!$D$5:$D$19,MATCH(L24,'В01 Каталог'!$B$5:$B$19,0)))),INDEX('В01 Каталог'!$F$5:$F$19,MATCH(L24,'В01 Каталог'!$B$5:$B$19,0)),0),0)) | O24: =IF(F24="","",MAX(1,F24-M24)) | P24: =IF(G24="","",MAX(1,G24-N24)) | Q24: =IF(O24="","",O24*P24) | R24: =IF(J24<>"Так","",IF(K24="","Оберіть стратегію",IF(AND(K24="Приймати",H24>=17),"Критичний ризик не приймають",IF(AND(K24="Приймати",L24<>""),"Приймання: заходу не потрібно",IF(AND(K24<>"Приймати",L24=""),"Оберіть захід",IF(AND(K24="Передавати",L24<>"Страхування готівки та кіберризиків"),"Передача: оберіть страхування",IF(AND(K24="Уникати",L24<>"Призупинити сервіс чи функцію (уникнення, втрата бізнесу)"),"Уникнення: оберіть призупинення",IF(AND(L24<>"",M24+N24=0),"Захід не діє на цю категорію",IF(AND(L24<>"",INDEX('В01 Каталог'!$H$5:$H$19,MATCH(L24,'В01 Каталог'!$B$5:$B$19,0))="Ні"),"Захід недоступний","ОК")))))))))

Sheet В01 Матриця
A1: Матриця «ймовірність × наслідки»
A2: Числа в клітинках: скільки ризиків із вашого реєстру потрапило в цю клітинку. Ліворуч, до заходів; праворуч, після заходів.
A4: До заходів | I4: Після заходів
B5: Ймовірність P → | J5: Ймовірність P →
A6: C = 5 | B6: =COUNTIFS('В01 Ризики'!$F$5:$F$24,1,'В01 Ризики'!$G$5:$G$24,5) | C6: =COUNTIFS('В01 Ризики'!$F$5:$F$24,2,'В01 Ризики'!$G$5:$G$24,5) | D6: =COUNTIFS('В01 Ризики'!$F$5:$F$24,3,'В01 Ризики'!$G$5:$G$24,5) | E6: =COUNTIFS('В01 Ризики'!$F$5:$F$24,4,'В01 Ризики'!$G$5:$G$24,5) | F6: =COUNTIFS('В01 Ризики'!$F$5:$F$24,5,'В01 Ризики'!$G$5:$G$24,5) | I6: C = 5 | J6: =COUNTIFS('В01 Ризики'!$O$5:$O$24,1,'В01 Ризики'!$P$5:$P$24,5) | K6: =COUNTIFS('В01 Ризики'!$O$5:$O$24,2,'В01 Ризики'!$P$5:$P$24,5) | L6: =COUNTIFS('В01 Ризики'!$O$5:$O$24,3,'В01 Ризики'!$P$5:$P$24,5) | M6: =COUNTIFS('В01 Ризики'!$O$5:$O$24,4,'В01 Ризики'!$P$5:$P$24,5) | N6: =COUNTIFS('В01 Ризики'!$O$5:$O$24,5,'В01 Ризики'!$P$5:$P$24,5)
A7: C = 4 | B7: =COUNTIFS('В01 Ризики'!$F$5:$F$24,1,'В01 Ризики'!$G$5:$G$24,4) | C7: =COUNTIFS('В01 Ризики'!$F$5:$F$24,2,'В01 Ризики'!$G$5:$G$24,4) | D7: =COUNTIFS('В01 Ризики'!$F$5:$F$24,3,'В01 Ризики'!$G$5:$G$24,4) | E7: =COUNTIFS('В01 Ризики'!$F$5:$F$24,4,'В01 Ризики'!$G$5:$G$24,4) | F7: =COUNTIFS('В01 Ризики'!$F$5:$F$24,5,'В01 Ризики'!$G$5:$G$24,4) | I7: C = 4 | J7: =COUNTIFS('В01 Ризики'!$O$5:$O$24,1,'В01 Ризики'!$P$5:$P$24,4) | K7: =COUNTIFS('В01 Ризики'!$O$5:$O$24,2,'В01 Ризики'!$P$5:$P$24,4) | L7: =COUNTIFS('В01 Ризики'!$O$5:$O$24,3,'В01 Ризики'!$P$5:$P$24,4) | M7: =COUNTIFS('В01 Ризики'!$O$5:$O$24,4,'В01 Ризики'!$P$5:$P$24,4) | N7: =COUNTIFS('В01 Ризики'!$O$5:$O$24,5,'В01 Ризики'!$P$5:$P$24,4)
A8: C = 3 | B8: =COUNTIFS('В01 Ризики'!$F$5:$F$24,1,'В01 Ризики'!$G$5:$G$24,3) | C8: =COUNTIFS('В01 Ризики'!$F$5:$F$24,2,'В01 Ризики'!$G$5:$G$24,3) | D8: =COUNTIFS('В01 Ризики'!$F$5:$F$24,3,'В01 Ризики'!$G$5:$G$24,3) | E8: =COUNTIFS('В01 Ризики'!$F$5:$F$24,4,'В01 Ризики'!$G$5:$G$24,3) | F8: =COUNTIFS('В01 Ризики'!$F$5:$F$24,5,'В01 Ризики'!$G$5:$G$24,3) | I8: C = 3 | J8: =COUNTIFS('В01 Ризики'!$O$5:$O$24,1,'В01 Ризики'!$P$5:$P$24,3) | K8: =COUNTIFS('В01 Ризики'!$O$5:$O$24,2,'В01 Ризики'!$P$5:$P$24,3) | L8: =COUNTIFS('В01 Ризики'!$O$5:$O$24,3,'В01 Ризики'!$P$5:$P$24,3) | M8: =COUNTIFS('В01 Ризики'!$O$5:$O$24,4,'В01 Ризики'!$P$5:$P$24,3) | N8: =COUNTIFS('В01 Ризики'!$O$5:$O$24,5,'В01 Ризики'!$P$5:$P$24,3)
A9: C = 2 | B9: =COUNTIFS('В01 Ризики'!$F$5:$F$24,1,'В01 Ризики'!$G$5:$G$24,2) | C9: =COUNTIFS('В01 Ризики'!$F$5:$F$24,2,'В01 Ризики'!$G$5:$G$24,2) | D9: =COUNTIFS('В01 Ризики'!$F$5:$F$24,3,'В01 Ризики'!$G$5:$G$24,2) | E9: =COUNTIFS('В01 Ризики'!$F$5:$F$24,4,'В01 Ризики'!$G$5:$G$24,2) | F9: =COUNTIFS('В01 Ризики'!$F$5:$F$24,5,'В01 Ризики'!$G$5:$G$24,2) | I9: C = 2 | J9: =COUNTIFS('В01 Ризики'!$O$5:$O$24,1,'В01 Ризики'!$P$5:$P$24,2) | K9: =COUNTIFS('В01 Ризики'!$O$5:$O$24,2,'В01 Ризики'!$P$5:$P$24,2) | L9: =COUNTIFS('В01 Ризики'!$O$5:$O$24,3,'В01 Ризики'!$P$5:$P$24,2) | M9: =COUNTIFS('В01 Ризики'!$O$5:$O$24,4,'В01 Ризики'!$P$5:$P$24,2) | N9: =COUNTIFS('В01 Ризики'!$O$5:$O$24,5,'В01 Ризики'!$P$5:$P$24,2)
A10: C = 1 | B10: =COUNTIFS('В01 Ризики'!$F$5:$F$24,1,'В01 Ризики'!$G$5:$G$24,1) | C10: =COUNTIFS('В01 Ризики'!$F$5:$F$24,2,'В01 Ризики'!$G$5:$G$24,1) | D10: =COUNTIFS('В01 Ризики'!$F$5:$F$24,3,'В01 Ризики'!$G$5:$G$24,1) | E10: =COUNTIFS('В01 Ризики'!$F$5:$F$24,4,'В01 Ризики'!$G$5:$G$24,1) | F10: =COUNTIFS('В01 Ризики'!$F$5:$F$24,5,'В01 Ризики'!$G$5:$G$24,1) | I10: C = 1 | J10: =COUNTIFS('В01 Ризики'!$O$5:$O$24,1,'В01 Ризики'!$P$5:$P$24,1) | K10: =COUNTIFS('В01 Ризики'!$O$5:$O$24,2,'В01 Ризики'!$P$5:$P$24,1) | L10: =COUNTIFS('В01 Ризики'!$O$5:$O$24,3,'В01 Ризики'!$P$5:$P$24,1) | M10: =COUNTIFS('В01 Ризики'!$O$5:$O$24,4,'В01 Ризики'!$P$5:$P$24,1) | N10: =COUNTIFS('В01 Ризики'!$O$5:$O$24,5,'В01 Ризики'!$P$5:$P$24,1)
B11: P = 1 | C11: P = 2 | D11: P = 3 | E11: P = 4 | F11: P = 5 | J11: P = 1 | K11: P = 2 | L11: P = 3 | M11: P = 4 | N11: P = 5
A14: Зелений: низький (1–4). Жовтий: середній (5–9). Помаранчевий: високий (10–16). Червоний: критичний (17–25).

Sheet В01 Бюджет
A1: Бюджет і ефект заходів
A4: Бюджет відділення | B4: 100
A5: Витрачено на заходи | B5: =SUM('В01 Каталог'!G5:G19)
A6: Залишок | B6: =B4-B5
A7: Перевірка бюджету | B7: =IF(B6>=0,"У межах бюджету","Перевищено на "&(-B6))
A8: Сума рівнів усіх ризиків до заходів | B8: =SUM('В01 Ризики'!H5:H24)
A9: Сума залишкових рівнів після заходів | B9: =SUM('В01 Ризики'!Q5:Q24)
A10: Зниження сукупного ризику | B10: =IF(B8=0,"",1-B9/B8)
A11: Ризики з позначкою «Топ-5» | B11: =COUNTIF('В01 Ризики'!J5:J24,"Так")
A12: Топ-5: що не так у перевірці | B12: =SUMPRODUCT(('В01 Ризики'!J5:J24="Так")*('В01 Ризики'!R5:R24<>"ОК"))
A13: Ризики у реєстрі | B13: =COUNTA('В01 Ризики'!B5:B24)
A15: Топ-5 має містити рівно 5 ризиків, у кожного з яких стратегія й захід узгоджені (колонка «Перевірка» = ОК); «Топ-5: що не так у перевірці» має дорівнювати 0.

Sheet В01 Обґрунтування
A1: Обґрунтування вибору
A2: Пишіть власні пояснення для 2–3 ризиків із топ-5 своїми словами (2–3 речення). Викладач може попросити пояснити їх усно.
A4: Ризик № (з реєстру) | B4: Нотатка | C4: Чому така стратегія і такий захід? Чому не інший? | D4: Що лишається після заходу й чому це прийнятно?
A11: Нова обставина
A12: Що сказано у файлі «Нова обставина» і які саме рядки таблиці ви змінили (ризик №, було → стало):

Sheet В02 Інструкція
A1: ПР 1. Оцінка ризиків для відділення «Банку N». Варіант 02
A2: Працюйте в жовтих комірках. Сірі комірки рахуються самі (захищені).
A4: Порядок роботи
A5: 1. Профіль | B5: Прочитайте аркуш «Профіль»: факти про ваше відділення.
A6: 2. Активи (питання 1) | B6: Складіть перелік активів (не менше 10) і оцініть цінність 1–5. Одночасно перегляньте аркуш «Чернетка»: у ній 3 помилки колеги. Запишіть їх у журнал виправлень.
A7: 3. Ризики (питання 2) | B7: Для активів запишіть ризики (не менше 12): актив, загроза, вразливість, категорія, ймовірність P та наслідки C за шкалою 1–5. Рівень і зона рахуються самі.
A8: 4. Матриця й заходи (питання 3) | B8: Аркуш «Матриця» будується автоматично. Позначте топ-5 ризиків («Так» у колонці «Топ-5»), оберіть стратегію й захід із «Каталогу». Бюджет перевіряється на аркуші «Бюджет».
A9: 5. Обґрунтування | B9: На аркуші «Обґрунтування» власними словами поясніть вибір для 2–3 ризиків із топ-5.
A10: 6. Нова обставина | B10: Коли завершите кроки 1–4, відкрийте окремий файл «Нова обставина» (не раніше). Оновіть таблицю й запишіть, що змінилось (аркуш «Обґрунтування», рядок «Інжект»).
A12: Шкала ймовірності P | B12: 1 — рідше ніж раз на 5 років · 2 — раз на 2–5 років · 3 — раз на 1–2 роки · 4 — кілька разів на рік · 5 — щомісяця і частіше
A13: Шкала наслідків C | B13: 1 — збитки до 10 тис. грн, без зупинки · 2 — 10–50 тис. грн · 3 — 50–250 тис. грн або зупинка відділення до кількох годин · 4 — 250 тис. – 1 млн грн, або зупинка на добу, або увага регулятора · 5 — понад 1 млн грн, тривала зупинка, витік даних клієнтів, серйозна репутаційна шкода
A14: Рівень ризику | B14: Рівень = P × C. 1–4 низький · 5–9 середній · 10–16 високий · 17–25 критичний
A15: Правила стратегій | B15: Критичний ризик (17–25) не приймають. «Приймати» — без заходу. «Передавати» — лише через захід «Страхування». «Уникати» — через захід «Призупинити сервіс чи функцію». «Зменшувати» — захід, що діє на категорію ризику.
A16: Бюджет | B16: 100 умовних одиниць (якщо бюджет зміниться, поправте комірку B4 на аркуші «Бюджет»). Кожен захід оплачується один раз, навіть якщо ним закрито кілька ризиків.

Sheet В02 Профіль
A1: Профіль відділення. Варіант 02
A3: Номер варіанта | B3: 02
A4: Студент (прізвище)
A5: Кількість працівників | B5: 12 (три каси, двоє менеджерів, керівник, операціоніст та інші)
A6: Банкомати | B6: 2: один у залі, один на вулиці
A7: POS-термінали | B7: 4
A8: Вуличний банкомат: освітлення | B8: добре
A9: Вуличний банкомат: камера | B9: є
A10: Готівка у вуличному банкоматі | B10: до 215 тис. грн
A11: Транзакцій на добу на вуличному банкоматі | B11: 130
A12: Резервне живлення | B12: генератор і ДБЖ
A13: Відключення електроенергії | B13: у середньому 2 год на добу
A14: Канал зв'язку з головним офісом | B14: два канали
A15: Спроб вішингу за останній рік (внутрішній облік) | B15: 0
A16: Особливий актив відділення | B16: Сервер відеоспостереження з віддаленим веб-доступом
... A18: Захід, недоступний у цьому кварталі | B18: немає

Sheet В02 Каталог
A1: Каталог заходів безпеки
A2: Вартість в умовних одиницях. ΔP і ΔC: на скільки балів захід знижує ймовірність і наслідки (лише для зазначених категорій).
A4: Код | B4: Назва заходу | C4: Вартість | D4: Діє на категорії ризику | E4: ΔP | F4: ΔC | G4: Оплачено | H4: Доступний
A5: M1 | B5: Навчання персоналу з фішингу та вішингу | C5: 10 | D5: Соціальна інженерія | E5: 1 | F5: 0 | G5: =IF(COUNTIF('В02 Ризики'!$L$5:$L$24,B5)>0,C5,0) | H5: Так
A6: M2 | B6: Багатофакторна автентифікація для адміністраторів і ДБО | C6: 15 | D6: Мережа/ІТ; Соціальна інженерія | E6: 2 | F6: 0 | G6: =IF(COUNTIF('В02 Ризики'!$L$5:$L$24,B6)>0,C6,0) | H6: Так
A7: M3 | B7: Антискімінгові накладки та датчик відкриття корпусу банкомата | C7: 12 | D7: Шахрайство з картками | E7: 2 | F7: 0 | G7: =IF(COUNTIF('В02 Ризики'!$L$5:$L$24,B7)>0,C7,0) | H7: Так
A8: M4 | B8: Освітлення та камера біля вуличного банкомата | C8: 8 | D8: Фізичний доступ; Шахрайство з картками | E8: 1 | F8: 0 | G8: =IF(COUNTIF('В02 Ризики'!$L$5:$L$24,B8)>0,C8,0) | H8: Так
A9: M5 | B9: Резервний канал зв'язку (LTE) | C9: 14 | D9: Живлення і зв'язок | E9: 2 | F9: 0 | G9: =IF(COUNTIF('В02 Ризики'!$L$5:$L$24,B9)>0,C9,0) | H9: Так
A10: M6 | B10: Генератор і ДБЖ | C10: 18 | D10: Живлення і зв'язок | E10: 2 | F10: 1 | G10: =IF(COUNTIF('В02 Ризики'!$L$5:$L$24,B10)>0,C10,0) | H10: Так
A11: M7 | B11: Сегментація мережі (VLAN, списки доступу) | C11: 16 | D11: Мережа/ІТ | E11: 1 | F11: 2 | G11: =IF(COUNTIF('В02 Ризики'!$L$5:$L$24,B11)>0,C11,0) | H11: Так
A12: M8 | B12: Резервні копії з перевіркою відновлення | C12: 12 | D12: Мережа/ІТ; Живлення і зв'язок | E12: 0 | F12: 2 | G12: =IF(COUNTIF('В02 Ризики'!$L$5:$L$24,B12)>0,C12,0) | H12: Так
A13: M9 | B13: Оновлення ПЗ за графіком | C13: 9 | D13: Мережа/ІТ | E13: 1 | F13: 0 | G13: =IF(COUNTIF('В02 Ризики'!$L$5:$L$24,B13)>0,C13,0) | H13: Так
A14: M10 | B14: Страхування готівки та кіберризиків | C14: 20 | D14: Фізичний доступ; Шахрайство з картками; Мережа/ІТ | E14: 0 | F14: 2 | G14: =IF(COUNTIF('В02 Ризики'!$L$5:$L$24,B14)>0,C14,0) | H14: Так
A15: M11 | B15: Електронні замки та журнал входу в серверну | C15: 10 | D15: Фізичний доступ; Персонал і процеси | E15: 1 | F15: 1 | G15: =IF(COUNTIF('В02 Ризики'!$L$5:$L$24,B15)>0,C15,0) | H15: Так
A16: M12 | B16: Захист від DDoS (послуга оператора) | C16: 17 | D16: Мережа/ІТ | E16: 2 | F16: 1 | G16: =IF(COUNTIF('В02 Ризики'!$L$5:$L$24,B16)>0,C16,0) | H16: Так
... A19: M15 | B19: Призупинити сервіс чи функцію (уникнення, втрата бізнесу) | C19: 6 | D19: Соціальна інженерія; Фізичний доступ; Шахрайство з картками; Мережа/ІТ; Живлення і зв'язок; Персонал і процеси | E19: 3 | F19: 0 | G19: =IF(COUNTIF('В02 Ризики'!$L$5:$L$24,B19)>0,C19,0) | H19: Так
B20: Разом | C20: =SUM(C5:C18) | G20: =SUM(G5:G19)
B21: Разом у рядку «Разом» вартість M1–M14 (без уникнення)

Sheet В02 Активи
A1: Активи відділення (питання 1)
A2: Не менше 10 активів. Цінність: 1 — незначна, 5 — критична для роботи банку.
A4: № | B4: Актив | C4: Група | D4: Власник (роль) | E4: Цінність 1–5 | F4: Чому цінний
A5: 1
A6: 2
A7: 3
A8: 4
A9: 5
A10: 6
A11: 7
A12: 8
A13: 9
A14: 10
A15: 11
A16: 12
... A24: 20

Sheet В02 Чернетка
A1: Чернетка таблиці ризиків від колеги
A2: У ній є три помилки. Знайдіть їх, запишіть у журнал виправлень (нижче) і не переносьте у свою таблицю без виправлення.
A4: № | B4: Актив | C4: Ризик | D4: Вразливість | E4: P | F4: C | G4: Коментар колеги
A5: 1 | B5: Вуличний банкомат (готівка) | C5: Злам банкомата з метою вилучення готівки | D5: камера є, освітлення добре | E5: 4 | F5: 4 | G5: другий запис, інші слова
A6: 2 | B6: Вуличний банкомат (картки клієнтів) | C6: Встановлення скімера й масове копіювання карток | D6: камера є, освітлення добре | E6: 2 | F6: 3 | G6: оцінено за даними профілю
A7: 3 | C7: Фішинг | E7: 4 | F7: 4 | G7: Дуже небезпечно, треба бачити
A8: 4 | B8: Канал зв'язку з головним офісом | C8: Відмова каналу до головного офісу | D8: два канали | E8: 2 | F8: 3 | G8: оцінено за даними профілю
A9: 5 | B9: Серверна | C9: Пожежа в серверній | D9: немає автоматичного пожежогасіння | E9: 5 | F9: 5 | G9: За останні сім років було лише один такий випадок у нашій мережі
A10: 6 | B10: Вуличний банкомат (готівка) | C10: Крадіжка готівки з вуличного банкомата | D10: камера є, освітлення добре | E10: 4 | F10: 4 | G10: перший з двох записів про одне й те саме
A11: 7 | B11: Серверна й обладнання відділення | C11: Зловживання правами недобросовісним співробітником | D11: права адміністратора в кількох працівників, журнали не переглядають | E11: 2 | F11: 4 | G11: оцінено за політикою доступу
A13: Журнал виправлень
A14: Рядок | B14: Тип помилки | C14: Що не так і як виправлено

Sheet В02 Ризики
A1: Реєстр ризиків (питання 2 і 3)
A2: Один ризик = актив + загроза + вразливість. P і C за шкалами з аркуша «Інструкція».
A4: № | B4: Актив | C4: Загроза (що може статися) | D4: Вразливість | E4: Категорія | F4: P | G4: C | H4: Рівень | I4: Зона | J4: Топ-5 | K4: Стратегія | L4: Захід (з Каталогу) | M4: ΔP | N4: ΔC | O4: P після | P4: C після | Q4: Залишковий рівень | R4: Перевірка | S4: Примітка
A5: 1 | H5: =IF(OR(F5="",G5=""),"",F5*G5) | I5: =IF(H5="","",IF(H5<=4,"Низький",IF(H5<=9,"Середній",IF(H5<=16,"Високий","Критичний")))) | M5: =IF(L5="",0,IFERROR(IF(ISNUMBER(SEARCH(E5,INDEX('В02 Каталог'!$D$5:$D$19,MATCH(L5,'В02 Каталог'!$B$5:$B$19,0)))),INDEX('В02 Каталог'!$E$5:$E$19,MATCH(L5,'В02 Каталог'!$B$5:$B$19,0)),0),0)) | N5: =IF(L5="",0,IFERROR(IF(ISNUMBER(SEARCH(E5,INDEX('В02 Каталог'!$D$5:$D$19,MATCH(L5,'В02 Каталог'!$B$5:$B$19,0)))),INDEX('В02 Каталог'!$F$5:$F$19,MATCH(L5,'В02 Каталог'!$B$5:$B$19,0)),0),0)) | O5: =IF(F5="","",MAX(1,F5-M5)) | P5: =IF(G5="","",MAX(1,G5-N5)) | Q5: =IF(O5="","",O5*P5) | R5: =IF(J5<>"Так","",IF(K5="","Оберіть стратегію",IF(AND(K5="Приймати",H5>=17),"Критичний ризик не приймають",IF(AND(K5="Приймати",L5<>""),"Приймання: заходу не потрібно",IF(AND(K5<>"Приймати",L5=""),"Оберіть захід",IF(AND(K5="Передавати",L5<>"Страхування готівки та кіберризиків"),"Передача: оберіть страхування",IF(AND(K5="Уникати",L5<>"Призупинити сервіс чи функцію (уникнення, втрата бізнесу)"),"Уникнення: оберіть призупинення",IF(AND(L5<>"",M5+N5=0),"Захід не діє на цю категорію",IF(AND(L5<>"",INDEX('В02 Каталог'!$H$5:$H$19,MATCH(L5,'В02 Каталог'!$B$5:$B$19,0))="Ні"),"Захід недоступний","ОК")))))))))
A6: 2 | H6: =IF(OR(F6="",G6=""),"",F6*G6) | I6: =IF(H6="","",IF(H6<=4,"Низький",IF(H6<=9,"Середній",IF(H6<=16,"Високий","Критичний")))) | M6: =IF(L6="",0,IFERROR(IF(ISNUMBER(SEARCH(E6,INDEX('В02 Каталог'!$D$5:$D$19,MATCH(L6,'В02 Каталог'!$B$5:$B$19,0)))),INDEX('В02 Каталог'!$E$5:$E$19,MATCH(L6,'В02 Каталог'!$B$5:$B$19,0)),0),0)) | N6: =IF(L6="",0,IFERROR(IF(ISNUMBER(SEARCH(E6,INDEX('В02 Каталог'!$D$5:$D$19,MATCH(L6,'В02 Каталог'!$B$5:$B$19,0)))),INDEX('В02 Каталог'!$F$5:$F$19,MATCH(L6,'В02 Каталог'!$B$5:$B$19,0)),0),0)) | O6: =IF(F6="","",MAX(1,F6-M6)) | P6: =IF(G6="","",MAX(1,G6-N6)) | Q6: =IF(O6="","",O6*P6) | R6: =IF(J6<>"Так","",IF(K6="","Оберіть стратегію",IF(AND(K6="Приймати",H6>=17),"Критичний ризик не приймають",IF(AND(K6="Приймати",L6<>""),"Приймання: заходу не потрібно",IF(AND(K6<>"Приймати",L6=""),"Оберіть захід",IF(AND(K6="Передавати",L6<>"Страхування готівки та кіберризиків"),"Передача: оберіть страхування",IF(AND(K6="Уникати",L6<>"Призупинити сервіс чи функцію (уникнення, втрата бізнесу)"),"Уникнення: оберіть призупинення",IF(AND(L6<>"",M6+N6=0),"Захід не діє на цю категорію",IF(AND(L6<>"",INDEX('В02 Каталог'!$H$5:$H$19,MATCH(L6,'В02 Каталог'!$B$5:$B$19,0))="Ні"),"Захід недоступний","ОК")))))))))
A7: 3 | H7: =IF(OR(F7="",G7=""),"",F7*G7) | I7: =IF(H7="","",IF(H7<=4,"Низький",IF(H7<=9,"Середній",IF(H7<=16,"Високий","Критичний")))) | M7: =IF(L7="",0,IFERROR(IF(ISNUMBER(SEARCH(E7,INDEX('В02 Каталог'!$D$5:$D$19,MATCH(L7,'В02 Каталог'!$B$5:$B$19,0)))),INDEX('В02 Каталог'!$E$5:$E$19,MATCH(L7,'В02 Каталог'!$B$5:$B$19,0)),0),0)) | N7: =IF(L7="",0,IFERROR(IF(ISNUMBER(SEARCH(E7,INDEX('В02 Каталог'!$D$5:$D$19,MATCH(L7,'В02 Каталог'!$B$5:$B$19,0)))),INDEX('В02 Каталог'!$F$5:$F$19,MATCH(L7,'В02 Каталог'!$B$5:$B$19,0)),0),0)) | O7: =IF(F7="","",MAX(1,F7-M7)) | P7: =IF(G7="","",MAX(1,G7-N7)) | Q7: =IF(O7="","",O7*P7) | R7: =IF(J7<>"Так","",IF(K7="","Оберіть стратегію",IF(AND(K7="Приймати",H7>=17),"Критичний ризик не приймають",IF(AND(K7="Приймати",L7<>""),"Приймання: заходу не потрібно",IF(AND(K7<>"Приймати",L7=""),"Оберіть захід",IF(AND(K7="Передавати",L7<>"Страхування готівки та кіберризиків"),"Передача: оберіть страхування",IF(AND(K7="Уникати",L7<>"Призупинити сервіс чи функцію (уникнення, втрата бізнесу)"),"Уникнення: оберіть призупинення",IF(AND(L7<>"",M7+N7=0),"Захід не діє на цю категорію",IF(AND(L7<>"",INDEX('В02 Каталог'!$H$5:$H$19,MATCH(L7,'В02 Каталог'!$B$5:$B$19,0))="Ні"),"Захід недоступний","ОК")))))))))
A8: 4 | H8: =IF(OR(F8="",G8=""),"",F8*G8) | I8: =IF(H8="","",IF(H8<=4,"Низький",IF(H8<=9,"Середній",IF(H8<=16,"Високий","Критичний")))) | M8: =IF(L8="",0,IFERROR(IF(ISNUMBER(SEARCH(E8,INDEX('В02 Каталог'!$D$5:$D$19,MATCH(L8,'В02 Каталог'!$B$5:$B$19,0)))),INDEX('В02 Каталог'!$E$5:$E$19,MATCH(L8,'В02 Каталог'!$B$5:$B$19,0)),0),0)) | N8: =IF(L8="",0,IFERROR(IF(ISNUMBER(SEARCH(E8,INDEX('В02 Каталог'!$D$5:$D$19,MATCH(L8,'В02 Каталог'!$B$5:$B$19,0)))),INDEX('В02 Каталог'!$F$5:$F$19,MATCH(L8,'В02 Каталог'!$B$5:$B$19,0)),0),0)) | O8: =IF(F8="","",MAX(1,F8-M8)) | P8: =IF(G8="","",MAX(1,G8-N8)) | Q8: =IF(O8="","",O8*P8) | R8: =IF(J8<>"Так","",IF(K8="","Оберіть стратегію",IF(AND(K8="Приймати",H8>=17),"Критичний ризик не приймають",IF(AND(K8="Приймати",L8<>""),"Приймання: заходу не потрібно",IF(AND(K8<>"Приймати",L8=""),"Оберіть захід",IF(AND(K8="Передавати",L8<>"Страхування готівки та кіберризиків"),"Передача: оберіть страхування",IF(AND(K8="Уникати",L8<>"Призупинити сервіс чи функцію (уникнення, втрата бізнесу)"),"Уникнення: оберіть призупинення",IF(AND(L8<>"",M8+N8=0),"Захід не діє на цю категорію",IF(AND(L8<>"",INDEX('В02 Каталог'!$H$5:$H$19,MATCH(L8,'В02 Каталог'!$B$5:$B$19,0))="Ні"),"Захід недоступний","ОК")))))))))
A9: 5 | H9: =IF(OR(F9="",G9=""),"",F9*G9) | I9: =IF(H9="","",IF(H9<=4,"Низький",IF(H9<=9,"Середній",IF(H9<=16,"Високий","Критичний")))) | M9: =IF(L9="",0,IFERROR(IF(ISNUMBER(SEARCH(E9,INDEX('В02 Каталог'!$D$5:$D$19,MATCH(L9,'В02 Каталог'!$B$5:$B$19,0)))),INDEX('В02 Каталог'!$E$5:$E$19,MATCH(L9,'В02 Каталог'!$B$5:$B$19,0)),0),0)) | N9: =IF(L9="",0,IFERROR(IF(ISNUMBER(SEARCH(E9,INDEX('В02 Каталог'!$D$5:$D$19,MATCH(L9,'В02 Каталог'!$B$5:$B$19,0)))),INDEX('В02 Каталог'!$F$5:$F$19,MATCH(L9,'В02 Каталог'!$B$5:$B$19,0)),0),0)) | O9: =IF(F9="","",MAX(1,F9-M9)) | P9: =IF(G9="","",MAX(1,G9-N9)) | Q9: =IF(O9="","",O9*P9) | R9: =IF(J9<>"Так","",IF(K9="","Оберіть стратегію",IF(AND(K9="Приймати",H9>=17),"Критичний ризик не приймають",IF(AND(K9="Приймати",L9<>""),"Приймання: заходу не потрібно",IF(AND(K9<>"Приймати",L9=""),"Оберіть захід",IF(AND(K9="Передавати",L9<>"Страхування готівки та кіберризиків"),"Передача: оберіть страхування",IF(AND(K9="Уникати",L9<>"Призупинити сервіс чи функцію (уникнення, втрата бізнесу)"),"Уникнення: оберіть призупинення",IF(AND(L9<>"",M9+N9=0),"Захід не діє на цю категорію",IF(AND(L9<>"",INDEX('В02 Каталог'!$H$5:$H$19,MATCH(L9,'В02 Каталог'!$B$5:$B$19,0))="Ні"),"Захід недоступний","ОК")))))))))
A10: 6 | H10: =IF(OR(F10="",G10=""),"",F10*G10) | I10: =IF(H10="","",IF(H10<=4,"Низький",IF(H10<=9,"Середній",IF(H10<=16,"Високий","Критичний")))) | M10: =IF(L10="",0,IFERROR(IF(ISNUMBER(SEARCH(E10,INDEX('В02 Каталог'!$D$5:$D$19,MATCH(L10,'В02 Каталог'!$B$5:$B$19,0)))),INDEX('В02 Каталог'!$E$5:$E$19,MATCH(L10,'В02 Каталог'!$B$5:$B$19,0)),0),0)) | N10: =IF(L10="",0,IFERROR(IF(ISNUMBER(SEARCH(E10,INDEX('В02 Каталог'!$D$5:$D$19,MATCH(L10,'В02 Каталог'!$B$5:$B$19,0)))),INDEX('В02 Каталог'!$F$5:$F$19,MATCH(L10,'В02 Каталог'!$B$5:$B$19,0)),0),0)) | O10: =IF(F10="","",MAX(1,F10-M10)) | P10: =IF(G10="","",MAX(1,G10-N10)) | Q10: =IF(O10="","",O10*P10) | R10: =IF(J10<>"Так","",IF(K10="","Оберіть стратегію",IF(AND(K10="Приймати",H10>=17),"Критичний ризик не приймають",IF(AND(K10="Приймати",L10<>""),"Приймання: заходу не потрібно",IF(AND(K10<>"Приймати",L10=""),"Оберіть захід",IF(AND(K10="Передавати",L10<>"Страхування готівки та кіберризиків"),"Передача: оберіть страхування",IF(AND(K10="Уникати",L10<>"Призупинити сервіс чи функцію (уникнення, втрата бізнесу)"),"Уникнення: оберіть призупинення",IF(AND(L10<>"",M10+N10=0),"Захід не діє на цю категорію",IF(AND(L10<>"",INDEX('В02 Каталог'!$H$5:$H$19,MATCH(L10,'В02 Каталог'!$B$5:$B$19,0))="Ні"),"Захід недоступний","ОК")))))))))
A11: 7 | H11: =IF(OR(F11="",G11=""),"",F11*G11) | I11: =IF(H11="","",IF(H11<=4,"Низький",IF(H11<=9,"Середній",IF(H11<=16,"Високий","Критичний")))) | M11: =IF(L11="",0,IFERROR(IF(ISNUMBER(SEARCH(E11,INDEX('В02 Каталог'!$D$5:$D$19,MATCH(L11,'В02 Каталог'!$B$5:$B$19,0)))),INDEX('В02 Каталог'!$E$5:$E$19,MATCH(L11,'В02 Каталог'!$B$5:$B$19,0)),0),0)) | N11: =IF(L11="",0,IFERROR(IF(ISNUMBER(SEARCH(E11,INDEX('В02 Каталог'!$D$5:$D$19,MATCH(L11,'В02 Каталог'!$B$5:$B$19,0)))),INDEX('В02 Каталог'!$F$5:$F$19,MATCH(L11,'В02 Каталог'!$B$5:$B$19,0)),0),0)) | O11: =IF(F11="","",MAX(1,F11-M11)) | P11: =IF(G11="","",MAX(1,G11-N11)) | Q11: =IF(O11="","",O11*P11) | R11: =IF(J11<>"Так","",IF(K11="","Оберіть стратегію",IF(AND(K11="Приймати",H11>=17),"Критичний ризик не приймають",IF(AND(K11="Приймати",L11<>""),"Приймання: заходу не потрібно",IF(AND(K11<>"Приймати",L11=""),"Оберіть захід",IF(AND(K11="Передавати",L11<>"Страхування готівки та кіберризиків"),"Передача: оберіть страхування",IF(AND(K11="Уникати",L11<>"Призупинити сервіс чи функцію (уникнення, втрата бізнесу)"),"Уникнення: оберіть призупинення",IF(AND(L11<>"",M11+N11=0),"Захід не діє на цю категорію",IF(AND(L11<>"",INDEX('В02 Каталог'!$H$5:$H$19,MATCH(L11,'В02 Каталог'!$B$5:$B$19,0))="Ні"),"Захід недоступний","ОК")))))))))
A12: 8 | H12: =IF(OR(F12="",G12=""),"",F12*G12) | I12: =IF(H12="","",IF(H12<=4,"Низький",IF(H12<=9,"Середній",IF(H12<=16,"Високий","Критичний")))) | M12: =IF(L12="",0,IFERROR(IF(ISNUMBER(SEARCH(E12,INDEX('В02 Каталог'!$D$5:$D$19,MATCH(L12,'В02 Каталог'!$B$5:$B$19,0)))),INDEX('В02 Каталог'!$E$5:$E$19,MATCH(L12,'В02 Каталог'!$B$5:$B$19,0)),0),0)) | N12: =IF(L12="",0,IFERROR(IF(ISNUMBER(SEARCH(E12,INDEX('В02 Каталог'!$D$5:$D$19,MATCH(L12,'В02 Каталог'!$B$5:$B$19,0)))),INDEX('В02 Каталог'!$F$5:$F$19,MATCH(L12,'В02 Каталог'!$B$5:$B$19,0)),0),0)) | O12: =IF(F12="","",MAX(1,F12-M12)) | P12: =IF(G12="","",MAX(1,G12-N12)) | Q12: =IF(O12="","",O12*P12) | R12: =IF(J12<>"Так","",IF(K12="","Оберіть стратегію",IF(AND(K12="Приймати",H12>=17),"Критичний ризик не приймають",IF(AND(K12="Приймати",L12<>""),"Приймання: заходу не потрібно",IF(AND(K12<>"Приймати",L12=""),"Оберіть захід",IF(AND(K12="Передавати",L12<>"Страхування готівки та кіберризиків"),"Передача: оберіть страхування",IF(AND(K12="Уникати",L12<>"Призупинити сервіс чи функцію (уникнення, втрата бізнесу)"),"Уникнення: оберіть призупинення",IF(AND(L12<>"",M12+N12=0),"Захід не діє на цю категорію",IF(AND(L12<>"",INDEX('В02 Каталог'!$H$5:$H$19,MATCH(L12,'В02 Каталог'!$B$5:$B$19,0))="Ні"),"Захід недоступний","ОК")))))))))
A13: 9 | H13: =IF(OR(F13="",G13=""),"",F13*G13) | I13: =IF(H13="","",IF(H13<=4,"Низький",IF(H13<=9,"Середній",IF(H13<=16,"Високий","Критичний")))) | M13: =IF(L13="",0,IFERROR(IF(ISNUMBER(SEARCH(E13,INDEX('В02 Каталог'!$D$5:$D$19,MATCH(L13,'В02 Каталог'!$B$5:$B$19,0)))),INDEX('В02 Каталог'!$E$5:$E$19,MATCH(L13,'В02 Каталог'!$B$5:$B$19,0)),0),0)) | N13: =IF(L13="",0,IFERROR(IF(ISNUMBER(SEARCH(E13,INDEX('В02 Каталог'!$D$5:$D$19,MATCH(L13,'В02 Каталог'!$B$5:$B$19,0)))),INDEX('В02 Каталог'!$F$5:$F$19,MATCH(L13,'В02 Каталог'!$B$5:$B$19,0)),0),0)) | O13: =IF(F13="","",MAX(1,F13-M13)) | P13: =IF(G13="","",MAX(1,G13-N13)) | Q13: =IF(O13="","",O13*P13) | R13: =IF(J13<>"Так","",IF(K13="","Оберіть стратегію",IF(AND(K13="Приймати",H13>=17),"Критичний ризик не приймають",IF(AND(K13="Приймати",L13<>""),"Приймання: заходу не потрібно",IF(AND(K13<>"Приймати",L13=""),"Оберіть захід",IF(AND(K13="Передавати",L13<>"Страхування готівки та кіберризиків"),"Передача: оберіть страхування",IF(AND(K13="Уникати",L13<>"Призупинити сервіс чи функцію (уникнення, втрата бізнесу)"),"Уникнення: оберіть призупинення",IF(AND(L13<>"",M13+N13=0),"Захід не діє на цю категорію",IF(AND(L13<>"",INDEX('В02 Каталог'!$H$5:$H$19,MATCH(L13,'В02 Каталог'!$B$5:$B$19,0))="Ні"),"Захід недоступний","ОК")))))))))
A14: 10 | H14: =IF(OR(F14="",G14=""),"",F14*G14) | I14: =IF(H14="","",IF(H14<=4,"Низький",IF(H14<=9,"Середній",IF(H14<=16,"Високий","Критичний")))) | M14: =IF(L14="",0,IFERROR(IF(ISNUMBER(SEARCH(E14,INDEX('В02 Каталог'!$D$5:$D$19,MATCH(L14,'В02 Каталог'!$B$5:$B$19,0)))),INDEX('В02 Каталог'!$E$5:$E$19,MATCH(L14,'В02 Каталог'!$B$5:$B$19,0)),0),0)) | N14: =IF(L14="",0,IFERROR(IF(ISNUMBER(SEARCH(E14,INDEX('В02 Каталог'!$D$5:$D$19,MATCH(L14,'В02 Каталог'!$B$5:$B$19,0)))),INDEX('В02 Каталог'!$F$5:$F$19,MATCH(L14,'В02 Каталог'!$B$5:$B$19,0)),0),0)) | O14: =IF(F14="","",MAX(1,F14-M14)) | P14: =IF(G14="","",MAX(1,G14-N14)) | Q14: =IF(O14="","",O14*P14) | R14: =IF(J14<>"Так","",IF(K14="","Оберіть стратегію",IF(AND(K14="Приймати",H14>=17),"Критичний ризик не приймають",IF(AND(K14="Приймати",L14<>""),"Приймання: заходу не потрібно",IF(AND(K14<>"Приймати",L14=""),"Оберіть захід",IF(AND(K14="Передавати",L14<>"Страхування готівки та кіберризиків"),"Передача: оберіть страхування",IF(AND(K14="Уникати",L14<>"Призупинити сервіс чи функцію (уникнення, втрата бізнесу)"),"Уникнення: оберіть призупинення",IF(AND(L14<>"",M14+N14=0),"Захід не діє на цю категорію",IF(AND(L14<>"",INDEX('В02 Каталог'!$H$5:$H$19,MATCH(L14,'В02 Каталог'!$B$5:$B$19,0))="Ні"),"Захід недоступний","ОК")))))))))
A15: 11 | H15: =IF(OR(F15="",G15=""),"",F15*G15) | I15: =IF(H15="","",IF(H15<=4,"Низький",IF(H15<=9,"Середній",IF(H15<=16,"Високий","Критичний")))) | M15: =IF(L15="",0,IFERROR(IF(ISNUMBER(SEARCH(E15,INDEX('В02 Каталог'!$D$5:$D$19,MATCH(L15,'В02 Каталог'!$B$5:$B$19,0)))),INDEX('В02 Каталог'!$E$5:$E$19,MATCH(L15,'В02 Каталог'!$B$5:$B$19,0)),0),0)) | N15: =IF(L15="",0,IFERROR(IF(ISNUMBER(SEARCH(E15,INDEX('В02 Каталог'!$D$5:$D$19,MATCH(L15,'В02 Каталог'!$B$5:$B$19,0)))),INDEX('В02 Каталог'!$F$5:$F$19,MATCH(L15,'В02 Каталог'!$B$5:$B$19,0)),0),0)) | O15: =IF(F15="","",MAX(1,F15-M15)) | P15: =IF(G15="","",MAX(1,G15-N15)) | Q15: =IF(O15="","",O15*P15) | R15: =IF(J15<>"Так","",IF(K15="","Оберіть стратегію",IF(AND(K15="Приймати",H15>=17),"Критичний ризик не приймають",IF(AND(K15="Приймати",L15<>""),"Приймання: заходу не потрібно",IF(AND(K15<>"Приймати",L15=""),"Оберіть захід",IF(AND(K15="Передавати",L15<>"Страхування готівки та кіберризиків"),"Передача: оберіть страхування",IF(AND(K15="Уникати",L15<>"Призупинити сервіс чи функцію (уникнення, втрата бізнесу)"),"Уникнення: оберіть призупинення",IF(AND(L15<>"",M15+N15=0),"Захід не діє на цю категорію",IF(AND(L15<>"",INDEX('В02 Каталог'!$H$5:$H$19,MATCH(L15,'В02 Каталог'!$B$5:$B$19,0))="Ні"),"Захід недоступний","ОК")))))))))
A16: 12 | H16: =IF(OR(F16="",G16=""),"",F16*G16) | I16: =IF(H16="","",IF(H16<=4,"Низький",IF(H16<=9,"Середній",IF(H16<=16,"Високий","Критичний")))) | M16: =IF(L16="",0,IFERROR(IF(ISNUMBER(SEARCH(E16,INDEX('В02 Каталог'!$D$5:$D$19,MATCH(L16,'В02 Каталог'!$B$5:$B$19,0)))),INDEX('В02 Каталог'!$E$5:$E$19,MATCH(L16,'В02 Каталог'!$B$5:$B$19,0)),0),0)) | N16: =IF(L16="",0,IFERROR(IF(ISNUMBER(SEARCH(E16,INDEX('В02 Каталог'!$D$5:$D$19,MATCH(L16,'В02 Каталог'!$B$5:$B$19,0)))),INDEX('В02 Каталог'!$F$5:$F$19,MATCH(L16,'В02 Каталог'!$B$5:$B$19,0)),0),0)) | O16: =IF(F16="","",MAX(1,F16-M16)) | P16: =IF(G16="","",MAX(1,G16-N16)) | Q16: =IF(O16="","",O16*P16) | R16: =IF(J16<>"Так","",IF(K16="","Оберіть стратегію",IF(AND(K16="Приймати",H16>=17),"Критичний ризик не приймають",IF(AND(K16="Приймати",L16<>""),"Приймання: заходу не потрібно",IF(AND(K16<>"Приймати",L16=""),"Оберіть захід",IF(AND(K16="Передавати",L16<>"Страхування готівки та кіберризиків"),"Передача: оберіть страхування",IF(AND(K16="Уникати",L16<>"Призупинити сервіс чи функцію (уникнення, втрата бізнесу)"),"Уникнення: оберіть призупинення",IF(AND(L16<>"",M16+N16=0),"Захід не діє на цю категорію",IF(AND(L16<>"",INDEX('В02 Каталог'!$H$5:$H$19,MATCH(L16,'В02 Каталог'!$B$5:$B$19,0))="Ні"),"Захід недоступний","ОК")))))))))
... A24: 20 | H24: =IF(OR(F24="",G24=""),"",F24*G24) | I24: =IF(H24="","",IF(H24<=4,"Низький",IF(H24<=9,"Середній",IF(H24<=16,"Високий","Критичний")))) | M24: =IF(L24="",0,IFERROR(IF(ISNUMBER(SEARCH(E24,INDEX('В02 Каталог'!$D$5:$D$19,MATCH(L24,'В02 Каталог'!$B$5:$B$19,0)))),INDEX('В02 Каталог'!$E$5:$E$19,MATCH(L24,'В02 Каталог'!$B$5:$B$19,0)),0),0)) | N24: =IF(L24="",0,IFERROR(IF(ISNUMBER(SEARCH(E24,INDEX('В02 Каталог'!$D$5:$D$19,MATCH(L24,'В02 Каталог'!$B$5:$B$19,0)))),INDEX('В02 Каталог'!$F$5:$F$19,MATCH(L24,'В02 Каталог'!$B$5:$B$19,0)),0),0)) | O24: =IF(F24="","",MAX(1,F24-M24)) | P24: =IF(G24="","",MAX(1,G24-N24)) | Q24: =IF(O24="","",O24*P24) | R24: =IF(J24<>"Так","",IF(K24="","Оберіть стратегію",IF(AND(K24="Приймати",H24>=17),"Критичний ризик не приймають",IF(AND(K24="Приймати",L24<>""),"Приймання: заходу не потрібно",IF(AND(K24<>"Приймати",L24=""),"Оберіть захід",IF(AND(K24="Передавати",L24<>"Страхування готівки та кіберризиків"),"Передача: оберіть страхування",IF(AND(K24="Уникати",L24<>"Призупинити сервіс чи функцію (уникнення, втрата бізнесу)"),"Уникнення: оберіть призупинення",IF(AND(L24<>"",M24+N24=0),"Захід не діє на цю категорію",IF(AND(L24<>"",INDEX('В02 Каталог'!$H$5:$H$19,MATCH(L24,'В02 Каталог'!$B$5:$B$19,0))="Ні"),"Захід недоступний","ОК")))))))))

Sheet В02 Матриця
A1: Матриця «ймовірність × наслідки»
A2: Числа в клітинках: скільки ризиків із вашого реєстру потрапило в цю клітинку. Ліворуч, до заходів; праворуч, після заходів.
A4: До заходів | I4: Після заходів
B5: Ймовірність P → | J5: Ймовірність P →
A6: C = 5 | B6: =COUNTIFS('В02 Ризики'!$F$5:$F$24,1,'В02 Ризики'!$G$5:$G$24,5) | C6: =COUNTIFS('В02 Ризики'!$F$5:$F$24,2,'В02 Ризики'!$G$5:$G$24,5) | D6: =COUNTIFS('В02 Ризики'!$F$5:$F$24,3,'В02 Ризики'!$G$5:$G$24,5) | E6: =COUNTIFS('В02 Ризики'!$F$5:$F$24,4,'В02 Ризики'!$G$5:$G$24,5) | F6: =COUNTIFS('В02 Ризики'!$F$5:$F$24,5,'В02 Ризики'!$G$5:$G$24,5) | I6: C = 5 | J6: =COUNTIFS('В02 Ризики'!$O$5:$O$24,1,'В02 Ризики'!$P$5:$P$24,5) | K6: =COUNTIFS('В02 Ризики'!$O$5:$O$24,2,'В02 Ризики'!$P$5:$P$24,5) | L6: =COUNTIFS('В02 Ризики'!$O$5:$O$24,3,'В02 Ризики'!$P$5:$P$24,5) | M6: =COUNTIFS('В02 Ризики'!$O$5:$O$24,4,'В02 Ризики'!$P$5:$P$24,5) | N6: =COUNTIFS('В02 Ризики'!$O$5:$O$24,5,'В02 Ризики'!$P$5:$P$24,5)
A7: C = 4 | B7: =COUNTIFS('В02 Ризики'!$F$5:$F$24,1,'В02 Ризики'!$G$5:$G$24,4) | C7: =COUNTIFS('В02 Ризики'!$F$5:$F$24,2,'В02 Ризики'!$G$5:$G$24,4) | D7: =COUNTIFS('В02 Ризики'!$F$5:$F$24,3,'В02 Ризики'!$G$5:$G$24,4) | E7: =COUNTIFS('В02 Ризики'!$F$5:$F$24,4,'В02 Ризики'!$G$5:$G$24,4) | F7: =COUNTIFS('В02 Ризики'!$F$5:$F$24,5,'В02 Ризики'!$G$5:$G$24,4) | I7: C = 4 | J7: =COUNTIFS('В02 Ризики'!$O$5:$O$24,1,'В02 Ризики'!$P$5:$P$24,4) | K7: =COUNTIFS('В02 Ризики'!$O$5:$O$24,2,'В02 Ризики'!$P$5:$P$24,4) | L7: =COUNTIFS('В02 Ризики'!$O$5:$O$24,3,'В02 Ризики'!$P$5:$P$24,4) | M7: =COUNTIFS('В02 Ризики'!$O$5:$O$24,4,'В02 Ризики'!$P$5:$P$24,4) | N7: =COUNTIFS('В02 Ризики'!$O$5:$O$24,5,'В02 Ризики'!$P$5:$P$24,4)
A8: C = 3 | B8: =COUNTIFS('В02 Ризики'!$F$5:$F$24,1,'В02 Ризики'!$G$5:$G$24,3) | C8: =COUNTIFS('В02 Ризики'!$F$5:$F$24,2,'В02 Ризики'!$G$5:$G$24,3) | D8: =COUNTIFS('В02 Ризики'!$F$5:$F$24,3,'В02 Ризики'!$G$5:$G$24,3) | E8: =COUNTIFS('В02 Ризики'!$F$5:$F$24,4,'В02 Ризики'!$G$5:$G$24,3) | F8: =COUNTIFS('В02 Ризики'!$F$5:$F$24,5,'В02 Ризики'!$G$5:$G$24,3) | I8: C = 3 | J8: =COUNTIFS('В02 Ризики'!$O$5:$O$24,1,'В02 Ризики'!$P$5:$P$24,3) | K8: =COUNTIFS('В02 Ризики'!$O$5:$O$24,2,'В02 Ризики'!$P$5:$P$24,3) | L8: =COUNTIFS('В02 Ризики'!$O$5:$O$24,3,'В02 Ризики'!$P$5:$P$24,3) | M8: =COUNTIFS('В02 Ризики'!$O$5:$O$24,4,'В02 Ризики'!$P$5:$P$24,3) | N8: =COUNTIFS('В02 Ризики'!$O$5:$O$24,5,'В02 Ризики'!$P$5:$P$24,3)
A9: C = 2 | B9: =COUNTIFS('В02 Ризики'!$F$5:$F$24,1,'В02 Ризики'!$G$5:$G$24,2) | C9: =COUNTIFS('В02 Ризики'!$F$5:$F$24,2,'В02 Ризики'!$G$5:$G$24,2) | D9: =COUNTIFS('В02 Ризики'!$F$5:$F$24,3,'В02 Ризики'!$G$5:$G$24,2) | E9: =COUNTIFS('В02 Ризики'!$F$5:$F$24,4,'В02 Ризики'!$G$5:$G$24,2) | F9: =COUNTIFS('В02 Ризики'!$F$5:$F$24,5,'В02 Ризики'!$G$5:$G$24,2) | I9: C = 2 | J9: =COUNTIFS('В02 Ризики'!$O$5:$O$24,1,'В02 Ризики'!$P$5:$P$24,2) | K9: =COUNTIFS('В02 Ризики'!$O$5:$O$24,2,'В02 Ризики'!$P$5:$P$24,2) | L9: =COUNTIFS('В02 Ризики'!$O$5:$O$24,3,'В02 Ризики'!$P$5:$P$24,2) | M9: =COUNTIFS('В02 Ризики'!$O$5:$O$24,4,'В02 Ризики'!$P$5:$P$24,2) | N9: =COUNTIFS('В02 Ризики'!$O$5:$O$24,5,'В02 Ризики'!$P$5:$P$24,2)
A10: C = 1 | B10: =COUNTIFS('В02 Ризики'!$F$5:$F$24,1,'В02 Ризики'!$G$5:$G$24,1) | C10: =COUNTIFS('В02 Ризики'!$F$5:$F$24,2,'В02 Ризики'!$G$5:$G$24,1) | D10: =COUNTIFS('В02 Ризики'!$F$5:$F$24,3,'В02 Ризики'!$G$5:$G$24,1) | E10: =COUNTIFS('В02 Ризики'!$F$5:$F$24,4,'В02 Ризики'!$G$5:$G$24,1) | F10: =COUNTIFS('В02 Ризики'!$F$5:$F$24,5,'В02 Ризики'!$G$5:$G$24,1) | I10: C = 1 | J10: =COUNTIFS('В02 Ризики'!$O$5:$O$24,1,'В02 Ризики'!$P$5:$P$24,1) | K10: =COUNTIFS('В02 Ризики'!$O$5:$O$24,2,'В02 Ризики'!$P$5:$P$24,1) | L10: =COUNTIFS('В02 Ризики'!$O$5:$O$24,3,'В02 Ризики'!$P$5:$P$24,1) | M10: =COUNTIFS('В02 Ризики'!$O$5:$O$24,4,'В02 Ризики'!$P$5:$P$24,1) | N10: =COUNTIFS('В02 Ризики'!$O$5:$O$24,5,'В02 Ризики'!$P$5:$P$24,1)
B11: P = 1 | C11: P = 2 | D11: P = 3 | E11: P = 4 | F11: P = 5 | J11: P = 1 | K11: P = 2 | L11: P = 3 | M11: P = 4 | N11: P = 5
A14: Зелений: низький (1–4). Жовтий: середній (5–9). Помаранчевий: високий (10–16). Червоний: критичний (17–25).

Sheet В02 Бюджет
A1: Бюджет і ефект заходів
A4: Бюджет відділення | B4: 100
A5: Витрачено на заходи | B5: =SUM('В02 Каталог'!G5:G19)
A6: Залишок | B6: =B4-B5
A7: Перевірка бюджету | B7: =IF(B6>=0,"У межах бюджету","Перевищено на "&(-B6))
A8: Сума рівнів усіх ризиків до заходів | B8: =SUM('В02 Ризики'!H5:H24)
A9: Сума залишкових рівнів після заходів | B9: =SUM('В02 Ризики'!Q5:Q24)
A10: Зниження сукупного ризику | B10: =IF(B8=0,"",1-B9/B8)
A11: Ризики з позначкою «Топ-5» | B11: =COUNTIF('В02 Ризики'!J5:J24,"Так")
A12: Топ-5: що не так у перевірці | B12: =SUMPRODUCT(('В02 Ризики'!J5:J24="Так")*('В02 Ризики'!R5:R24<>"ОК"))
A13: Ризики у реєстрі | B13: =COUNTA('В02 Ризики'!B5:B24)
